Workbook

Sheet Leia-me
A1: ChatGPT (GPT-5.6 Luna, deslogado) × Gemini 3.8 Flash (logado) — 60 rodadas pareadas + 4 reexecuções, mesmo protocolo de reparo
A2: Fontes: fase2/ (42 limpas + 7 bugs originais), fase2-chatgpt-reexec/ (15 bugs reexecutados em 2026-09-24 com reparo fixo), fase2-gemini-consolidado. Pass/fail final cruzado com a última saída de flutter test nos três conjuntos: 0 divergências. Os 39 prompts de reparo da reexecução foram conferidos: só o template + saída do terminal.
A4: Regras de contagem (iguais para os dois modelos)
A5: 1. As 60 usam os prompts ORIGINAIS de W-SILENT-FS e I-CRASH-{ZS,FS,COT}; as 4 _REEXEC (prompt corrigido) ficam fora e aparecem em bloco próprio. A planilha Fase2_Consolidado_60rodadas.xlsx do autor conta o inverso — alinhar.
A6: 2. formatName em grupo próprio. Limpo = 39 (21+9+9). Bug plantado = 18.
A7: 3. "Passando (final)" = estado arquivado após a última iteração; arquivo que não compila = 0 passando e "Estado final" ≠ executa. "Taxa (executados)" = passando ÷ (passando + falhando) só quando o arquivo executa; senão 0. "Gerados" = contagem da geração inicial (volume).
A8: 4. Lado ChatGPT: 15 rodadas de bug vêm da reexecução com reparo fixo (coluna "GPT execução"); as 7 de bug e as 42 limpas são da execução original. Nas 42 limpas, 3 rodadas tiveram contexto extra no reparo a pedido do modelo (WIDGET-ZS-02, WIDGET-COT-01, INT-FS-01) — coluna "GPT dica operador". A execução assistida das 15 está em fase2/_execucao-assistida/ e na aba "Assistida (ref.)"; não entra na comparação.
A9: 5. Detecção dos bugs plantados codificada de forma uniforme nos dois modelos, pelo código e pelas respostas literais: Capturou (teste falha com o bug e é mantido) · Caracterizou com alerta (asserção fixa o comportamento defeituoso E a resposta o chama de defeito/suspeito) · Viu sem asserção (mencionou; nenhuma asserção toca o bug) · Canonizou sem alerta (asserção fixa o defeito, sem menção) · Não viu. "(C) com asserção" dos docs unitários = Caracterizou com alerta.
A11: Abas
A12: Pareado — uma linha por rodada, os dois modelos lado a lado. Consolidado — fórmulas sobre Pareado. Bugs plantados — 6 bugs × 3 estratégias × 2 modelos. Assistida (ref.) — as 15 rodadas na execução assistida × reexecução, só para as limitações. Assimetrias — o que ainda difere entre as execuções. Perguntas — as 8 perguntas da comparação.

Sheet Pareado
A1: # | B1: ID | C1: Nível | D1: Estratégia | E1: Alvo | F1: Grupo | G1: Bug | H1: GPT execução | I1: GPT gerados | J1: GPT passando | K1: GPT falhando | L1: GPT taxa (executados) | M1: GPT iter | N1: GPT compilou 1ª | O1: GPT estado final | P1: GPT dica operador | Q1: GPT classes | R1: GPT detecção | S1: GEM gerados | T1: GEM passando | U1: GEM falhando | V1: GEM taxa (executados) | W1: GEM iter | X1: GEM compilou 1ª | Y1: GEM estado final | Z1: GEM tentativas | AA1: GEM recusas | AB1: GEM classes | AC1: GEM detecção | AD1: Δ gerados (GEM−GPT) | AE1: Δ taxa (GEM−GPT) | AF1: Quem gerou mais | AG1: Quem aprovou mais
A2: 1 | B2: FASE2-UCRASH-ZS | C2: Unitário | D2: ZS | E2: capitalize | F2: Bug plantado | G2: U-CRASH | H2: original | I2: 12 | J2: 12 | K2: 0 | L2: =IF(O2="executa",IFERROR(J2/(J2+K2),0),0) -> 1 | M2: 0 | N2: Sim | O2: executa | P2: Não | Q2: (C) | R2: (C) com asserção | S2: 11 | T2: 11 | U2: 0 | V2: =IF(Y2="executa",IFERROR(T2/(T2+U2),0),0) -> 1 | W2: 0 | X2: Sim | Y2: executa | Z2: 1 | AA2: 0 | AB2: (C) | AC2: (C) com asserção | AD2: =S2-I2 -> -1 | AE2: =V2-L2 -> 0 | AF2: =IF(S2>I2,"Gemini",IF(S2<I2,"ChatGPT","empate")) -> ChatGPT | AG2: =IF(V2>L2+0.0001,"Gemini",IF(V2<L2-0.0001,"ChatGPT","empate")) -> empate
A3: 2 | B3: FASE2-UCRASH-FS | C3: Unitário | D3: FS | E3: capitalize | F3: Bug plantado | G3: U-CRASH | H3: original | I3: 6 | J3: 5 | K3: 1 | L3: =IF(O3="executa",IFERROR(J3/(J3+K3),0),0) -> 0.83333333 | M3: 1 | N3: Sim | O3: executa | P3: Não | Q3: (B) | R3: (B) exposto por falha | S3: 6 | T3: 6 | U3: 0 | V3: =IF(Y3="executa",IFERROR(T3/(T3+U3),0),0) -> 1 | W3: 0 | X3: Sim | Y3: executa | Z3: 1 | AA3: 0 | AB3: (C) | AC3: (C) só em prosa | AD3: =S3-I3 -> 0 | AE3: =V3-L3 -> 0.16666667 | AF3: =IF(S3>I3,"Gemini",IF(S3<I3,"ChatGPT","empate")) -> empate | AG3: =IF(V3>L3+0.0001,"Gemini",IF(V3<L3-0.0001,"ChatGPT","empate")) -> Gemini
A4: 3 | B4: FASE2-UCRASH-COT | C4: Unitário | D4: COT | E4: capitalize | F4: Bug plantado | G4: U-CRASH | H4: original | I4: 12 | J4: 12 | K4: 0 | L4: =IF(O4="executa",IFERROR(J4/(J4+K4),0),0) -> 1 | M4: 0 | N4: Sim | O4: executa | P4: Não | Q4: (C) | R4: (C) com asserção | S4: 10 | T4: 10 | U4: 0 | V4: =IF(Y4="executa",IFERROR(T4/(T4+U4),0),0) -> 1 | W4: 0 | X4: Sim | Y4: executa | Z4: 1 | AA4: 0 | AB4: (C) | AC4: (C) com asserção | AD4: =S4-I4 -> -2 | AE4: =V4-L4 -> 0 | AF4: =IF(S4>I4,"Gemini",IF(S4<I4,"ChatGPT","empate")) -> ChatGPT | AG4: =IF(V4>L4+0.0001,"Gemini",IF(V4<L4-0.0001,"ChatGPT","empate")) -> empate
A5: 4 | B5: FASE2-USILENT-ZS | C5: Unitário | D5: ZS | E5: validateSenha | F5: Bug plantado | G5: U-SILENT | H5: original | I5: 12 | J5: 12 | K5: 0 | L5: =IF(O5="executa",IFERROR(J5/(J5+K5),0),0) -> 1 | M5: 0 | N5: Sim | O5: executa | P5: Não | Q5: (C) | R5: (C) com asserção | S5: 7 | T5: 7 | U5: 0 | V5: =IF(Y5="executa",IFERROR(T5/(T5+U5),0),0) -> 1 | W5: 0 | X5: Sim | Y5: executa | Z5: 1 | AA5: 0 | AB5: (C) | AC5: (C) com asserção | AD5: =S5-I5 -> -5 | AE5: =V5-L5 -> 0 | AF5: =IF(S5>I5,"Gemini",IF(S5<I5,"ChatGPT","empate")) -> ChatGPT | AG5: =IF(V5>L5+0.0001,"Gemini",IF(V5<L5-0.0001,"ChatGPT","empate")) -> empate
A6: 5 | B6: FASE2-USILENT-FS | C6: Unitário | D6: FS | E6: validateSenha | F6: Bug plantado | G6: U-SILENT | H6: original | I6: 6 | J6: 6 | K6: 0 | L6: =IF(O6="executa",IFERROR(J6/(J6+K6),0),0) -> 1 | M6: 0 | N6: Sim | O6: executa | P6: Não | Q6: (C) | R6: (C) com asserção | S6: 5 | T6: 5 | U6: 0 | V6: =IF(Y6="executa",IFERROR(T6/(T6+U6),0),0) -> 1 | W6: 0 | X6: Sim | Y6: executa | Z6: 1 | AA6: 0 | AB6: (C) | AC6: (C) com asserção | AD6: =S6-I6 -> -1 | AE6: =V6-L6 -> 0 | AF6: =IF(S6>I6,"Gemini",IF(S6<I6,"ChatGPT","empate")) -> ChatGPT | AG6: =IF(V6>L6+0.0001,"Gemini",IF(V6<L6-0.0001,"ChatGPT","empate")) -> empate
A7: 6 | B7: FASE2-USILENT-COT | C7: Unitário | D7: COT | E7: validateSenha | F7: Bug plantado | G7: U-SILENT | H7: original | I7: 14 | J7: 14 | K7: 0 | L7: =IF(O7="executa",IFERROR(J7/(J7+K7),0),0) -> 1 | M7: 0 | N7: Sim | O7: executa | P7: Não | Q7: (C) | R7: (C) com asserção | S7: 8 | T7: 8 | U7: 0 | V7: =IF(Y7="executa",IFERROR(T7/(T7+U7),0),0) -> 1 | W7: 0 | X7: Sim | Y7: executa | Z7: 2 | AA7: 1 | AB7: (C) | AC7: (C) com asserção | AD7: =S7-I7 -> -6 | AE7: =V7-L7 -> 0 | AF7: =IF(S7>I7,"Gemini",IF(S7<I7,"ChatGPT","empate")) -> ChatGPT | AG7: =IF(V7>L7+0.0001,"Gemini",IF(V7<L7-0.0001,"ChatGPT","empate")) -> empate
A8: 7 | B8: FASE2-WCRASH-ZS | C8: Widget | D8: ZS | E8: CriarPlaylistScreen | F8: Bug plantado | G8: W-CRASH | H8: original | I8: 14 | J8: 14 | K8: 0 | L8: =IF(O8="executa",IFERROR(J8/(J8+K8),0),0) -> 1 | M8: 0 | N8: Sim | O8: executa | P8: Não | Q8: — | R8: Não detectado | S8: 5 | T8: 5 | U8: 0 | V8: =IF(Y8="executa",IFERROR(T8/(T8+U8),0),0) -> 1 | W8: 0 | X8: Sim | Y8: executa | Z8: 2 | AA8: 1 | AB8: — | AC8: Não detectado | AD8: =S8-I8 -> -9 | AE8: =V8-L8 -> 0 | AF8: =IF(S8>I8,"Gemini",IF(S8<I8,"ChatGPT","empate")) -> ChatGPT | AG8: =IF(V8>L8+0.0001,"Gemini",IF(V8<L8-0.0001,"ChatGPT","empate")) -> empate
A9: 8 | B9: FASE2-WCRASH-FS | C9: Widget | D9: FS | E9: CriarPlaylistScreen | F9: Bug plantado | G9: W-CRASH | H9: reexecução 2026-09-24 (reparo fixo) | I9: 10 | J9: 0 | K9: 10 | L9: =IF(O9="executa",IFERROR(J9/(J9+K9),0),0) -> 0 | M9: 3 | N9: Não | O9: não compila | P9: Não | Q9: (A); (A); (A) | R9: Não detectado | S9: 5 | T9: 3 | U9: 2 | V9: =IF(Y9="executa",IFERROR(T9/(T9+U9),0),0) -> 0.6 | W9: 3 | X9: Não | Y9: executa | Z9: 1 | AA9: 0 | AB9: (A); (A); (A) | AC9: Não detectado | AD9: =S9-I9 -> -5 | AE9: =V9-L9 -> 0.6 | AF9: =IF(S9>I9,"Gemini",IF(S9<I9,"ChatGPT","empate")) -> ChatGPT | AG9: =IF(V9>L9+0.0001,"Gemini",IF(V9<L9-0.0001,"ChatGPT","empate")) -> Gemini
A10: 9 | B10: FASE2-WCRASH-COT | C10: Widget | D10: COT | E10: CriarPlaylistScreen | F10: Bug plantado | G10: W-CRASH | H10: reexecução 2026-09-24 (reparo fixo) | I10: 21 | J10: 20 | K10: 1 | L10: =IF(O10="executa",IFERROR(J10/(J10+K10),0),0) -> 0.95238095 | M10: 3 | N10: Sim | O10: executa | P10: Não | Q10: (A); (A); (A) | R10: Não detectado | S10: 9 | T10: 9 | U10: 0 | V10: =IF(Y10="executa",IFERROR(T10/(T10+U10),0),0) -> 1 | W10: 0 | X10: Sim | Y10: executa | Z10: 1 | AA10: 0 | AB10: — | AC10: Não detectado | AD10: =S10-I10 -> -12 | AE10: =V10-L10 -> 0.047619048 | AF10: =IF(S10>I10,"Gemini",IF(S10<I10,"ChatGPT","empate")) -> ChatGPT | AG10: =IF(V10>L10+0.0001,"Gemini",IF(V10<L10-0.0001,"ChatGPT","empate")) -> Gemini
A11: 10 | B11: FASE2-WSILENT-ZS | C11: Widget | D11: ZS | E11: LoginScreen | F11: Bug plantado | G11: W-SILENT | H11: reexecução 2026-09-24 (reparo fixo) | I11: 14 | J11: 7 | K11: 1 | L11: =IF(O11="executa",IFERROR(J11/(J11+K11),0),0) -> 0.875 | M11: 3 | N11: Não | O11: executa | P11: Não | Q11: (C) geração; (A); (A); (A) | R11: Caracterização com alerta | S11: 11 | T11: 10 | U11: 1 | V11: =IF(Y11="executa",IFERROR(T11/(T11+U11),0),0) -> 0.90909091 | W11: 2 | X11: Sim | Y11: executa | Z11: 1 | AA11: 0 | AB11: (A); (B) | AC11: Canonizado | AD11: =S11-I11 -> -3 | AE11: =V11-L11 -> 0.034090909 | AF11: =IF(S11>I11,"Gemini",IF(S11<I11,"ChatGPT","empate")) -> ChatGPT | AG11: =IF(V11>L11+0.0001,"Gemini",IF(V11<L11-0.0001,"ChatGPT","empate")) -> Gemini
A12: 11 | B12: FASE2-WSILENT-FS | C12: Widget | D12: FS | E12: LoginScreen | F12: Bug plantado | G12: W-SILENT | H12: reexecução 2026-09-24 (reparo fixo) | I12: 10 | J12: 0 | K12: 9 | L12: =IF(O12="executa",IFERROR(J12/(J12+K12),0),0) -> 0 | M12: 3 | N12: Não | O12: não compila | P12: Não | Q12: (C) geração; (A); (A); (A) | R12: Caracterização com alerta (código nunca rodou) | S12: 9 | T12: 9 | U12: 0 | V12: =IF(Y12="executa",IFERROR(T12/(T12+U12),0),0) -> 1 | W12: 2 | X12: Não | Y12: executa | Z12: 1 | AA12: 0 | AB12: (A); (A) | AC12: Canonizado (sobre cópia) | AD12: =S12-I12 -> -1 | AE12: =V12-L12 -> 1 | AF12: =IF(S12>I12,"Gemini",IF(S12<I12,"ChatGPT","empate")) -> ChatGPT | AG12: =IF(V12>L12+0.0001,"Gemini",IF(V12<L12-0.0001,"ChatGPT","empate")) -> Gemini
A13: 12 | B13: FASE2-WSILENT-COT | C13: Widget | D13: COT | E13: LoginScreen | F13: Bug plantado | G13: W-SILENT | H13: reexecução 2026-09-24 (reparo fixo) | I13: 21 | J13: 0 | K13: 20 | L13: =IF(O13="executa",IFERROR(J13/(J13+K13),0),0) -> 0 | M13: 3 | N13: Não | O13: não compila | P13: Não | Q13: (C) geração; (A); (A); (A) | R13: Caracterização com alerta | S13: 10 | T13: 9 | U13: 1 | V13: =IF(Y13="executa",IFERROR(T13/(T13+U13),0),0) -> 0.9 | W13: 1 | X13: Sim | Y13: executa | Z13: 1 | AA13: 0 | AB13: (B) | AC13: Canonizado | AD13: =S13-I13 -> -11 | AE13: =V13-L13 -> 0.9 | AF13: =IF(S13>I13,"Gemini",IF(S13<I13,"ChatGPT","empate")) -> ChatGPT | AG13: =IF(V13>L13+0.0001,"Gemini",IF(V13<L13-0.0001,"ChatGPT","empate")) -> Gemini
... A61: 60 | B61: FASE2-INT-COT-03_playlistFlow | C61: Integração | D61: COT | E61: playlistFlow | F61: Limpo | G61: — | H61: original | I61: 5 | J61: 5 | K61: 0 | L61: =IF(O61="executa",IFERROR(J61/(J61+K61),0),0) -> 1 | M61: 1 | N61: Não | O61: executa | P61: Não | Q61: (A) | R61: — | S61: 6 | T61: 6 | U61: 0 | V61: =IF(Y61="executa",IFERROR(T61/(T61+U61),0),0) -> 1 | W61: 2 | X61: Não | Y61: executa | Z61: 1 | AA61: 0 | AB61: (A); (A) | AC61: — | AD61: =S61-I61 -> 1 | AE61: =V61-L61 -> 0 | AF61: =IF(S61>I61,"Gemini",IF(S61<I61,"ChatGPT","empate")) -> Gemini | AG61: =IF(V61>L61+0.0001,"Gemini",IF(V61<L61-0.0001,"ChatGPT","empate")) -> empate
A62: — | B62: FASE2-ICRASH-COT_REEXEC | C62: Integração | D62: COT | E62: GenerosCadastroScreen | F62: REEXEC | G62: I-CRASH | H62: reexecução 2026-09-24 (reparo fixo) | I62: 13 | J62: 0 | K62: 13 | L62: =IF(O62="executa",IFERROR(J62/(J62+K62),0),0) -> 0 | M62: 3 | N62: Sim | O62: executa | P62: Não | Q62: (A); (B); (B) | R62: (B) exposto por falha (acidental); teste dedicado canoniza | S62: 8 | T62: 4 | U62: 4 | V62: =IF(Y62="executa",IFERROR(T62/(T62+U62),0),0) -> 0.5 | W62: 3 | X62: Não | Y62: executa | Z62: 2 | AA62: 1 | AB62: (A); (A)+(B); (B) | AC62: Canonizado (exercitado) | AD62: =S62-I62 -> -5 | AE62: =V62-L62 -> 0.5 | AF62: =IF(S62>I62,"Gemini",IF(S62<I62,"ChatGPT","empate")) -> ChatGPT | AG62: =IF(V62>L62+0.0001,"Gemini",IF(V62<L62-0.0001,"ChatGPT","empate")) -> Gemini
A63: — | B63: FASE2-ICRASH-FS_REEXEC | C63: Integração | D63: FS | E63: GenerosCadastroScreen | F63: REEXEC | G63: I-CRASH | H63: reexecução 2026-09-24 (reparo fixo) | I63: 2 | J63: 1 | K63: 1 | L63: =IF(O63="executa",IFERROR(J63/(J63+K63),0),0) -> 0.5 | M63: 3 | N63: Sim | O63: executa | P63: Não | Q63: (A); (A); (A) | R63: Não detectado | S63: 2 | T63: 0 | U63: 2 | V63: =IF(Y63="executa",IFERROR(T63/(T63+U63),0),0) -> 0 | W63: 2 | X63: Não | Y63: não compila | Z63: 2 | AA63: 1 | AB63: (A); (B)→(A) | AC63: Não detectado | AD63: =S63-I63 -> 0 | AE63: =V63-L63 -> -0.5 | AF63: =IF(S63>I63,"Gemini",IF(S63<I63,"ChatGPT","empate")) -> empate | AG63: =IF(V63>L63+0.0001,"Gemini",IF(V63<L63-0.0001,"ChatGPT","empate")) -> ChatGPT
A64: — | B64: FASE2-ICRASH-ZS_REEXEC | C64: Integração | D64: ZS | E64: GenerosCadastroScreen | F64: REEXEC | G64: I-CRASH | H64: reexecução 2026-09-24 (reparo fixo) | I64: 6 | J64: 1 | K64: 4 | L64: =IF(O64="executa",IFERROR(J64/(J64+K64),0),0) -> 0.2 | M64: 3 | N64: Sim | O64: executa | P64: Não | Q64: (A); (B); (B) | R64: (B) exposto por falha, capturado por asserção | S64: 0 | T64: 0 | U64: 0 | V64: =IF(Y64="executa",IFERROR(T64/(T64+U64),0),0) -> 0 | W64: 0 | X64: — | Y64: não executada | Z64: 2 | AA64: 2 | AB64: — | AC64: n/a | AD64: =S64-I64 -> -6 | AE64: =V64-L64 -> -0.2 | AF64: =IF(S64>I64,"Gemini",IF(S64<I64,"ChatGPT","empate")) -> ChatGPT | AG64: =IF(V64>L64+0.0001,"Gemini",IF(V64<L64-0.0001,"ChatGPT","empate")) -> ChatGPT
A65: — | B65: FASE2-WSILENT-FS_REEXEC | C65: Widget | D65: FS | E65: LoginScreen | F65: REEXEC | G65: W-SILENT | H65: reexecução 2026-09-24 (reparo fixo) | I65: 10 | J65: 0 | K65: 10 | L65: =IF(O65="executa",IFERROR(J65/(J65+K65),0),0) -> 0 | M65: 3 | N65: Não | O65: não compila | P65: Não | Q65: (A); (A); (A) | R65: Canonizado (sem menção) | S65: 9 | T65: 0 | U65: 9 | V65: =IF(Y65="executa",IFERROR(T65/(T65+U65),0),0) -> 0 | W65: 3 | X65: Não | Y65: não compila | Z65: 2 | AA65: 1 | AB65: (A); (A); (A) | AC65: Canonizado | AD65: =S65-I65 -> -1 | AE65: =V65-L65 -> 0 | AF65: =IF(S65>I65,"Gemini",IF(S65<I65,"ChatGPT","empate")) -> ChatGPT | AG65: =IF(V65>L65+0.0001,"Gemini",IF(V65<L65-0.0001,"ChatGPT","empate")) -> empate

Sheet Consolidado
A1: Consolidado comparativo — fórmulas sobre a aba Pareado (REEXEC excluídas). Taxa = passando ÷ (passando + falhando) nas rodadas que executam.
A3: Grupo | B3: Nível | C3: Estratégia | D3: Rodadas | E3: GPT gerados | F3: GPT passando | G3: GPT taxa (executados) | H3: GPT 100% verdes | I3: GPT iterações | J3: GPT no máx. | K3: GPT não compila | L3: GPT c/ dica | M3: GEM gerados | N3: GEM passando | O3: GEM taxa (executados) | P3: GEM 100% verdes | Q3: GEM iterações | R3: GEM no máx. | S3: GEM não compila | T3: GEM recusas | U3: GPT gerou mais | V3: Empate | W3: GEM gerou mais | X3: GPT taxa maior | Y3: Taxa igual | Z3: GEM taxa maior
A4: Limpo | B4: Unitário | C4: ZS | D4: =COUNTIFS(Pareado!$F$2:$F$65,"Limpo",Pareado!$C$2:$C$65,"Unitário",Pareado!$D$2:$D$65,"ZS") -> 7 | E4: =SUMIFS(Pareado!$I$2:$I$65,Pareado!$F$2:$F$65,"Limpo",Pareado!$C$2:$C$65,"Unitário",Pareado!$D$2:$D$65,"ZS") -> 145 | F4: =SUMIFS(Pareado!$J$2:$J$65,Pareado!$F$2:$F$65,"Limpo",Pareado!$C$2:$C$65,"Unitário",Pareado!$D$2:$D$65,"ZS") -> 145 | G4: =IFERROR(F4/(F4+SUMIFS(Pareado!$K$2:$K$65,Pareado!$F$2:$F$65,"Limpo",Pareado!$C$2:$C$65,"Unitário",Pareado!$D$2:$D$65,"ZS",Pareado!$O$2:$O$65,"executa")),0) -> 1 | H4: =COUNTIFS(Pareado!$F$2:$F$65,"Limpo",Pareado!$C$2:$C$65,"Unitário",Pareado!$D$2:$D$65,"ZS",Pareado!$L$2:$L$65,1) -> 7 | I4: =SUMIFS(Pareado!$M$2:$M$65,Pareado!$F$2:$F$65,"Limpo",Pareado!$C$2:$C$65,"Unitário",Pareado!$D$2:$D$65,"ZS") -> 3 | J4: =COUNTIFS(Pareado!$F$2:$F$65,"Limpo",Pareado!$C$2:$C$65,"Unitário",Pareado!$D$2:$D$65,"ZS",Pareado!$M$2:$M$65,3) -> 0 | K4: =COUNTIFS(Pareado!$F$2:$F$65,"Limpo",Pareado!$C$2:$C$65,"Unitário",Pareado!$D$2:$D$65,"ZS",Pareado!$O$2:$O$65,"<>executa") -> 0 | L4: =COUNTIFS(Pareado!$F$2:$F$65,"Limpo",Pareado!$C$2:$C$65,"Unitário",Pareado!$D$2:$D$65,"ZS",Pareado!$P$2:$P$65,"Sim") -> 0 | M4: =SUMIFS(Pareado!$S$2:$S$65,Pareado!$F$2:$F$65,"Limpo",Pareado!$C$2:$C$65,"Unitário",Pareado!$D$2:$D$65,"ZS") -> 114 | N4: =SUMIFS(Pareado!$T$2:$T$65,Pareado!$F$2:$F$65,"Limpo",Pareado!$C$2:$C$65,"Unitário",Pareado!$D$2:$D$65,"ZS") -> 114 | O4: =IFERROR(N4/(N4+SUMIFS(Pareado!$U$2:$U$65,Pareado!$F$2:$F$65,"Limpo",Pareado!$C$2:$C$65,"Unitário",Pareado!$D$2:$D$65,"ZS",Pareado!$Y$2:$Y$65,"executa")),0) -> 1 | P4: =COUNTIFS(Pareado!$F$2:$F$65,"Limpo",Pareado!$C$2:$C$65,"Unitário",Pareado!$D$2:$D$65,"ZS",Pareado!$V$2:$V$65,1) -> 7 | Q4: =SUMIFS(Pareado!$W$2:$W$65,Pareado!$F$2:$F$65,"Limpo",Pareado!$C$2:$C$65,"Unitário",Pareado!$D$2:$D$65,"ZS") -> 1 | R4: =COUNTIFS(Pareado!$F$2:$F$65,"Limpo",Pareado!$C$2:$C$65,"Unitário",Pareado!$D$2:$D$65,"ZS",Pareado!$W$2:$W$65,3) -> 0 | S4: =COUNTIFS(Pareado!$F$2:$F$65,"Limpo",Pareado!$C$2:$C$65,"Unitário",Pareado!$D$2:$D$65,"ZS",Pareado!$Y$2:$Y$65,"<>executa") -> 0 | T4: =SUMIFS(Pareado!$AA$2:$AA$65,Pareado!$F$2:$F$65,"Limpo",Pareado!$C$2:$C$65,"Unitário",Pareado!$D$2:$D$65,"ZS") -> 4 | U4: =COUNTIFS(Pareado!$F$2:$F$65,"Limpo",Pareado!$C$2:$C$65,"Unitário",Pareado!$D$2:$D$65,"ZS",Pareado!$AF$2:$AF$65,"ChatGPT") -> 6 | V4: =COUNTIFS(Pareado!$F$2:$F$65,"Limpo",Pareado!$C$2:$C$65,"Unitário",Pareado!$D$2:$D$65,"ZS",Pareado!$AF$2:$AF$65,"empate") -> 0 | W4: =COUNTIFS(Pareado!$F$2:$F$65,"Limpo",Pareado!$C$2:$C$65,"Unitário",Pareado!$D$2:$D$65,"ZS",Pareado!$AF$2:$AF$65,"Gemini") -> 1 | X4: =COUNTIFS(Pareado!$F$2:$F$65,"Limpo",Pareado!$C$2:$C$65,"Unitário",Pareado!$D$2:$D$65,"ZS",Pareado!$AG$2:$AG$65,"ChatGPT") -> 0 | Y4: =COUNTIFS(Pareado!$F$2:$F$65,"Limpo",Pareado!$C$2:$C$65,"Unitário",Pareado!$D$2:$D$65,"ZS",Pareado!$AG$2:$AG$65,"empate") -> 7 | Z4: =COUNTIFS(Pareado!$F$2:$F$65,"Limpo",Pareado!$C$2:$C$65,"Unitário",Pareado!$D$2:$D$65,"ZS",Pareado!$AG$2:$AG$65,"Gemini") -> 0
A5: Limpo | B5: Unitário | C5: FS | D5: =COUNTIFS(Pareado!$F$2:$F$65,"Limpo",Pareado!$C$2:$C$65,"Unitário",Pareado!$D$2:$D$65,"FS") -> 7 | E5: =SUMIFS(Pareado!$I$2:$I$65,Pareado!$F$2:$F$65,"Limpo",Pareado!$C$2:$C$65,"Unitário",Pareado!$D$2:$D$65,"FS") -> 54 | F5: =SUMIFS(Pareado!$J$2:$J$65,Pareado!$F$2:$F$65,"Limpo",Pareado!$C$2:$C$65,"Unitário",Pareado!$D$2:$D$65,"FS") -> 54 | G5: =IFERROR(F5/(F5+SUMIFS(Pareado!$K$2:$K$65,Pareado!$F$2:$F$65,"Limpo",Pareado!$C$2:$C$65,"Unitário",Pareado!$D$2:$D$65,"FS",Pareado!$O$2:$O$65,"executa")),0) -> 1 | H5: =COUNTIFS(Pareado!$F$2:$F$65,"Limpo",Pareado!$C$2:$C$65,"Unitário",Pareado!$D$2:$D$65,"FS",Pareado!$L$2:$L$65,1) -> 7 | I5: =SUMIFS(Pareado!$M$2:$M$65,Pareado!$F$2:$F$65,"Limpo",Pareado!$C$2:$C$65,"Unitário",Pareado!$D$2:$D$65,"FS") -> 0 | J5: =COUNTIFS(Pareado!$F$2:$F$65,"Limpo",Pareado!$C$2:$C$65,"Unitário",Pareado!$D$2:$D$65,"FS",Pareado!$M$2:$M$65,3) -> 0 | K5: =COUNTIFS(Pareado!$F$2:$F$65,"Limpo",Pareado!$C$2:$C$65,"Unitário",Pareado!$D$2:$D$65,"FS",Pareado!$O$2:$O$65,"<>executa") -> 0 | L5: =COUNTIFS(Pareado!$F$2:$F$65,"Limpo",Pareado!$C$2:$C$65,"Unitário",Pareado!$D$2:$D$65,"FS",Pareado!$P$2:$P$65,"Sim") -> 0 | M5: =SUMIFS(Pareado!$S$2:$S$65,Pareado!$F$2:$F$65,"Limpo",Pareado!$C$2:$C$65,"Unitário",Pareado!$D$2:$D$65,"FS") -> 53 | N5: =SUMIFS(Pareado!$T$2:$T$65,Pareado!$F$2:$F$65,"Limpo",Pareado!$C$2:$C$65,"Unitário",Pareado!$D$2:$D$65,"FS") -> 53 | O5: =IFERROR(N5/(N5+SUMIFS(Pareado!$U$2:$U$65,Pareado!$F$2:$F$65,"Limpo",Pareado!$C$2:$C$65,"Unitário",Pareado!$D$2:$D$65,"FS",Pareado!$Y$2:$Y$65,"executa")),0) -> 1 | P5: =COUNTIFS(Pareado!$F$2:$F$65,"Limpo",Pareado!$C$2:$C$65,"Unitário",Pareado!$D$2:$D$65,"FS",Pareado!$V$2:$V$65,1) -> 7 | Q5: =SUMIFS(Pareado!$W$2:$W$65,Pareado!$F$2:$F$65,"Limpo",Pareado!$C$2:$C$65,"Unitário",Pareado!$D$2:$D$65,"FS") -> 0 | R5: =COUNTIFS(Pareado!$F$2:$F$65,"Limpo",Pareado!$C$2:$C$65,"Unitário",Pareado!$D$2:$D$65,"FS",Pareado!$W$2:$W$65,3) -> 0 | S5: =COUNTIFS(Pareado!$F$2:$F$65,"Limpo",Pareado!$C$2:$C$65,"Unitário",Pareado!$D$2:$D$65,"FS",Pareado!$Y$2:$Y$65,"<>executa") -> 0 | T5: =SUMIFS(Pareado!$AA$2:$AA$65,Pareado!$F$2:$F$65,"Limpo",Pareado!$C$2:$C$65,"Unitário",Pareado!$D$2:$D$65,"FS") -> 2 | U5: =COUNTIFS(Pareado!$F$2:$F$65,"Limpo",Pareado!$C$2:$C$65,"Unitário",Pareado!$D$2:$D$65,"FS",Pareado!$AF$2:$AF$65,"ChatGPT") -> 3 | V5: =COUNTIFS(Pareado!$F$2:$F$65,"Limpo",Pareado!$C$2:$C$65,"Unitário",Pareado!$D$2:$D$65,"FS",Pareado!$AF$2:$AF$65,"empate") -> 0 | W5: =COUNTIFS(Pareado!$F$2:$F$65,"Limpo",Pareado!$C$2:$C$65,"Unitário",Pareado!$D$2:$D$65,"FS",Pareado!$AF$2:$AF$65,"Gemini") -> 4 | X5: =COUNTIFS(Pareado!$F$2:$F$65,"Limpo",Pareado!$C$2:$C$65,"Unitário",Pareado!$D$2:$D$65,"FS",Pareado!$AG$2:$AG$65,"ChatGPT") -> 0 | Y5: =COUNTIFS(Pareado!$F$2:$F$65,"Limpo",Pareado!$C$2:$C$65,"Unitário",Pareado!$D$2:$D$65,"FS",Pareado!$AG$2:$AG$65,"empate") -> 7 | Z5: =COUNTIFS(Pareado!$F$2:$F$65,"Limpo",Pareado!$C$2:$C$65,"Unitário",Pareado!$D$2:$D$65,"FS",Pareado!$AG$2:$AG$65,"Gemini") -> 0
A6: Limpo | B6: Unitário | C6: COT | D6: =COUNTIFS(Pareado!$F$2:$F$65,"Limpo",Pareado!$C$2:$C$65,"Unitário",Pareado!$D$2:$D$65,"COT") -> 7 | E6: =SUMIFS(Pareado!$I$2:$I$65,Pareado!$F$2:$F$65,"Limpo",Pareado!$C$2:$C$65,"Unitário",Pareado!$D$2:$D$65,"COT") -> 175 | F6: =SUMIFS(Pareado!$J$2:$J$65,Pareado!$F$2:$F$65,"Limpo",Pareado!$C$2:$C$65,"Unitário",Pareado!$D$2:$D$65,"COT") -> 174 | G6: =IFERROR(F6/(F6+SUMIFS(Pareado!$K$2:$K$65,Pareado!$F$2:$F$65,"Limpo",Pareado!$C$2:$C$65,"Unitário",Pareado!$D$2:$D$65,"COT",Pareado!$O$2:$O$65,"executa")),0) -> 0.99428571 | H6: =COUNTIFS(Pareado!$F$2:$F$65,"Limpo",Pareado!$C$2:$C$65,"Unitário",Pareado!$D$2:$D$65,"COT",Pareado!$L$2:$L$65,1) -> 6 | I6: =SUMIFS(Pareado!$M$2:$M$65,Pareado!$F$2:$F$65,"Limpo",Pareado!$C$2:$C$65,"Unitário",Pareado!$D$2:$D$65,"COT") -> 3 | J6: =COUNTIFS(Pareado!$F$2:$F$65,"Limpo",Pareado!$C$2:$C$65,"Unitário",Pareado!$D$2:$D$65,"COT",Pareado!$M$2:$M$65,3) -> 0 | K6: =COUNTIFS(Pareado!$F$2:$F$65,"Limpo",Pareado!$C$2:$C$65,"Unitário",Pareado!$D$2:$D$65,"COT",Pareado!$O$2:$O$65,"<>executa") -> 0 | L6: =COUNTIFS(Pareado!$F$2:$F$65,"Limpo",Pareado!$C$2:$C$65,"Unitário",Pareado!$D$2:$D$65,"COT",Pareado!$P$2:$P$65,"Sim") -> 0 | M6: =SUMIFS(Pareado!$S$2:$S$65,Pareado!$F$2:$F$65,"Limpo",Pareado!$C$2:$C$65,"Unitário",Pareado!$D$2:$D$65,"COT") -> 97 | N6: =SUMIFS(Pareado!$T$2:$T$65,Pareado!$F$2:$F$65,"Limpo",Pareado!$C$2:$C$65,"Unitário",Pareado!$D$2:$D$65,"COT") -> 97 | O6: =IFERROR(N6/(N6+SUMIFS(Pareado!$U$2:$U$65,Pareado!$F$2:$F$65,"Limpo",Pareado!$C$2:$C$65,"Unitário",Pareado!$D$2:$D$65,"COT",Pareado!$Y$2:$Y$65,"executa")),0) -> 1 | P6: =COUNTIFS(Pareado!$F$2:$F$65,"Limpo",Pareado!$C$2:$C$65,"Unitário",Pareado!$D$2:$D$65,"COT",Pareado!$V$2:$V$65,1) -> 7 | Q6: =SUMIFS(Pareado!$W$2:$W$65,Pareado!$F$2:$F$65,"Limpo",Pareado!$C$2:$C$65,"Unitário",Pareado!$D$2:$D$65,"COT") -> 1 | R6: =COUNTIFS(Pareado!$F$2:$F$65,"Limpo",Pareado!$C$2:$C$65,"Unitário",Pareado!$D$2:$D$65,"COT",Pareado!$W$2:$W$65,3) -> 0 | S6: =COUNTIFS(Pareado!$F$2:$F$65,"Limpo",Pareado!$C$2:$C$65,"Unitário",Pareado!$D$2:$D$65,"COT",Pareado!$Y$2:$Y$65,"<>executa") -> 0 | T6: =SUMIFS(Pareado!$AA$2:$AA$65,Pareado!$F$2:$F$65,"Limpo",Pareado!$C$2:$C$65,"Unitário",Pareado!$D$2:$D$65,"COT") -> 4 | U6: =COUNTIFS(Pareado!$F$2:$F$65,"Limpo",Pareado!$C$2:$C$65,"Unitário",Pareado!$D$2:$D$65,"COT",Pareado!$AF$2:$AF$65,"ChatGPT") -> 7 | V6: =COUNTIFS(Pareado!$F$2:$F$65,"Limpo",Pareado!$C$2:$C$65,"Unitário",Pareado!$D$2:$D$65,"COT",Pareado!$AF$2:$AF$65,"empate") -> 0 | W6: =COUNTIFS(Pareado!$F$2:$F$65,"Limpo",Pareado!$C$2:$C$65,"Unitário",Pareado!$D$2:$D$65,"COT",Pareado!$AF$2:$AF$65,"Gemini") -> 0 | X6: =COUNTIFS(Pareado!$F$2:$F$65,"Limpo",Pareado!$C$2:$C$65,"Unitário",Pareado!$D$2:$D$65,"COT",Pareado!$AG$2:$AG$65,"ChatGPT") -> 0 | Y6: =COUNTIFS(Pareado!$F$2:$F$65,"Limpo",Pareado!$C$2:$C$65,"Unitário",Pareado!$D$2:$D$65,"COT",Pareado!$AG$2:$AG$65,"empate") -> 6 | Z6: =COUNTIFS(Pareado!$F$2:$F$65,"Limpo",Pareado!$C$2:$C$65,"Unitário",Pareado!$D$2:$D$65,"COT",Pareado!$AG$2:$AG$65,"Gemini") -> 1
A7: Limpo | B7: Unitário | C7: Todas | D7: =COUNTIFS(Pareado!$F$2:$F$65,"Limpo",Pareado!$C$2:$C$65,"Unitário") -> 21 | E7: =SUMIFS(Pareado!$I$2:$I$65,Pareado!$F$2:$F$65,"Limpo",Pareado!$C$2:$C$65,"Unitário") -> 374 | F7: =SUMIFS(Pareado!$J$2:$J$65,Pareado!$F$2:$F$65,"Limpo",Pareado!$C$2:$C$65,"Unitário") -> 373 | G7: =IFERROR(F7/(F7+SUMIFS(Pareado!$K$2:$K$65,Pareado!$F$2:$F$65,"Limpo",Pareado!$C$2:$C$65,"Unitário",Pareado!$O$2:$O$65,"executa")),0) -> 0.9973262 | H7: =COUNTIFS(Pareado!$F$2:$F$65,"Limpo",Pareado!$C$2:$C$65,"Unitário",Pareado!$L$2:$L$65,1) -> 20 | I7: =SUMIFS(Pareado!$M$2:$M$65,Pareado!$F$2:$F$65,"Limpo",Pareado!$C$2:$C$65,"Unitário") -> 6 | J7: =COUNTIFS(Pareado!$F$2:$F$65,"Limpo",Pareado!$C$2:$C$65,"Unitário",Pareado!$M$2:$M$65,3) -> 0 | K7: =COUNTIFS(Pareado!$F$2:$F$65,"Limpo",Pareado!$C$2:$C$65,"Unitário",Pareado!$O$2:$O$65,"<>executa") -> 0 | L7: =COUNTIFS(Pareado!$F$2:$F$65,"Limpo",Pareado!$C$2:$C$65,"Unitário",Pareado!$P$2:$P$65,"Sim") -> 0 | M7: =SUMIFS(Pareado!$S$2:$S$65,Pareado!$F$2:$F$65,"Limpo",Pareado!$C$2:$C$65,"Unitário") -> 264 | N7: =SUMIFS(Pareado!$T$2:$T$65,Pareado!$F$2:$F$65,"Limpo",Pareado!$C$2:$C$65,"Unitário") -> 264 | O7: =IFERROR(N7/(N7+SUMIFS(Pareado!$U$2:$U$65,Pareado!$F$2:$F$65,"Limpo",Pareado!$C$2:$C$65,"Unitário",Pareado!$Y$2:$Y$65,"executa")),0) -> 1 | P7: =COUNTIFS(Pareado!$F$2:$F$65,"Limpo",Pareado!$C$2:$C$65,"Unitário",Pareado!$V$2:$V$65,1) -> 21 | Q7: =SUMIFS(Pareado!$W$2:$W$65,Pareado!$F$2:$F$65,"Limpo",Pareado!$C$2:$C$65,"Unitário") -> 2 | R7: =COUNTIFS(Pareado!$F$2:$F$65,"Limpo",Pareado!$C$2:$C$65,"Unitário",Pareado!$W$2:$W$65,3) -> 0 | S7: =COUNTIFS(Pareado!$F$2:$F$65,"Limpo",Pareado!$C$2:$C$65,"Unitário",Pareado!$Y$2:$Y$65,"<>executa") -> 0 | T7: =SUMIFS(Pareado!$AA$2:$AA$65,Pareado!$F$2:$F$65,"Limpo",Pareado!$C$2:$C$65,"Unitário") -> 10 | U7: =COUNTIFS(Pareado!$F$2:$F$65,"Limpo",Pareado!$C$2:$C$65,"Unitário",Pareado!$AF$2:$AF$65,"ChatGPT") -> 16 | V7: =COUNTIFS(Pareado!$F$2:$F$65,"Limpo",Pareado!$C$2:$C$65,"Unitário",Pareado!$AF$2:$AF$65,"empate") -> 0 | W7: =COUNTIFS(Pareado!$F$2:$F$65,"Limpo",Pareado!$C$2:$C$65,"Unitário",Pareado!$AF$2:$AF$65,"Gemini") -> 5 | X7: =COUNTIFS(Pareado!$F$2:$F$65,"Limpo",Pareado!$C$2:$C$65,"Unitário",Pareado!$AG$2:$AG$65,"ChatGPT") -> 0 | Y7: =COUNTIFS(Pareado!$F$2:$F$65,"Limpo",Pareado!$C$2:$C$65,"Unitário",Pareado!$AG$2:$AG$65,"empate") -> 20 | Z7: =COUNTIFS(Pareado!$F$2:$F$65,"Limpo",Pareado!$C$2:$C$65,"Unitário",Pareado!$AG$2:$AG$65,"Gemini") -> 1
A8: Limpo | B8: Widget | C8: ZS | D8: =COUNTIFS(Pareado!$F$2:$F$65,"Limpo",Pareado!$C$2:$C$65,"Widget",Pareado!$D$2:$D$65,"ZS") -> 3 | E8: =SUMIFS(Pareado!$I$2:$I$65,Pareado!$F$2:$F$65,"Limpo",Pareado!$C$2:$C$65,"Widget",Pareado!$D$2:$D$65,"ZS") -> 42 | F8: =SUMIFS(Pareado!$J$2:$J$65,Pareado!$F$2:$F$65,"Limpo",Pareado!$C$2:$C$65,"Widget",Pareado!$D$2:$D$65,"ZS") -> 40 | G8: =IFERROR(F8/(F8+SUMIFS(Pareado!$K$2:$K$65,Pareado!$F$2:$F$65,"Limpo",Pareado!$C$2:$C$65,"Widget",Pareado!$D$2:$D$65,"ZS",Pareado!$O$2:$O$65,"executa")),0) -> 0.95238095 | H8: =COUNTIFS(Pareado!$F$2:$F$65,"Limpo",Pareado!$C$2:$C$65,"Widget",Pareado!$D$2:$D$65,"ZS",Pareado!$L$2:$L$65,1) -> 1 | I8: =SUMIFS(Pareado!$M$2:$M$65,Pareado!$F$2:$F$65,"Limpo",Pareado!$C$2:$C$65,"Widget",Pareado!$D$2:$D$65,"ZS") -> 6 | J8: =COUNTIFS(Pareado!$F$2:$F$65,"Limpo",Pareado!$C$2:$C$65,"Widget",Pareado!$D$2:$D$65,"ZS",Pareado!$M$2:$M$65,3) -> 1 | K8: =COUNTIFS(Pareado!$F$2:$F$65,"Limpo",Pareado!$C$2:$C$65,"Widget",Pareado!$D$2:$D$65,"ZS",Pareado!$O$2:$O$65,"<>executa") -> 0 | L8: =COUNTIFS(Pareado!$F$2:$F$65,"Limpo",Pareado!$C$2:$C$65,"Widget",Pareado!$D$2:$D$65,"ZS",Pareado!$P$2:$P$65,"Sim") -> 1 | M8: =SUMIFS(Pareado!$S$2:$S$65,Pareado!$F$2:$F$65,"Limpo",Pareado!$C$2:$C$65,"Widget",Pareado!$D$2:$D$65,"ZS") -> 19 | N8: =SUMIFS(Pareado!$T$2:$T$65,Pareado!$F$2:$F$65,"Limpo",Pareado!$C$2:$C$65,"Widget",Pareado!$D$2:$D$65,"ZS") -> 19 | O8: =IFERROR(N8/(N8+SUMIFS(Pareado!$U$2:$U$65,Pareado!$F$2:$F$65,"Limpo",Pareado!$C$2:$C$65,"Widget",Pareado!$D$2:$D$65,"ZS",Pareado!$Y$2:$Y$65,"executa")),0) -> 1 | P8: =COUNTIFS(Pareado!$F$2:$F$65,"Limpo",Pareado!$C$2:$C$65,"Widget",Pareado!$D$2:$D$65,"ZS",Pareado!$V$2:$V$65,1) -> 3 | Q8: =SUMIFS(Pareado!$W$2:$W$65,Pareado!$F$2:$F$65,"Limpo",Pareado!$C$2:$C$65,"Widget",Pareado!$D$2:$D$65,"ZS") -> 5 | R8: =COUNTIFS(Pareado!$F$2:$F$65,"Limpo",Pareado!$C$2:$C$65,"Widget",Pareado!$D$2:$D$65,"ZS",Pareado!$W$2:$W$65,3) -> 1 | S8: =COUNTIFS(Pareado!$F$2:$F$65,"Limpo",Pareado!$C$2:$C$65,"Widget",Pareado!$D$2:$D$65,"ZS",Pareado!$Y$2:$Y$65,"<>executa") -> 0 | T8: =SUMIFS(Pareado!$AA$2:$AA$65,Pareado!$F$2:$F$65,"Limpo",Pareado!$C$2:$C$65,"Widget",Pareado!$D$2:$D$65,"ZS") -> 0 | U8: =COUNTIFS(Pareado!$F$2:$F$65,"Limpo",Pareado!$C$2:$C$65,"Widget",Pareado!$D$2:$D$65,"ZS",Pareado!$AF$2:$AF$65,"ChatGPT") -> 3 | V8: =COUNTIFS(Pareado!$F$2:$F$65,"Limpo",Pareado!$C$2:$C$65,"Widget",Pareado!$D$2:$D$65,"ZS",Pareado!$AF$2:$AF$65,"empate") -> 0 | W8: =COUNTIFS(Pareado!$F$2:$F$65,"Limpo",Pareado!$C$2:$C$65,"Widget",Pareado!$D$2:$D$65,"ZS",Pareado!$AF$2:$AF$65,"Gemini") -> 0 | X8: =COUNTIFS(Pareado!$F$2:$F$65,"Limpo",Pareado!$C$2:$C$65,"Widget",Pareado!$D$2:$D$65,"ZS",Pareado!$AG$2:$AG$65,"ChatGPT") -> 0 | Y8: =COUNTIFS(Pareado!$F$2:$F$65,"Limpo",Pareado!$C$2:$C$65,"Widget",Pareado!$D$2:$D$65,"ZS",Pareado!$AG$2:$AG$65,"empate") -> 1 | Z8: =COUNTIFS(Pareado!$F$2:$F$65,"Limpo",Pareado!$C$2:$C$65,"Widget",Pareado!$D$2:$D$65,"ZS",Pareado!$AG$2:$AG$65,"Gemini") -> 2
A9: Limpo | B9: Widget | C9: FS | D9: =COUNTIFS(Pareado!$F$2:$F$65,"Limpo",Pareado!$C$2:$C$65,"Widget",Pareado!$D$2:$D$65,"FS") -> 3 | E9: =SUMIFS(Pareado!$I$2:$I$65,Pareado!$F$2:$F$65,"Limpo",Pareado!$C$2:$C$65,"Widget",Pareado!$D$2:$D$65,"FS") -> 48 | F9: =SUMIFS(Pareado!$J$2:$J$65,Pareado!$F$2:$F$65,"Limpo",Pareado!$C$2:$C$65,"Widget",Pareado!$D$2:$D$65,"FS") -> 39 | G9: =IFERROR(F9/(F9+SUMIFS(Pareado!$K$2:$K$65,Pareado!$F$2:$F$65,"Limpo",Pareado!$C$2:$C$65,"Widget",Pareado!$D$2:$D$65,"FS",Pareado!$O$2:$O$65,"executa")),0) -> 0.8125 | H9: =COUNTIFS(Pareado!$F$2:$F$65,"Limpo",Pareado!$C$2:$C$65,"Widget",Pareado!$D$2:$D$65,"FS",Pareado!$L$2:$L$65,1) -> 0 | I9: =SUMIFS(Pareado!$M$2:$M$65,Pareado!$F$2:$F$65,"Limpo",Pareado!$C$2:$C$65,"Widget",Pareado!$D$2:$D$65,"FS") -> 9 | J9: =COUNTIFS(Pareado!$F$2:$F$65,"Limpo",Pareado!$C$2:$C$65,"Widget",Pareado!$D$2:$D$65,"FS",Pareado!$M$2:$M$65,3) -> 3 | K9: =COUNTIFS(Pareado!$F$2:$F$65,"Limpo",Pareado!$C$2:$C$65,"Widget",Pareado!$D$2:$D$65,"FS",Pareado!$O$2:$O$65,"<>executa") -> 0 | L9: =COUNTIFS(Pareado!$F$2:$F$65,"Limpo",Pareado!$C$2:$C$65,"Widget",Pareado!$D$2:$D$65,"FS",Pareado!$P$2:$P$65,"Sim") -> 0 | M9: =SUMIFS(Pareado!$S$2:$S$65,Pareado!$F$2:$F$65,"Limpo",Pareado!$C$2:$C$65,"Widget",Pareado!$D$2:$D$65,"FS") -> 21 | N9: =SUMIFS(Pareado!$T$2:$T$65,Pareado!$F$2:$F$65,"Limpo",Pareado!$C$2:$C$65,"Widget",Pareado!$D$2:$D$65,"FS") -> 21 | O9: =IFERROR(N9/(N9+SUMIFS(Pareado!$U$2:$U$65,Pareado!$F$2:$F$65,"Limpo",Pareado!$C$2:$C$65,"Widget",Pareado!$D$2:$D$65,"FS",Pareado!$Y$2:$Y$65,"executa")),0) -> 1 | P9: =COUNTIFS(Pareado!$F$2:$F$65,"Limpo",Pareado!$C$2:$C$65,"Widget",Pareado!$D$2:$D$65,"FS",Pareado!$V$2:$V$65,1) -> 3 | Q9: =SUMIFS(Pareado!$W$2:$W$65,Pareado!$F$2:$F$65,"Limpo",Pareado!$C$2:$C$65,"Widget",Pareado!$D$2:$D$65,"FS") -> 3 | R9: =COUNTIFS(Pareado!$F$2:$F$65,"Limpo",Pareado!$C$2:$C$65,"Widget",Pareado!$D$2:$D$65,"FS",Pareado!$W$2:$W$65,3) -> 0 | S9: =COUNTIFS(Pareado!$F$2:$F$65,"Limpo",Pareado!$C$2:$C$65,"Widget",Pareado!$D$2:$D$65,"FS",Pareado!$Y$2:$Y$65,"<>executa") -> 0 | T9: =SUMIFS(Pareado!$AA$2:$AA$65,Pareado!$F$2:$F$65,"Limpo",Pareado!$C$2:$C$65,"Widget",Pareado!$D$2:$D$65,"FS") -> 3 | U9: =COUNTIFS(Pareado!$F$2:$F$65,"Limpo",Pareado!$C$2:$C$65,"Widget",Pareado!$D$2:$D$65,"FS",Pareado!$AF$2:$AF$65,"ChatGPT") -> 3 | V9: =COUNTIFS(Pareado!$F$2:$F$65,"Limpo",Pareado!$C$2:$C$65,"Widget",Pareado!$D$2:$D$65,"FS",Pareado!$AF$2:$AF$65,"empate") -> 0 | W9: =COUNTIFS(Pareado!$F$2:$F$65,"Limpo",Pareado!$C$2:$C$65,"Widget",Pareado!$D$2:$D$65,"FS",Pareado!$AF$2:$AF$65,"Gemini") -> 0 | X9: =COUNTIFS(Pareado!$F$2:$F$65,"Limpo",Pareado!$C$2:$C$65,"Widget",Pareado!$D$2:$D$65,"FS",Pareado!$AG$2:$AG$65,"ChatGPT") -> 0 | Y9: =COUNTIFS(Pareado!$F$2:$F$65,"Limpo",Pareado!$C$2:$C$65,"Widget",Pareado!$D$2:$D$65,"FS",Pareado!$AG$2:$AG$65,"empate") -> 0 | Z9: =COUNTIFS(Pareado!$F$2:$F$65,"Limpo",Pareado!$C$2:$C$65,"Widget",Pareado!$D$2:$D$65,"FS",Pareado!$AG$2:$AG$65,"Gemini") -> 3
A10: Limpo | B10: Widget | C10: COT | D10: =COUNTIFS(Pareado!$F$2:$F$65,"Limpo",Pareado!$C$2:$C$65,"Widget",Pareado!$D$2:$D$65,"COT") -> 3 | E10: =SUMIFS(Pareado!$I$2:$I$65,Pareado!$F$2:$F$65,"Limpo",Pareado!$C$2:$C$65,"Widget",Pareado!$D$2:$D$65,"COT") -> 62 | F10: =SUMIFS(Pareado!$J$2:$J$65,Pareado!$F$2:$F$65,"Limpo",Pareado!$C$2:$C$65,"Widget",Pareado!$D$2:$D$65,"COT") -> 34 | G10: =IFERROR(F10/(F10+SUMIFS(Pareado!$K$2:$K$65,Pareado!$F$2:$F$65,"Limpo",Pareado!$C$2:$C$65,"Widget",Pareado!$D$2:$D$65,"COT",Pareado!$O$2:$O$65,"executa")),0) -> 0.91891892 | H10: =COUNTIFS(Pareado!$F$2:$F$65,"Limpo",Pareado!$C$2:$C$65,"Widget",Pareado!$D$2:$D$65,"COT",Pareado!$L$2:$L$65,1) -> 1 | I10: =SUMIFS(Pareado!$M$2:$M$65,Pareado!$F$2:$F$65,"Limpo",Pareado!$C$2:$C$65,"Widget",Pareado!$D$2:$D$65,"COT") -> 9 | J10: =COUNTIFS(Pareado!$F$2:$F$65,"Limpo",Pareado!$C$2:$C$65,"Widget",Pareado!$D$2:$D$65,"COT",Pareado!$M$2:$M$65,3) -> 3 | K10: =COUNTIFS(Pareado!$F$2:$F$65,"Limpo",Pareado!$C$2:$C$65,"Widget",Pareado!$D$2:$D$65,"COT",Pareado!$O$2:$O$65,"<>executa") -> 1 | L10: =COUNTIFS(Pareado!$F$2:$F$65,"Limpo",Pareado!$C$2:$C$65,"Widget",Pareado!$D$2:$D$65,"COT",Pareado!$P$2:$P$65,"Sim") -> 1 | M10: =SUMIFS(Pareado!$S$2:$S$65,Pareado!$F$2:$F$65,"Limpo",Pareado!$C$2:$C$65,"Widget",Pareado!$D$2:$D$65,"COT") -> 31 | N10: =SUMIFS(Pareado!$T$2:$T$65,Pareado!$F$2:$F$65,"Limpo",Pareado!$C$2:$C$65,"Widget",Pareado!$D$2:$D$65,"COT") -> 15 | O10: =IFERROR(N10/(N10+SUMIFS(Pareado!$U$2:$U$65,Pareado!$F$2:$F$65,"Limpo",Pareado!$C$2:$C$65,"Widget",Pareado!$D$2:$D$65,"COT",Pareado!$Y$2:$Y$65,"executa")),0) -> 0.48387097 | P10: =COUNTIFS(Pareado!$F$2:$F$65,"Limpo",Pareado!$C$2:$C$65,"Widget",Pareado!$D$2:$D$65,"COT",Pareado!$V$2:$V$65,1) -> 0 | Q10: =SUMIFS(Pareado!$W$2:$W$65,Pareado!$F$2:$F$65,"Limpo",Pareado!$C$2:$C$65,"Widget",Pareado!$D$2:$D$65,"COT") -> 9 | R10: =COUNTIFS(Pareado!$F$2:$F$65,"Limpo",Pareado!$C$2:$C$65,"Widget",Pareado!$D$2:$D$65,"COT",Pareado!$W$2:$W$65,3) -> 3 | S10: =COUNTIFS(Pareado!$F$2:$F$65,"Limpo",Pareado!$C$2:$C$65,"Widget",Pareado!$D$2:$D$65,"COT",Pareado!$Y$2:$Y$65,"<>executa") -> 0 | T10: =SUMIFS(Pareado!$AA$2:$AA$65,Pareado!$F$2:$F$65,"Limpo",Pareado!$C$2:$C$65,"Widget",Pareado!$D$2:$D$65,"COT") -> 3 | U10: =COUNTIFS(Pareado!$F$2:$F$65,"Limpo",Pareado!$C$2:$C$65,"Widget",Pareado!$D$2:$D$65,"COT",Pareado!$AF$2:$AF$65,"ChatGPT") -> 3 | V10: =COUNTIFS(Pareado!$F$2:$F$65,"Limpo",Pareado!$C$2:$C$65,"Widget",Pareado!$D$2:$D$65,"COT",Pareado!$AF$2:$AF$65,"empate") -> 0 | W10: =COUNTIFS(Pareado!$F$2:$F$65,"Limpo",Pareado!$C$2:$C$65,"Widget",Pareado!$D$2:$D$65,"COT",Pareado!$AF$2:$AF$65,"Gemini") -> 0 | X10: =COUNTIFS(Pareado!$F$2:$F$65,"Limpo",Pareado!$C$2:$C$65,"Widget",Pareado!$D$2:$D$65,"COT",Pareado!$AG$2:$AG$65,"ChatGPT") -> 1 | Y10: =COUNTIFS(Pareado!$F$2:$F$65,"Limpo",Pareado!$C$2:$C$65,"Widget",Pareado!$D$2:$D$65,"COT",Pareado!$AG$2:$AG$65,"empate") -> 1 | Z10: =COUNTIFS(Pareado!$F$2:$F$65,"Limpo",Pareado!$C$2:$C$65,"Widget",Pareado!$D$2:$D$65,"COT",Pareado!$AG$2:$AG$65,"Gemini") -> 1
A11: Limpo | B11: Widget | C11: Todas | D11: =COUNTIFS(Pareado!$F$2:$F$65,"Limpo",Pareado!$C$2:$C$65,"Widget") -> 9 | E11: =SUMIFS(Pareado!$I$2:$I$65,Pareado!$F$2:$F$65,"Limpo",Pareado!$C$2:$C$65,"Widget") -> 152 | F11: =SUMIFS(Pareado!$J$2:$J$65,Pareado!$F$2:$F$65,"Limpo",Pareado!$C$2:$C$65,"Widget") -> 113 | G11: =IFERROR(F11/(F11+SUMIFS(Pareado!$K$2:$K$65,Pareado!$F$2:$F$65,"Limpo",Pareado!$C$2:$C$65,"Widget",Pareado!$O$2:$O$65,"executa")),0) -> 0.88976378 | H11: =COUNTIFS(Pareado!$F$2:$F$65,"Limpo",Pareado!$C$2:$C$65,"Widget",Pareado!$L$2:$L$65,1) -> 2 | I11: =SUMIFS(Pareado!$M$2:$M$65,Pareado!$F$2:$F$65,"Limpo",Pareado!$C$2:$C$65,"Widget") -> 24 | J11: =COUNTIFS(Pareado!$F$2:$F$65,"Limpo",Pareado!$C$2:$C$65,"Widget",Pareado!$M$2:$M$65,3) -> 7 | K11: =COUNTIFS(Pareado!$F$2:$F$65,"Limpo",Pareado!$C$2:$C$65,"Widget",Pareado!$O$2:$O$65,"<>executa") -> 1 | L11: =COUNTIFS(Pareado!$F$2:$F$65,"Limpo",Pareado!$C$2:$C$65,"Widget",Pareado!$P$2:$P$65,"Sim") -> 2 | M11: =SUMIFS(Pareado!$S$2:$S$65,Pareado!$F$2:$F$65,"Limpo",Pareado!$C$2:$C$65,"Widget") -> 71 | N11: =SUMIFS(Pareado!$T$2:$T$65,Pareado!$F$2:$F$65,"Limpo",Pareado!$C$2:$C$65,"Widget") -> 55 | O11: =IFERROR(N11/(N11+SUMIFS(Pareado!$U$2:$U$65,Pareado!$F$2:$F$65,"Limpo",Pareado!$C$2:$C$65,"Widget",Pareado!$Y$2:$Y$65,"executa")),0) -> 0.77464789 | P11: =COUNTIFS(Pareado!$F$2:$F$65,"Limpo",Pareado!$C$2:$C$65,"Widget",Pareado!$V$2:$V$65,1) -> 6 | Q11: =SUMIFS(Pareado!$W$2:$W$65,Pareado!$F$2:$F$65,"Limpo",Pareado!$C$2:$C$65,"Widget") -> 17 | R11: =COUNTIFS(Pareado!$F$2:$F$65,"Limpo",Pareado!$C$2:$C$65,"Widget",Pareado!$W$2:$W$65,3) -> 4 | S11: =COUNTIFS(Pareado!$F$2:$F$65,"Limpo",Pareado!$C$2:$C$65,"Widget",Pareado!$Y$2:$Y$65,"<>executa") -> 0 | T11: =SUMIFS(Pareado!$AA$2:$AA$65,Pareado!$F$2:$F$65,"Limpo",Pareado!$C$2:$C$65,"Widget") -> 6 | U11: =COUNTIFS(Pareado!$F$2:$F$65,"Limpo",Pareado!$C$2:$C$65,"Widget",Pareado!$AF$2:$AF$65,"ChatGPT") -> 9 | V11: =COUNTIFS(Pareado!$F$2:$F$65,"Limpo",Pareado!$C$2:$C$65,"Widget",Pareado!$AF$2:$AF$65,"empate") -> 0 | W11: =COUNTIFS(Pareado!$F$2:$F$65,"Limpo",Pareado!$C$2:$C$65,"Widget",Pareado!$AF$2:$AF$65,"Gemini") -> 0 | X11: =COUNTIFS(Pareado!$F$2:$F$65,"Limpo",Pareado!$C$2:$C$65,"Widget",Pareado!$AG$2:$AG$65,"ChatGPT") -> 1 | Y11: =COUNTIFS(Pareado!$F$2:$F$65,"Limpo",Pareado!$C$2:$C$65,"Widget",Pareado!$AG$2:$AG$65,"empate") -> 2 | Z11: =COUNTIFS(Pareado!$F$2:$F$65,"Limpo",Pareado!$C$2:$C$65,"Widget",Pareado!$AG$2:$AG$65,"Gemini") -> 6
A12: Limpo | B12: Integração | C12: ZS | D12: =COUNTIFS(Pareado!$F$2:$F$65,"Limpo",Pareado!$C$2:$C$65,"Integração",Pareado!$D$2:$D$65,"ZS") -> 3 | E12: =SUMIFS(Pareado!$I$2:$I$65,Pareado!$F$2:$F$65,"Limpo",Pareado!$C$2:$C$65,"Integração",Pareado!$D$2:$D$65,"ZS") -> 14 | F12: =SUMIFS(Pareado!$J$2:$J$65,Pareado!$F$2:$F$65,"Limpo",Pareado!$C$2:$C$65,"Integração",Pareado!$D$2:$D$65,"ZS") -> 11 | G12: =IFERROR(F12/(F12+SUMIFS(Pareado!$K$2:$K$65,Pareado!$F$2:$F$65,"Limpo",Pareado!$C$2:$C$65,"Integração",Pareado!$D$2:$D$65,"ZS",Pareado!$O$2:$O$65,"executa")),0) -> 0.78571429 | H12: =COUNTIFS(Pareado!$F$2:$F$65,"Limpo",Pareado!$C$2:$C$65,"Integração",Pareado!$D$2:$D$65,"ZS",Pareado!$L$2:$L$65,1) -> 1 | I12: =SUMIFS(Pareado!$M$2:$M$65,Pareado!$F$2:$F$65,"Limpo",Pareado!$C$2:$C$65,"Integração",Pareado!$D$2:$D$65,"ZS") -> 6 | J12: =COUNTIFS(Pareado!$F$2:$F$65,"Limpo",Pareado!$C$2:$C$65,"Integração",Pareado!$D$2:$D$65,"ZS",Pareado!$M$2:$M$65,3) -> 2 | K12: =COUNTIFS(Pareado!$F$2:$F$65,"Limpo",Pareado!$C$2:$C$65,"Integração",Pareado!$D$2:$D$65,"ZS",Pareado!$O$2:$O$65,"<>executa") -> 0 | L12: =COUNTIFS(Pareado!$F$2:$F$65,"Limpo",Pareado!$C$2:$C$65,"Integração",Pareado!$D$2:$D$65,"ZS",Pareado!$P$2:$P$65,"Sim") -> 0 | M12: =SUMIFS(Pareado!$S$2:$S$65,Pareado!$F$2:$F$65,"Limpo",Pareado!$C$2:$C$65,"Integração",Pareado!$D$2:$D$65,"ZS") -> 14 | N12: =SUMIFS(Pareado!$T$2:$T$65,Pareado!$F$2:$F$65,"Limpo",Pareado!$C$2:$C$65,"Integração",Pareado!$D$2:$D$65,"ZS") -> 9 | O12: =IFERROR(N12/(N12+SUMIFS(Pareado!$U$2:$U$65,Pareado!$F$2:$F$65,"Limpo",Pareado!$C$2:$C$65,"Integração",Pareado!$D$2:$D$65,"ZS",Pareado!$Y$2:$Y$65,"executa")),0) -> 0.9 | P12: =COUNTIFS(Pareado!$F$2:$F$65,"Limpo",Pareado!$C$2:$C$65,"Integração",Pareado!$D$2:$D$65,"ZS",Pareado!$V$2:$V$65,1) -> 1 | Q12: =SUMIFS(Pareado!$W$2:$W$65,Pareado!$F$2:$F$65,"Limpo",Pareado!$C$2:$C$65,"Integração",Pareado!$D$2:$D$65,"ZS") -> 6 | R12: =COUNTIFS(Pareado!$F$2:$F$65,"Limpo",Pareado!$C$2:$C$65,"Integração",Pareado!$D$2:$D$65,"ZS",Pareado!$W$2:$W$65,3) -> 2 | S12: =COUNTIFS(Pareado!$F$2:$F$65,"Limpo",Pareado!$C$2:$C$65,"Integração",Pareado!$D$2:$D$65,"ZS",Pareado!$Y$2:$Y$65,"<>executa") -> 1 | T12: =SUMIFS(Pareado!$AA$2:$AA$65,Pareado!$F$2:$F$65,"Limpo",Pareado!$C$2:$C$65,"Integração",Pareado!$D$2:$D$65,"ZS") -> 0 | U12: =COUNTIFS(Pareado!$F$2:$F$65,"Limpo",Pareado!$C$2:$C$65,"Integração",Pareado!$D$2:$D$65,"ZS",Pareado!$AF$2:$AF$65,"ChatGPT") -> 1 | V12: =COUNTIFS(Pareado!$F$2:$F$65,"Limpo",Pareado!$C$2:$C$65,"Integração",Pareado!$D$2:$D$65,"ZS",Pareado!$AF$2:$AF$65,"empate") -> 1 | W12: =COUNTIFS(Pareado!$F$2:$F$65,"Limpo",Pareado!$C$2:$C$65,"Integração",Pareado!$D$2:$D$65,"ZS",Pareado!$AF$2:$AF$65,"Gemini") -> 1 | X12: =COUNTIFS(Pareado!$F$2:$F$65,"Limpo",Pareado!$C$2:$C$65,"Integração",Pareado!$D$2:$D$65,"ZS",Pareado!$AG$2:$AG$65,"ChatGPT") -> 2 | Y12: =COUNTIFS(Pareado!$F$2:$F$65,"Limpo",Pareado!$C$2:$C$65,"Integração",Pareado!$D$2:$D$65,"ZS",Pareado!$AG$2:$AG$65,"empate") -> 1 | Z12: =COUNTIFS(Pareado!$F$2:$F$65,"Limpo",Pareado!$C$2:$C$65,"Integração",Pareado!$D$2:$D$65,"ZS",Pareado!$AG$2:$AG$65,"Gemini") -> 0
A13: Limpo | B13: Integração | C13: FS | D13: =COUNTIFS(Pareado!$F$2:$F$65,"Limpo",Pareado!$C$2:$C$65,"Integração",Pareado!$D$2:$D$65,"FS") -> 3 | E13: =SUMIFS(Pareado!$I$2:$I$65,Pareado!$F$2:$F$65,"Limpo",Pareado!$C$2:$C$65,"Integração",Pareado!$D$2:$D$65,"FS") -> 11 | F13: =SUMIFS(Pareado!$J$2:$J$65,Pareado!$F$2:$F$65,"Limpo",Pareado!$C$2:$C$65,"Integração",Pareado!$D$2:$D$65,"FS") -> 8 | G13: =IFERROR(F13/(F13+SUMIFS(Pareado!$K$2:$K$65,Pareado!$F$2:$F$65,"Limpo",Pareado!$C$2:$C$65,"Integração",Pareado!$D$2:$D$65,"FS",Pareado!$O$2:$O$65,"executa")),0) -> 0.72727273 | H13: =COUNTIFS(Pareado!$F$2:$F$65,"Limpo",Pareado!$C$2:$C$65,"Integração",Pareado!$D$2:$D$65,"FS",Pareado!$L$2:$L$65,1) -> 1 | I13: =SUMIFS(Pareado!$M$2:$M$65,Pareado!$F$2:$F$65,"Limpo",Pareado!$C$2:$C$65,"Integração",Pareado!$D$2:$D$65,"FS") -> 7 | J13: =COUNTIFS(Pareado!$F$2:$F$65,"Limpo",Pareado!$C$2:$C$65,"Integração",Pareado!$D$2:$D$65,"FS",Pareado!$M$2:$M$65,3) -> 2 | K13: =COUNTIFS(Pareado!$F$2:$F$65,"Limpo",Pareado!$C$2:$C$65,"Integração",Pareado!$D$2:$D$65,"FS",Pareado!$O$2:$O$65,"<>executa") -> 0 | L13: =COUNTIFS(Pareado!$F$2:$F$65,"Limpo",Pareado!$C$2:$C$65,"Integração",Pareado!$D$2:$D$65,"FS",Pareado!$P$2:$P$65,"Sim") -> 1 | M13: =SUMIFS(Pareado!$S$2:$S$65,Pareado!$F$2:$F$65,"Limpo",Pareado!$C$2:$C$65,"Integração",Pareado!$D$2:$D$65,"FS") -> 8 | N13: =SUMIFS(Pareado!$T$2:$T$65,Pareado!$F$2:$F$65,"Limpo",Pareado!$C$2:$C$65,"Integração",Pareado!$D$2:$D$65,"FS") -> 3 | O13: =IFERROR(N13/(N13+SUMIFS(Pareado!$U$2:$U$65,Pareado!$F$2:$F$65,"Limpo",Pareado!$C$2:$C$65,"Integração",Pareado!$D$2:$D$65,"FS",Pareado!$Y$2:$Y$65,"executa")),0) -> 0.375 | P13: =COUNTIFS(Pareado!$F$2:$F$65,"Limpo",Pareado!$C$2:$C$65,"Integração",Pareado!$D$2:$D$65,"FS",Pareado!$V$2:$V$65,1) -> 1 | Q13: =SUMIFS(Pareado!$W$2:$W$65,Pareado!$F$2:$F$65,"Limpo",Pareado!$C$2:$C$65,"Integração",Pareado!$D$2:$D$65,"FS") -> 6 | R13: =COUNTIFS(Pareado!$F$2:$F$65,"Limpo",Pareado!$C$2:$C$65,"Integração",Pareado!$D$2:$D$65,"FS",Pareado!$W$2:$W$65,3) -> 2 | S13: =COUNTIFS(Pareado!$F$2:$F$65,"Limpo",Pareado!$C$2:$C$65,"Integração",Pareado!$D$2:$D$65,"FS",Pareado!$Y$2:$Y$65,"<>executa") -> 0 | T13: =SUMIFS(Pareado!$AA$2:$AA$65,Pareado!$F$2:$F$65,"Limpo",Pareado!$C$2:$C$65,"Integração",Pareado!$D$2:$D$65,"FS") -> 1 | U13: =COUNTIFS(Pareado!$F$2:$F$65,"Limpo",Pareado!$C$2:$C$65,"Integração",Pareado!$D$2:$D$65,"FS",Pareado!$AF$2:$AF$65,"ChatGPT") -> 2 | V13: =COUNTIFS(Pareado!$F$2:$F$65,"Limpo",Pareado!$C$2:$C$65,"Integração",Pareado!$D$2:$D$65,"FS",Pareado!$AF$2:$AF$65,"empate") -> 1 | W13: =COUNTIFS(Pareado!$F$2:$F$65,"Limpo",Pareado!$C$2:$C$65,"Integração",Pareado!$D$2:$D$65,"FS",Pareado!$AF$2:$AF$65,"Gemini") -> 0 | X13: =COUNTIFS(Pareado!$F$2:$F$65,"Limpo",Pareado!$C$2:$C$65,"Integração",Pareado!$D$2:$D$65,"FS",Pareado!$AG$2:$AG$65,"ChatGPT") -> 1 | Y13: =COUNTIFS(Pareado!$F$2:$F$65,"Limpo",Pareado!$C$2:$C$65,"Integração",Pareado!$D$2:$D$65,"FS",Pareado!$AG$2:$AG$65,"empate") -> 1 | Z13: =COUNTIFS(Pareado!$F$2:$F$65,"Limpo",Pareado!$C$2:$C$65,"Integração",Pareado!$D$2:$D$65,"FS",Pareado!$AG$2:$AG$65,"Gemini") -> 1
A14: Limpo | B14: Integração | C14: COT | D14: =COUNTIFS(Pareado!$F$2:$F$65,"Limpo",Pareado!$C$2:$C$65,"Integração",Pareado!$D$2:$D$65,"COT") -> 3 | E14: =SUMIFS(Pareado!$I$2:$I$65,Pareado!$F$2:$F$65,"Limpo",Pareado!$C$2:$C$65,"Integração",Pareado!$D$2:$D$65,"COT") -> 25 | F14: =SUMIFS(Pareado!$J$2:$J$65,Pareado!$F$2:$F$65,"Limpo",Pareado!$C$2:$C$65,"Integração",Pareado!$D$2:$D$65,"COT") -> 24 | G14: =IFERROR(F14/(F14+SUMIFS(Pareado!$K$2:$K$65,Pareado!$F$2:$F$65,"Limpo",Pareado!$C$2:$C$65,"Integração",Pareado!$D$2:$D$65,"COT",Pareado!$O$2:$O$65,"executa")),0) -> 0.96 | H14: =COUNTIFS(Pareado!$F$2:$F$65,"Limpo",Pareado!$C$2:$C$65,"Integração",Pareado!$D$2:$D$65,"COT",Pareado!$L$2:$L$65,1) -> 2 | I14: =SUMIFS(Pareado!$M$2:$M$65,Pareado!$F$2:$F$65,"Limpo",Pareado!$C$2:$C$65,"Integração",Pareado!$D$2:$D$65,"COT") -> 7 | J14: =COUNTIFS(Pareado!$F$2:$F$65,"Limpo",Pareado!$C$2:$C$65,"Integração",Pareado!$D$2:$D$65,"COT",Pareado!$M$2:$M$65,3) -> 2 | K14: =COUNTIFS(Pareado!$F$2:$F$65,"Limpo",Pareado!$C$2:$C$65,"Integração",Pareado!$D$2:$D$65,"COT",Pareado!$O$2:$O$65,"<>executa") -> 0 | L14: =COUNTIFS(Pareado!$F$2:$F$65,"Limpo",Pareado!$C$2:$C$65,"Integração",Pareado!$D$2:$D$65,"COT",Pareado!$P$2:$P$65,"Sim") -> 0 | M14: =SUMIFS(Pareado!$S$2:$S$65,Pareado!$F$2:$F$65,"Limpo",Pareado!$C$2:$C$65,"Integração",Pareado!$D$2:$D$65,"COT") -> 19 | N14: =SUMIFS(Pareado!$T$2:$T$65,Pareado!$F$2:$F$65,"Limpo",Pareado!$C$2:$C$65,"Integração",Pareado!$D$2:$D$65,"COT") -> 11 | O14: =IFERROR(N14/(N14+SUMIFS(Pareado!$U$2:$U$65,Pareado!$F$2:$F$65,"Limpo",Pareado!$C$2:$C$65,"Integração",Pareado!$D$2:$D$65,"COT",Pareado!$Y$2:$Y$65,"executa")),0) -> 1 | P14: =COUNTIFS(Pareado!$F$2:$F$65,"Limpo",Pareado!$C$2:$C$65,"Integração",Pareado!$D$2:$D$65,"COT",Pareado!$V$2:$V$65,1) -> 2 | Q14: =SUMIFS(Pareado!$W$2:$W$65,Pareado!$F$2:$F$65,"Limpo",Pareado!$C$2:$C$65,"Integração",Pareado!$D$2:$D$65,"COT") -> 8 | R14: =COUNTIFS(Pareado!$F$2:$F$65,"Limpo",Pareado!$C$2:$C$65,"Integração",Pareado!$D$2:$D$65,"COT",Pareado!$W$2:$W$65,3) -> 2 | S14: =COUNTIFS(Pareado!$F$2:$F$65,"Limpo",Pareado!$C$2:$C$65,"Integração",Pareado!$D$2:$D$65,"COT",Pareado!$Y$2:$Y$65,"<>executa") -> 1 | T14: =SUMIFS(Pareado!$AA$2:$AA$65,Pareado!$F$2:$F$65,"Limpo",Pareado!$C$2:$C$65,"Integração",Pareado!$D$2:$D$65,"COT") -> 0 | U14: =COUNTIFS(Pareado!$F$2:$F$65,"Limpo",Pareado!$C$2:$C$65,"Integração",Pareado!$D$2:$D$65,"COT",Pareado!$AF$2:$AF$65,"ChatGPT") -> 2 | V14: =COUNTIFS(Pareado!$F$2:$F$65,"Limpo",Pareado!$C$2:$C$65,"Integração",Pareado!$D$2:$D$65,"COT",Pareado!$AF$2:$AF$65,"empate") -> 0 | W14: =COUNTIFS(Pareado!$F$2:$F$65,"Limpo",Pareado!$C$2:$C$65,"Integração",Pareado!$D$2:$D$65,"COT",Pareado!$AF$2:$AF$65,"Gemini") -> 1 | X14: =COUNTIFS(Pareado!$F$2:$F$65,"Limpo",Pareado!$C$2:$C$65,"Integração",Pareado!$D$2:$D$65,"COT",Pareado!$AG$2:$AG$65,"ChatGPT") -> 1 | Y14: =COUNTIFS(Pareado!$F$2:$F$65,"Limpo",Pareado!$C$2:$C$65,"Integração",Pareado!$D$2:$D$65,"COT",Pareado!$AG$2:$AG$65,"empate") -> 1 | Z14: =COUNTIFS(Pareado!$F$2:$F$65,"Limpo",Pareado!$C$2:$C$65,"Integração",Pareado!$D$2:$D$65,"COT",Pareado!$AG$2:$AG$65,"Gemini") -> 1
A15: Limpo | B15: Integração | C15: Todas | D15: =COUNTIFS(Pareado!$F$2:$F$65,"Limpo",Pareado!$C$2:$C$65,"Integração") -> 9 | E15: =SUMIFS(Pareado!$I$2:$I$65,Pareado!$F$2:$F$65,"Limpo",Pareado!$C$2:$C$65,"Integração") -> 50 | F15: =SUMIFS(Pareado!$J$2:$J$65,Pareado!$F$2:$F$65,"Limpo",Pareado!$C$2:$C$65,"Integração") -> 43 | G15: =IFERROR(F15/(F15+SUMIFS(Pareado!$K$2:$K$65,Pareado!$F$2:$F$65,"Limpo",Pareado!$C$2:$C$65,"Integração",Pareado!$O$2:$O$65,"executa")),0) -> 0.86 | H15: =COUNTIFS(Pareado!$F$2:$F$65,"Limpo",Pareado!$C$2:$C$65,"Integração",Pareado!$L$2:$L$65,1) -> 4 | I15: =SUMIFS(Pareado!$M$2:$M$65,Pareado!$F$2:$F$65,"Limpo",Pareado!$C$2:$C$65,"Integração") -> 20 | J15: =COUNTIFS(Pareado!$F$2:$F$65,"Limpo",Pareado!$C$2:$C$65,"Integração",Pareado!$M$2:$M$65,3) -> 6 | K15: =COUNTIFS(Pareado!$F$2:$F$65,"Limpo",Pareado!$C$2:$C$65,"Integração",Pareado!$O$2:$O$65,"<>executa") -> 0 | L15: =COUNTIFS(Pareado!$F$2:$F$65,"Limpo",Pareado!$C$2:$C$65,"Integração",Pareado!$P$2:$P$65,"Sim") -> 1 | M15: =SUMIFS(Pareado!$S$2:$S$65,Pareado!$F$2:$F$65,"Limpo",Pareado!$C$2:$C$65,"Integração") -> 41 | N15: =SUMIFS(Pareado!$T$2:$T$65,Pareado!$F$2:$F$65,"Limpo",Pareado!$C$2:$C$65,"Integração") -> 23 | O15: =IFERROR(N15/(N15+SUMIFS(Pareado!$U$2:$U$65,Pareado!$F$2:$F$65,"Limpo",Pareado!$C$2:$C$65,"Integração",Pareado!$Y$2:$Y$65,"executa")),0) -> 0.79310345 | P15: =COUNTIFS(Pareado!$F$2:$F$65,"Limpo",Pareado!$C$2:$C$65,"Integração",Pareado!$V$2:$V$65,1) -> 4 | Q15: =SUMIFS(Pareado!$W$2:$W$65,Pareado!$F$2:$F$65,"Limpo",Pareado!$C$2:$C$65,"Integração") -> 20 | R15: =COUNTIFS(Pareado!$F$2:$F$65,"Limpo",Pareado!$C$2:$C$65,"Integração",Pareado!$W$2:$W$65,3) -> 6 | S15: =COUNTIFS(Pareado!$F$2:$F$65,"Limpo",Pareado!$C$2:$C$65,"Integração",Pareado!$Y$2:$Y$65,"<>executa") -> 2 | T15: =SUMIFS(Pareado!$AA$2:$AA$65,Pareado!$F$2:$F$65,"Limpo",Pareado!$C$2:$C$65,"Integração") -> 1 | U15: =COUNTIFS(Pareado!$F$2:$F$65,"Limpo",Pareado!$C$2:$C$65,"Integração",Pareado!$AF$2:$AF$65,"ChatGPT") -> 5 | V15: =COUNTIFS(Pareado!$F$2:$F$65,"Limpo",Pareado!$C$2:$C$65,"Integração",Pareado!$AF$2:$AF$65,"empate") -> 2 | W15: =COUNTIFS(Pareado!$F$2:$F$65,"Limpo",Pareado!$C$2:$C$65,"Integração",Pareado!$AF$2:$AF$65,"Gemini") -> 2 | X15: =COUNTIFS(Pareado!$F$2:$F$65,"Limpo",Pareado!$C$2:$C$65,"Integração",Pareado!$AG$2:$AG$65,"ChatGPT") -> 4 | Y15: =COUNTIFS(Pareado!$F$2:$F$65,"Limpo",Pareado!$C$2:$C$65,"Integração",Pareado!$AG$2:$AG$65,"empate") -> 3 | Z15: =COUNTIFS(Pareado!$F$2:$F$65,"Limpo",Pareado!$C$2:$C$65,"Integração",Pareado!$AG$2:$AG$65,"Gemini") -> 2
A16: Limpo | B16: Todos | C16: ZS | D16: =COUNTIFS(Pareado!$F$2:$F$65,"Limpo",Pareado!$D$2:$D$65,"ZS") -> 13 | E16: =SUMIFS(Pareado!$I$2:$I$65,Pareado!$F$2:$F$65,"Limpo",Pareado!$D$2:$D$65,"ZS") -> 201 | F16: =SUMIFS(Pareado!$J$2:$J$65,Pareado!$F$2:$F$65,"Limpo",Pareado!$D$2:$D$65,"ZS") -> 196 | G16: =IFERROR(F16/(F16+SUMIFS(Pareado!$K$2:$K$65,Pareado!$F$2:$F$65,"Limpo",Pareado!$D$2:$D$65,"ZS",Pareado!$O$2:$O$65,"executa")),0) -> 0.97512438 | H16: =COUNTIFS(Pareado!$F$2:$F$65,"Limpo",Pareado!$D$2:$D$65,"ZS",Pareado!$L$2:$L$65,1) -> 9 | I16: =SUMIFS(Pareado!$M$2:$M$65,Pareado!$F$2:$F$65,"Limpo",Pareado!$D$2:$D$65,"ZS") -> 15 | J16: =COUNTIFS(Pareado!$F$2:$F$65,"Limpo",Pareado!$D$2:$D$65,"ZS",Pareado!$M$2:$M$65,3) -> 3 | K16: =COUNTIFS(Pareado!$F$2:$F$65,"Limpo",Pareado!$D$2:$D$65,"ZS",Pareado!$O$2:$O$65,"<>executa") -> 0 | L16: =COUNTIFS(Pareado!$F$2:$F$65,"Limpo",Pareado!$D$2:$D$65,"ZS",Pareado!$P$2:$P$65,"Sim") -> 1 | M16: =SUMIFS(Pareado!$S$2:$S$65,Pareado!$F$2:$F$65,"Limpo",Pareado!$D$2:$D$65,"ZS") -> 147 | N16: =SUMIFS(Pareado!$T$2:$T$65,Pareado!$F$2:$F$65,"Limpo",Pareado!$D$2:$D$65,"ZS") -> 142 | O16: =IFERROR(N16/(N16+SUMIFS(Pareado!$U$2:$U$65,Pareado!$F$2:$F$65,"Limpo",Pareado!$D$2:$D$65,"ZS",Pareado!$Y$2:$Y$65,"executa")),0) -> 0.99300699 | P16: =COUNTIFS(Pareado!$F$2:$F$65,"Limpo",Pareado!$D$2:$D$65,"ZS",Pareado!$V$2:$V$65,1) -> 11 | Q16: =SUMIFS(Pareado!$W$2:$W$65,Pareado!$F$2:$F$65,"Limpo",Pareado!$D$2:$D$65,"ZS") -> 12 | R16: =COUNTIFS(Pareado!$F$2:$F$65,"Limpo",Pareado!$D$2:$D$65,"ZS",Pareado!$W$2:$W$65,3) -> 3 | S16: =COUNTIFS(Pareado!$F$2:$F$65,"Limpo",Pareado!$D$2:$D$65,"ZS",Pareado!$Y$2:$Y$65,"<>executa") -> 1 | T16: =SUMIFS(Pareado!$AA$2:$AA$65,Pareado!$F$2:$F$65,"Limpo",Pareado!$D$2:$D$65,"ZS") -> 4 | U16: =COUNTIFS(Pareado!$F$2:$F$65,"Limpo",Pareado!$D$2:$D$65,"ZS",Pareado!$AF$2:$AF$65,"ChatGPT") -> 10 | V16: =COUNTIFS(Pareado!$F$2:$F$65,"Limpo",Pareado!$D$2:$D$65,"ZS",Pareado!$AF$2:$AF$65,"empate") -> 1 | W16: =COUNTIFS(Pareado!$F$2:$F$65,"Limpo",Pareado!$D$2:$D$65,"ZS",Pareado!$AF$2:$AF$65,"Gemini") -> 2 | X16: =COUNTIFS(Pareado!$F$2:$F$65,"Limpo",Pareado!$D$2:$D$65,"ZS",Pareado!$AG$2:$AG$65,"ChatGPT") -> 2 | Y16: =COUNTIFS(Pareado!$F$2:$F$65,"Limpo",Pareado!$D$2:$D$65,"ZS",Pareado!$AG$2:$AG$65,"empate") -> 9 | Z16: =COUNTIFS(Pareado!$F$2:$F$65,"Limpo",Pareado!$D$2:$D$65,"ZS",Pareado!$AG$2:$AG$65,"Gemini") -> 2
A17: Limpo | B17: Todos | C17: FS | D17: =COUNTIFS(Pareado!$F$2:$F$65,"Limpo",Pareado!$D$2:$D$65,"FS") -> 13 | E17: =SUMIFS(Pareado!$I$2:$I$65,Pareado!$F$2:$F$65,"Limpo",Pareado!$D$2:$D$65,"FS") -> 113 | F17: =SUMIFS(Pareado!$J$2:$J$65,Pareado!$F$2:$F$65,"Limpo",Pareado!$D$2:$D$65,"FS") -> 101 | G17: =IFERROR(F17/(F17+SUMIFS(Pareado!$K$2:$K$65,Pareado!$F$2:$F$65,"Limpo",Pareado!$D$2:$D$65,"FS",Pareado!$O$2:$O$65,"executa")),0) -> 0.89380531 | H17: =COUNTIFS(Pareado!$F$2:$F$65,"Limpo",Pareado!$D$2:$D$65,"FS",Pareado!$L$2:$L$65,1) -> 8 | I17: =SUMIFS(Pareado!$M$2:$M$65,Pareado!$F$2:$F$65,"Limpo",Pareado!$D$2:$D$65,"FS") -> 16 | J17: =COUNTIFS(Pareado!$F$2:$F$65,"Limpo",Pareado!$D$2:$D$65,"FS",Pareado!$M$2:$M$65,3) -> 5 | K17: =COUNTIFS(Pareado!$F$2:$F$65,"Limpo",Pareado!$D$2:$D$65,"FS",Pareado!$O$2:$O$65,"<>executa") -> 0 | L17: =COUNTIFS(Pareado!$F$2:$F$65,"Limpo",Pareado!$D$2:$D$65,"FS",Pareado!$P$2:$P$65,"Sim") -> 1 | M17: =SUMIFS(Pareado!$S$2:$S$65,Pareado!$F$2:$F$65,"Limpo",Pareado!$D$2:$D$65,"FS") -> 82 | N17: =SUMIFS(Pareado!$T$2:$T$65,Pareado!$F$2:$F$65,"Limpo",Pareado!$D$2:$D$65,"FS") -> 77 | O17: =IFERROR(N17/(N17+SUMIFS(Pareado!$U$2:$U$65,Pareado!$F$2:$F$65,"Limpo",Pareado!$D$2:$D$65,"FS",Pareado!$Y$2:$Y$65,"executa")),0) -> 0.93902439 | P17: =COUNTIFS(Pareado!$F$2:$F$65,"Limpo",Pareado!$D$2:$D$65,"FS",Pareado!$V$2:$V$65,1) -> 11 | Q17: =SUMIFS(Pareado!$W$2:$W$65,Pareado!$F$2:$F$65,"Limpo",Pareado!$D$2:$D$65,"FS") -> 9 | R17: =COUNTIFS(Pareado!$F$2:$F$65,"Limpo",Pareado!$D$2:$D$65,"FS",Pareado!$W$2:$W$65,3) -> 2 | S17: =COUNTIFS(Pareado!$F$2:$F$65,"Limpo",Pareado!$D$2:$D$65,"FS",Pareado!$Y$2:$Y$65,"<>executa") -> 0 | T17: =SUMIFS(Pareado!$AA$2:$AA$65,Pareado!$F$2:$F$65,"Limpo",Pareado!$D$2:$D$65,"FS") -> 6 | U17: =COUNTIFS(Pareado!$F$2:$F$65,"Limpo",Pareado!$D$2:$D$65,"FS",Pareado!$AF$2:$AF$65,"ChatGPT") -> 8 | V17: =COUNTIFS(Pareado!$F$2:$F$65,"Limpo",Pareado!$D$2:$D$65,"FS",Pareado!$AF$2:$AF$65,"empate") -> 1 | W17: =COUNTIFS(Pareado!$F$2:$F$65,"Limpo",Pareado!$D$2:$D$65,"FS",Pareado!$AF$2:$AF$65,"Gemini") -> 4 | X17: =COUNTIFS(Pareado!$F$2:$F$65,"Limpo",Pareado!$D$2:$D$65,"FS",Pareado!$AG$2:$AG$65,"ChatGPT") -> 1 | Y17: =COUNTIFS(Pareado!$F$2:$F$65,"Limpo",Pareado!$D$2:$D$65,"FS",Pareado!$AG$2:$AG$65,"empate") -> 8 | Z17: =COUNTIFS(Pareado!$F$2:$F$65,"Limpo",Pareado!$D$2:$D$65,"FS",Pareado!$AG$2:$AG$65,"Gemini") -> 4
A18: Limpo | B18: Todos | C18: COT | D18: =COUNTIFS(Pareado!$F$2:$F$65,"Limpo",Pareado!$D$2:$D$65,"COT") -> 13 | E18: =SUMIFS(Pareado!$I$2:$I$65,Pareado!$F$2:$F$65,"Limpo",Pareado!$D$2:$D$65,"COT") -> 262 | F18: =SUMIFS(Pareado!$J$2:$J$65,Pareado!$F$2:$F$65,"Limpo",Pareado!$D$2:$D$65,"COT") -> 232 | G18: =IFERROR(F18/(F18+SUMIFS(Pareado!$K$2:$K$65,Pareado!$F$2:$F$65,"Limpo",Pareado!$D$2:$D$65,"COT",Pareado!$O$2:$O$65,"executa")),0) -> 0.97890295 | H18: =COUNTIFS(Pareado!$F$2:$F$65,"Limpo",Pareado!$D$2:$D$65,"COT",Pareado!$L$2:$L$65,1) -> 9 | I18: =SUMIFS(Pareado!$M$2:$M$65,Pareado!$F$2:$F$65,"Limpo",Pareado!$D$2:$D$65,"COT") -> 19 | J18: =COUNTIFS(Pareado!$F$2:$F$65,"Limpo",Pareado!$D$2:$D$65,"COT",Pareado!$M$2:$M$65,3) -> 5 | K18: =COUNTIFS(Pareado!$F$2:$F$65,"Limpo",Pareado!$D$2:$D$65,"COT",Pareado!$O$2:$O$65,"<>executa") -> 1 | L18: =COUNTIFS(Pareado!$F$2:$F$65,"Limpo",Pareado!$D$2:$D$65,"COT",Pareado!$P$2:$P$65,"Sim") -> 1 | M18: =SUMIFS(Pareado!$S$2:$S$65,Pareado!$F$2:$F$65,"Limpo",Pareado!$D$2:$D$65,"COT") -> 147 | N18: =SUMIFS(Pareado!$T$2:$T$65,Pareado!$F$2:$F$65,"Limpo",Pareado!$D$2:$D$65,"COT") -> 123 | O18: =IFERROR(N18/(N18+SUMIFS(Pareado!$U$2:$U$65,Pareado!$F$2:$F$65,"Limpo",Pareado!$D$2:$D$65,"COT",Pareado!$Y$2:$Y$65,"executa")),0) -> 0.88489209 | P18: =COUNTIFS(Pareado!$F$2:$F$65,"Limpo",Pareado!$D$2:$D$65,"COT",Pareado!$V$2:$V$65,1) -> 9 | Q18: =SUMIFS(Pareado!$W$2:$W$65,Pareado!$F$2:$F$65,"Limpo",Pareado!$D$2:$D$65,"COT") -> 18 | R18: =COUNTIFS(Pareado!$F$2:$F$65,"Limpo",Pareado!$D$2:$D$65,"COT",Pareado!$W$2:$W$65,3) -> 5 | S18: =COUNTIFS(Pareado!$F$2:$F$65,"Limpo",Pareado!$D$2:$D$65,"COT",Pareado!$Y$2:$Y$65,"<>executa") -> 1 | T18: =SUMIFS(Pareado!$AA$2:$AA$65,Pareado!$F$2:$F$65,"Limpo",Pareado!$D$2:$D$65,"COT") -> 7 | U18: =COUNTIFS(Pareado!$F$2:$F$65,"Limpo",Pareado!$D$2:$D$65,"COT",Pareado!$AF$2:$AF$65,"ChatGPT") -> 12 | V18: =COUNTIFS(Pareado!$F$2:$F$65,"Limpo",Pareado!$D$2:$D$65,"COT",Pareado!$AF$2:$AF$65,"empate") -> 0 | W18: =COUNTIFS(Pareado!$F$2:$F$65,"Limpo",Pareado!$D$2:$D$65,"COT",Pareado!$AF$2:$AF$65,"Gemini") -> 1 | X18: =COUNTIFS(Pareado!$F$2:$F$65,"Limpo",Pareado!$D$2:$D$65,"COT",Pareado!$AG$2:$AG$65,"ChatGPT") -> 2 | Y18: =COUNTIFS(Pareado!$F$2:$F$65,"Limpo",Pareado!$D$2:$D$65,"COT",Pareado!$AG$2:$AG$65,"empate") -> 8 | Z18: =COUNTIFS(Pareado!$F$2:$F$65,"Limpo",Pareado!$D$2:$D$65,"COT",Pareado!$AG$2:$AG$65,"Gemini") -> 3
A19: Limpo | B19: Todos | C19: Todas | D19: =COUNTIFS(Pareado!$F$2:$F$65,"Limpo") -> 39 | E19: =SUMIFS(Pareado!$I$2:$I$65,Pareado!$F$2:$F$65,"Limpo") -> 576 | F19: =SUMIFS(Pareado!$J$2:$J$65,Pareado!$F$2:$F$65,"Limpo") -> 529 | G19: =IFERROR(F19/(F19+SUMIFS(Pareado!$K$2:$K$65,Pareado!$F$2:$F$65,"Limpo",Pareado!$O$2:$O$65,"executa")),0) -> 0.9600726 | H19: =COUNTIFS(Pareado!$F$2:$F$65,"Limpo",Pareado!$L$2:$L$65,1) -> 26 | I19: =SUMIFS(Pareado!$M$2:$M$65,Pareado!$F$2:$F$65,"Limpo") -> 50 | J19: =COUNTIFS(Pareado!$F$2:$F$65,"Limpo",Pareado!$M$2:$M$65,3) -> 13 | K19: =COUNTIFS(Pareado!$F$2:$F$65,"Limpo",Pareado!$O$2:$O$65,"<>executa") -> 1 | L19: =COUNTIFS(Pareado!$F$2:$F$65,"Limpo",Pareado!$P$2:$P$65,"Sim") -> 3 | M19: =SUMIFS(Pareado!$S$2:$S$65,Pareado!$F$2:$F$65,"Limpo") -> 376 | N19: =SUMIFS(Pareado!$T$2:$T$65,Pareado!$F$2:$F$65,"Limpo") -> 342 | O19: =IFERROR(N19/(N19+SUMIFS(Pareado!$U$2:$U$65,Pareado!$F$2:$F$65,"Limpo",Pareado!$Y$2:$Y$65,"executa")),0) -> 0.93956044 | P19: =COUNTIFS(Pareado!$F$2:$F$65,"Limpo",Pareado!$V$2:$V$65,1) -> 31 | Q19: =SUMIFS(Pareado!$W$2:$W$65,Pareado!$F$2:$F$65,"Limpo") -> 39 | R19: =COUNTIFS(Pareado!$F$2:$F$65,"Limpo",Pareado!$W$2:$W$65,3) -> 10 | S19: =COUNTIFS(Pareado!$F$2:$F$65,"Limpo",Pareado!$Y$2:$Y$65,"<>executa") -> 2 | T19: =SUMIFS(Pareado!$AA$2:$AA$65,Pareado!$F$2:$F$65,"Limpo") -> 17 | U19: =COUNTIFS(Pareado!$F$2:$F$65,"Limpo",Pareado!$AF$2:$AF$65,"ChatGPT") -> 30 | V19: =COUNTIFS(Pareado!$F$2:$F$65,"Limpo",Pareado!$AF$2:$AF$65,"empate") -> 2 | W19: =COUNTIFS(Pareado!$F$2:$F$65,"Limpo",Pareado!$AF$2:$AF$65,"Gemini") -> 7 | X19: =COUNTIFS(Pareado!$F$2:$F$65,"Limpo",Pareado!$AG$2:$AG$65,"ChatGPT") -> 5 | Y19: =COUNTIFS(Pareado!$F$2:$F$65,"Limpo",Pareado!$AG$2:$AG$65,"empate") -> 25 | Z19: =COUNTIFS(Pareado!$F$2:$F$65,"Limpo",Pareado!$AG$2:$AG$65,"Gemini") -> 9
