Workbook

Sheet Leia-me
A1: Réplica Fase 2 — Gemini 3.8 Flash · consolidado das 60 rodadas (+4 reexecuções)
A2: Fonte: fase2-gemini-consolidado (2026-09-24): 64 docs de rodada, 134 saídas de flutter test, 70 arquivos de teste. Nenhum arquivo do pacote foi alterado.
A4: Regras de contagem aplicadas
A5: 1. As 4 rodadas _REEXEC estão na aba Rodadas com grupo "REEXEC" e ficam FORA de toda agregação das 60.
A6: 2. formatName (3 rodadas) tem grupo próprio "formatName (bug nativo)" — não entra nos alvos limpos nem nos bugs plantados.
A7: 3. Alvos limpos na contagem: 21 unitário + 9 widget + 9 integração = 39. Bugs plantados: 18. formatName: 3. Total 60.
A8: 4. "Testes passando (final)" = estado arquivado após a última iteração usada. Quando o arquivo final não compila/não carrega, vale 0 e a coluna "Estado final" diz por quê; o melhor estado intermediário fica em "Melhor intermediário".
A9: 5. "Iterações" = iterações de reparo efetivamente usadas (0–3). "Tentativas" = envios até obter resposta na geração (recusas + erros de serviço + 1). Recusas em reparo (rodada 51) somadas em Tentativas.
A10: 6. "Ajuda de import" = prompt traz a linha de import real (6 prompts limpos de CriarPlaylistScreen/playlistFlow + W-CRASH-{ZS,COT} + I-SILENT-{ZS,COT}). Todo prompt FS NÃO traz. Rodadas 13, 14, 15 usam prompt com material divergente do app (defeituoso).
A11: 7. "Avaliação" = auditoria humana registrada nos docs de rodada, se cada autoclassificação (A)/(B)/(C) procede.
A12: 8. Taxa de aprovação e qualidade de diagnóstico são dimensões separadas — ver aba Consolidado (colunas de aprovação) e aba Classificações (colunas de diagnóstico). Não somar limpo com bug plantado.
A14: Abas
... A16: Coluna "Ajuda de import" corrigida em 2026-10-08 (fase2-gemini/analise/ajuda_import.md): 10 prompts de bug com linha import package:sintonize/ (9 + 1 genérico), 5 com caminho só em prosa/comentário, 3 sem nada (W-CRASH-FS, W-SILENT-FS, I-SILENT-FS). A contagem "4" do LEIA-PRIMEIRO referia-se só à linha de criar_playlist.dart.

Sheet Rodadas
A1: # | B1: ID da rodada | C1: Nível | D1: Estratégia | E1: Alvo | F1: Grupo | G1: Bug | H1: Ajuda de import | I1: Compilou na 1ª | J1: Testes gerados | K1: Passando (final) | L1: Falhando (final) | M1: Estado final | N1: Melhor intermediário | O1: Iterações de reparo | P1: Tentativas de envio | Q1: Recusas | R1: Erros de serviço | S1: Autoclassificações | T1: Avaliação da auditoria | U1: Detecção do bug | V1: Notas
A2: 1 | B2: FASE2-UCRASH-ZS | C2: Unitário | D2: ZS | E2: capitalize | F2: Bug plantado | G2: U-CRASH | H2: Só em prosa/comentário | I2: Sim | J2: 11 | K2: 11 | L2: 0 | M2: executa | N2: — | O2: 0 | P2: 1 | Q2: 0 | R2: 0 | S2: (C) | T2: Procede — (C) confirmado com 3 asserções throwsA | U2: (C) com asserção | V2: Contradisse a docstring, testou 3 variantes e propôs a guarda exata.
A3: 2 | B3: FASE2-UCRASH-FS | C3: Unitário | D3: FS | E3: capitalize | F3: Bug plantado | G3: U-CRASH | H3: Só em prosa/comentário | I3: Sim | J3: 6 | K3: 6 | L3: 0 | M3: executa | N3: — | O3: 0 | P3: 1 | Q3: 0 | R3: 0 | S3: (C) | T3: Procede na categoria; (C) só em prosa, 0 asserções capturam o bug | U3: (C) só em prosa | V3: Suíte passa porque desvia das entradas que disparam o bug. Exemplos FS só usam isNull/isNotNull.
A4: 3 | B4: FASE2-UCRASH-COT | C4: Unitário | D4: COT | E4: capitalize | F4: Bug plantado | G4: U-CRASH | H4: Sim (linha import) | I4: Sim | J4: 10 | K4: 10 | L4: 0 | M4: executa | N4: — | O4: 0 | P4: 1 | Q4: 0 | R4: 0 | S4: (C) | T4: Procede — detecção no passo de análise, 3 asserções | U4: (C) com asserção | V4: Mesmas 3 entradas da ZS; prosa com formatação corrompida.
A5: 4 | B5: FASE2-USILENT-ZS | C5: Unitário | D5: ZS | E5: validateSenha | F5: Bug plantado | G5: U-SILENT | H5: Só em prosa/comentário | I5: Sim | J5: 7 | K5: 7 | L5: 0 | M5: executa | N5: — | O5: 0 | P5: 1 | Q5: 0 | R5: 0 | S5: (C) | T5: Procede — teste de borda dedicado a 6 chars | U5: (C) com asserção | V5: Declarou a política "testar o código, não a especificação" e apontou a correção (< 6).
A6: 5 | B6: FASE2-USILENT-FS | C6: Unitário | D6: FS | E6: validateSenha | F6: Bug plantado | G6: U-SILENT | H6: Só em prosa/comentário | I6: Sim | J6: 5 | K6: 5 | L6: 0 | M6: executa | N6: — | O6: 0 | P6: 1 | Q6: 0 | R6: 0 | S6: (C) | T6: Procede — asserção dedicada | U6: (C) com asserção | V6: Forma de asserção necessária (comparação de string) estava nos exemplos; capturou.
A7: 6 | B7: FASE2-USILENT-COT | C7: Unitário | D7: COT | E7: validateSenha | F7: Bug plantado | G7: U-SILENT | H7: Sim (linha import) | I7: Sim | J7: 8 | K7: 8 | L7: 0 | M7: executa | N7: — | O7: 0 | P7: 2 | Q7: 1 | R7: 0 | S7: (C) | T7: Procede — asserção dedicada | U7: (C) com asserção | V7: 1ª recusa em 3.8 Flash, prompt de geração. Primeira rodada automatizada.
A8: 7 | B8: FASE2-WCRASH-ZS | C8: Widget | D8: ZS | E8: CriarPlaylistScreen | F8: Bug plantado | G8: W-CRASH | H8: Sim (linha import) | I8: Sim | J8: 5 | K8: 5 | L8: 0 | M8: executa | N8: — | O8: 0 | P8: 2 | Q8: 1 | R8: 0 | S8: — | T8: n/a (sem reparo, sem (C)) | U8: Não detectado | V8: Testa _filterMusicas mas todos os mocks têm artist_name.
A9: 8 | B9: FASE2-WCRASH-FS | C9: Widget | D9: FS | E9: CriarPlaylistScreen | F9: Bug plantado | G9: W-CRASH | H9: Não | I9: Não | J9: 5 | K9: 3 | L9: 2 | M9: executa | N9: — | O9: 3 | P9: 1 | Q9: 0 | R9: 0 | S9: (A); (A); (A) | T9: Categoria correta nas 3; correções erradas (3 caminhos inventados); iteração 3 colou o widget no teste → suíte não testa a aplicação | U9: Não detectado | V9: Regressão introduzida na iter 2 (findsOneWidget→findsNothing). Execução anterior com 2 recusas perdida, fora da contagem.
A10: 9 | B10: FASE2-WCRASH-COT | C10: Widget | D10: COT | E10: CriarPlaylistScreen | F10: Bug plantado | G10: W-CRASH | H10: Sim (linha import) | I10: Sim | J10: 9 | K10: 9 | L10: 0 | M10: executa | N10: — | O10: 0 | P10: 1 | Q10: 0 | R10: 0 | S10: — | T10: n/a | U10: Não detectado | V10: Suíte mais sofisticada do bloco (mocks gerados, navegação); "cenários de erro" lido só como infraestrutura.
A11: 10 | B11: FASE2-WSILENT-ZS | C11: Widget | D11: ZS | E11: LoginScreen | F11: Bug plantado | G11: W-SILENT | H11: Sim (linha import) | I11: Sim | J11: 11 | K11: 10 | L11: 1 | M11: executa | N11: — | O11: 2 | P11: 1 | Q11: 0 | R11: 0 | S11: (A); (B) | T11: (A) procede. (B) procede como limitação de testabilidade (TelaInicialScreen acopla FirebaseAuth.instance) — real, mas não é o bug plantado | U11: Canonizado | V11: 4 testes de mensagem passam asserindo as strings trocadas; corrigir o bug quebraria 2 testes.
A12: 11 | B12: FASE2-WSILENT-FS | C12: Widget | D12: FS | E12: LoginScreen | F12: Bug plantado | G12: W-SILENT | H12: Não | I12: Não | J12: 9 | K12: 9 | L12: 0 | M12: executa | N12: — | O12: 2 | P12: 1 | Q12: 0 | R12: 0 | S12: (A); (A) | T12: Diagnósticos corretos; correção da iter 2 colou LoginScreen no teste → suíte não testa a aplicação | U12: Canonizado (sobre cópia) | V12: Copiou a API inexistente do exemplo (authExceptions) e descartou a asserção do exemplo que exporia o bug.
A13: 12 | B13: FASE2-WSILENT-COT | C13: Widget | D13: COT | E13: LoginScreen | F13: Bug plantado | G13: W-SILENT | H13: Sim (linha import) | I13: Sim | J13: 10 | K13: 9 | L13: 1 | M13: executa | N13: — | O13: 1 | P13: 1 | Q13: 0 | R13: 0 | S13: (B) | T13: Procede (TelaInicialScreen) — não é o bug plantado | U13: Canonizado | V13: Enunciou o par invertido no passo de análise e chamou de "correta". Prompt mais favorável do experimento.
... A19: 18 | B19: FASE2-ISILENT-COT | C19: Integração | D19: COT | E19: CriarPlaylistScreen | F19: Bug plantado | G19: I-SILENT | H19: Sim (linha import) | I19: Não | J19: 4 | K19: 4 | L19: 0 | M19: executa | N19: — | O19: 1 | P19: 1 | Q19: 0 | R19: 0 | S19: (A) | T19: Procede | U19: Canonizado | V19: expect(nome, equals("Nova Playlist")) — canonização mais explícita da réplica. Mencionou o bug 2x como "nota técnica".
A20: 19 | B20: FASE2-UNIT-ZS-01_validateNome | C20: Unitário | D20: ZS | E20: validateNome | F20: Limpo | G20: — | H20: n/a | I20: Sim | J20: 13 | K20: 13 | L20: 0 | M20: executa | N20: — | O20: 0 | P20: 2 | Q20: 1 | R20: 0 | S20: — | T20: n/a (sem reparo) | U20: —
A21: 20 | B21: FASE2-UNIT-FS-01_validateNome | C21: Unitário | D21: FS | E21: validateNome | F21: Limpo | G21: — | H21: n/a | I21: Sim | J21: 7 | K21: 7 | L21: 0 | M21: executa | N21: — | O21: 0 | P21: 2 | Q21: 1 | R21: 0 | S21: — | T21: n/a (sem reparo) | U21: — | V21: Resposta truncada e recomeçada
A22: 21 | B22: FASE2-UNIT-COT-01_validateNome | C22: Unitário | D22: COT | E22: validateNome | F22: Limpo | G22: — | H22: n/a | I22: Sim | J22: 11 | K22: 11 | L22: 0 | M22: executa | N22: — | O22: 0 | P22: 2 | Q22: 1 | R22: 0 | S22: — | T22: n/a (sem reparo) | U22: — | V22: Resposta truncada e recomeçada
A23: 22 | B23: FASE2-UNIT-ZS-03_validateNumero | C23: Unitário | D23: ZS | E23: validateNumero | F23: Limpo | G23: — | H23: n/a | I23: Sim | J23: 13 | K23: 13 | L23: 0 | M23: executa | N23: — | O23: 1 | P23: 1 | Q23: 0 | R23: 0 | S23: (A) | T23: Procede — premissa falsa sobre int.tryParse | U23: —
A24: 23 | B24: FASE2-UNIT-FS-03_validateNumero | C24: Unitário | D24: FS | E24: validateNumero | F24: Limpo | G24: — | H24: n/a | I24: Sim | J24: 6 | K24: 6 | L24: 0 | M24: executa | N24: — | O24: 0 | P24: 1 | Q24: 0 | R24: 0 | S24: — | T24: n/a (sem reparo) | U24: —
A25: 24 | B25: FASE2-UNIT-COT-03_validateNumero | C25: Unitário | D25: COT | E25: validateNumero | F25: Limpo | G25: — | H25: n/a | I25: Sim | J25: 13 | K25: 13 | L25: 0 | M25: executa | N25: — | O25: 1 | P25: 1 | Q25: 0 | R25: 0 | S25: (A) | T25: Procede — mesma premissa falsa sobre int.tryParse | U25: —
A26: 25 | B26: FASE2-UNIT-ZS-04_validateCEP | C26: Unitário | D26: ZS | E26: validateCEP | F26: Limpo | G26: — | H26: n/a | I26: Sim | J26: 12 | K26: 12 | L26: 0 | M26: executa | N26: — | O26: 0 | P26: 1 | Q26: 0 | R26: 0 | S26: — | T26: n/a (sem reparo) | U26: —
A27: 26 | B27: FASE2-UNIT-FS-04_validateCEP | C27: Unitário | D27: FS | E27: validateCEP | F27: Limpo | G27: — | H27: n/a | I27: Sim | J27: 8 | K27: 8 | L27: 0 | M27: executa | N27: — | O27: 0 | P27: 1 | Q27: 0 | R27: 0 | S27: — | T27: n/a (sem reparo) | U27: — | V27: Resposta truncada e recomeçada
A28: 27 | B28: FASE2-UNIT-COT-04_validateCEP | C28: Unitário | D28: COT | E28: validateCEP | F28: Limpo | G28: — | H28: n/a | I28: Sim | J28: 12 | K28: 12 | L28: 0 | M28: executa | N28: — | O28: 0 | P28: 2 | Q28: 0 | R28: 1 | S28: — | T28: n/a (sem reparo) | U28: — | V28: Erro de serviço 1096 na tentativa 1
A29: 28 | B29: FASE2-UNIT-ZS-05_validateEmail | C29: Unitário | D29: ZS | E29: validateEmail | F29: Limpo | G29: — | H29: n/a | I29: Sim | J29: 26 | K29: 26 | L29: 0 | M29: executa | N29: — | O29: 0 | P29: 2 | Q29: 1 | R29: 0 | S29: — | T29: n/a (sem reparo) | U29: —
A30: 29 | B30: FASE2-UNIT-FS-05_validateEmail | C30: Unitário | D30: FS | E30: validateEmail | F30: Limpo | G30: — | H30: n/a | I30: Sim | J30: 8 | K30: 8 | L30: 0 | M30: executa | N30: — | O30: 0 | P30: 1 | Q30: 0 | R30: 0 | S30: — | T30: n/a (sem reparo) | U30: —
A31: 30 | B31: FASE2-UNIT-COT-05_validateEmail | C31: Unitário | D31: COT | E31: validateEmail | F31: Limpo | G31: — | H31: n/a | I31: Sim | J31: 15 | K31: 15 | L31: 0 | M31: executa | N31: — | O31: 0 | P31: 2 | Q31: 1 | R31: 0 | S31: — | T31: n/a (sem reparo) | U31: —
A32: 31 | B32: FASE2-UNIT-ZS-06_validateEmailLogin | C32: Unitário | D32: ZS | E32: validateEmailLogin | F32: Limpo | G32: — | H32: n/a | I32: Sim | J32: 11 | K32: 11 | L32: 0 | M32: executa | N32: — | O32: 0 | P32: 1 | Q32: 0 | R32: 0 | S32: — | T32: n/a (sem reparo) | U32: — | V32: Resposta truncada e recomeçada
A33: 32 | B33: FASE2-UNIT-FS-06_validateEmailLogin | C33: Unitário | D33: FS | E33: validateEmailLogin | F33: Limpo | G33: — | H33: n/a | I33: Sim | J33: 8 | K33: 8 | L33: 0 | M33: executa | N33: — | O33: 0 | P33: 1 | Q33: 0 | R33: 0 | S33: — | T33: n/a (sem reparo) | U33: — | V33: Resposta truncada e recomeçada
A34: 33 | B34: FASE2-UNIT-COT-06_validateEmailLogin | C34: Unitário | D34: COT | E34: validateEmailLogin | F34: Limpo | G34: — | H34: n/a | I34: Sim | J34: 11 | K34: 11 | L34: 0 | M34: executa | N34: — | O34: 0 | P34: 1 | Q34: 0 | R34: 0 | S34: — | T34: cenário listado e não testado | U34: —
A35: 34 | B35: FASE2-UNIT-ZS-07_validateEmailEdit | C35: Unitário | D35: ZS | E35: validateEmailEdit | F35: Limpo | G35: — | H35: n/a | I35: Sim | J35: 16 | K35: 16 | L35: 0 | M35: executa | N35: — | O35: 0 | P35: 1 | Q35: 0 | R35: 0 | S35: — | T35: n/a (sem reparo) | U35: —
A36: 35 | B36: FASE2-UNIT-FS-07_validateEmailEdit | C36: Unitário | D36: FS | E36: validateEmailEdit | F36: Limpo | G36: — | H36: n/a | I36: Sim | J36: 7 | K36: 7 | L36: 0 | M36: executa | N36: — | O36: 0 | P36: 2 | Q36: 1 | R36: 0 | S36: — | T36: n/a (sem reparo) | U36: —
A37: 36 | B37: FASE2-UNIT-COT-07_validateEmailEdit | C37: Unitário | D37: COT | E37: validateEmailEdit | F37: Limpo | G37: — | H37: n/a | I37: Sim | J37: 16 | K37: 16 | L37: 0 | M37: executa | N37: — | O37: 0 | P37: 1 | Q37: 0 | R37: 0 | S37: — | T37: n/a (sem reparo) | U37: —
A38: 37 | B38: FASE2-UNIT-ZS-08_formatName | C38: Unitário | D38: ZS | E38: formatName | F38: formatName (bug nativo) | G38: — | H38: n/a | I38: Sim | J38: 10 | K38: 10 | L38: 0 | M38: executa | N38: — | O38: 0 | P38: 3 | Q38: 2 | R38: 0 | S38: — | T38: n/a (sem reparo) | U38: — | V38: RangeError canonizado (3 testes)
A39: 38 | B39: FASE2-UNIT-FS-08_formatName | C39: Unitário | D39: FS | E39: formatName | F39: formatName (bug nativo) | G39: — | H39: n/a | I39: Sim | J39: 5 | K39: 5 | L39: 0 | M39: executa | N39: — | O39: 0 | P39: 1 | Q39: 0 | R39: 0 | S39: — | T39: n/a (sem reparo) | U39: — | V39: RangeError só em prosa
A40: 39 | B40: FASE2-UNIT-COT-08_formatName | C40: Unitário | D40: COT | E40: formatName | F40: formatName (bug nativo) | G40: — | H40: n/a | I40: Sim | J40: 9 | K40: 9 | L40: 0 | M40: executa | N40: — | O40: 0 | P40: 1 | Q40: 0 | R40: 0 | S40: — | T40: n/a (sem reparo) | U40: — | V40: Resposta truncada e recomeçada; RangeError canonizado (2 testes)
A41: 40 | B41: FASE2-UNIT-ZS-10_validateDate | C41: Unitário | D41: ZS | E41: validateDate | F41: Limpo | G41: — | H41: n/a | I41: Sim | J41: 23 | K41: 23 | L41: 0 | M41: executa | N41: — | O41: 0 | P41: 3 | Q41: 2 | R41: 0 | S41: — | T41: n/a (sem reparo) | U41: —
A42: 41 | B42: FASE2-UNIT-FS-10_validateDate | C42: Unitário | D42: FS | E42: validateDate | F42: Limpo | G42: — | H42: n/a | I42: Sim | J42: 9 | K42: 9 | L42: 0 | M42: executa | N42: — | O42: 0 | P42: 1 | Q42: 0 | R42: 0 | S42: — | T42: só isNotNull, mensagens não conferidas | U42: —
A43: 42 | B43: FASE2-UNIT-COT-10_validateDate | C43: Unitário | D43: COT | E43: validateDate | F43: Limpo | G43: — | H43: n/a | I43: Sim | J43: 19 | K43: 19 | L43: 0 | M43: executa | N43: — | O43: 0 | P43: 3 | Q43: 2 | R43: 0 | S43: — | T43: n/a (sem reparo) | U43: —
A44: 43 | B44: FASE2-WIDGET-ZS-01_CadastroScreen | C44: Widget | D44: ZS | E44: CadastroScreen | F44: Limpo | G44: — | H44: Não | I44: Sim | J44: 6 | K44: 6 | L44: 0 | M44: executa | N44: — | O44: 2 | P44: 1 | Q44: 0 | R44: 0 | S44: (A); (A) | T44: Procedem (seletor ambíguo por Column; viewport 800×600) | U44: — | V44: Resposta truncada e recomeçada na geração.
A45: 44 | B45: FASE2-WIDGET-FS-01_CadastroScreen | C45: Widget | D45: FS | E45: CadastroScreen | F45: Limpo | G45: — | H45: Não | I45: Sim | J45: 7 | K45: 7 | L45: 0 | M45: executa | N45: — | O45: 2 | P45: 2 | Q45: 1 | R45: 0 | S45: (A); (A) | T45: Procedem | U45: — | V45: Mesmo seletor ambíguo da ZS, gerado de forma independente.
...

Sheet Consolidado
A1: Consolidado por nível × estratégia — fórmulas sobre a aba Rodadas (REEXEC excluídas)
A3: Grupo | B3: Nível | C3: Estratégia | D3: Rodadas | E3: Testes gerados | F3: Passando (final) | G3: Aprovação final (%) | H3: Rodadas 100% verdes | I3: Compilou na 1ª | J3: Rodadas com reparo | K3: Iterações usadas (soma) | L3: Média de iterações | M3: Rodadas no máx. (3) | N3: Tentativas (soma) | O3: Recusas | P3: Rodadas com recusa | Q3: Arquivo final não compila/carrega
A4: Limpo | B4: Unitário | C4: ZS | D4: =COUNTIFS(Rodadas!$F$2:$F$65,"Limpo",Rodadas!$C$2:$C$65,"Unitário",Rodadas!$D$2:$D$65,"ZS") -> 7 | E4: =SUMIFS(Rodadas!$J$2:$J$65,Rodadas!$F$2:$F$65,"Limpo",Rodadas!$C$2:$C$65,"Unitário",Rodadas!$D$2:$D$65,"ZS") -> 114 | F4: =SUMIFS(Rodadas!$K$2:$K$65,Rodadas!$F$2:$F$65,"Limpo",Rodadas!$C$2:$C$65,"Unitário",Rodadas!$D$2:$D$65,"ZS") -> 114 | G4: =IFERROR(F4/E4,0) -> 1 | H4: =COUNTIFS(Rodadas!$F$2:$F$65,"Limpo",Rodadas!$C$2:$C$65,"Unitário",Rodadas!$D$2:$D$65,"ZS",Rodadas!$L$2:$L$65,0,Rodadas!$K$2:$K$65,">0") -> 7 | I4: =COUNTIFS(Rodadas!$F$2:$F$65,"Limpo",Rodadas!$C$2:$C$65,"Unitário",Rodadas!$D$2:$D$65,"ZS",Rodadas!$I$2:$I$65,"Sim") -> 7 | J4: =COUNTIFS(Rodadas!$F$2:$F$65,"Limpo",Rodadas!$C$2:$C$65,"Unitário",Rodadas!$D$2:$D$65,"ZS",Rodadas!$O$2:$O$65,">0") -> 1 | K4: =SUMIFS(Rodadas!$O$2:$O$65,Rodadas!$F$2:$F$65,"Limpo",Rodadas!$C$2:$C$65,"Unitário",Rodadas!$D$2:$D$65,"ZS") -> 1 | L4: =IFERROR(K4/D4,0) -> 0.14285714 | M4: =COUNTIFS(Rodadas!$F$2:$F$65,"Limpo",Rodadas!$C$2:$C$65,"Unitário",Rodadas!$D$2:$D$65,"ZS",Rodadas!$O$2:$O$65,3) -> 0 | N4: =SUMIFS(Rodadas!$P$2:$P$65,Rodadas!$F$2:$F$65,"Limpo",Rodadas!$C$2:$C$65,"Unitário",Rodadas!$D$2:$D$65,"ZS") -> 11 | O4: =SUMIFS(Rodadas!$Q$2:$Q$65,Rodadas!$F$2:$F$65,"Limpo",Rodadas!$C$2:$C$65,"Unitário",Rodadas!$D$2:$D$65,"ZS") -> 4 | P4: =COUNTIFS(Rodadas!$F$2:$F$65,"Limpo",Rodadas!$C$2:$C$65,"Unitário",Rodadas!$D$2:$D$65,"ZS",Rodadas!$Q$2:$Q$65,">0") -> 3 | Q4: =COUNTIFS(Rodadas!$F$2:$F$65,"Limpo",Rodadas!$C$2:$C$65,"Unitário",Rodadas!$D$2:$D$65,"ZS",Rodadas!$M$2:$M$65,"<>executa") -> 0
A5: Limpo | B5: Unitário | C5: FS | D5: =COUNTIFS(Rodadas!$F$2:$F$65,"Limpo",Rodadas!$C$2:$C$65,"Unitário",Rodadas!$D$2:$D$65,"FS") -> 7 | E5: =SUMIFS(Rodadas!$J$2:$J$65,Rodadas!$F$2:$F$65,"Limpo",Rodadas!$C$2:$C$65,"Unitário",Rodadas!$D$2:$D$65,"FS") -> 53 | F5: =SUMIFS(Rodadas!$K$2:$K$65,Rodadas!$F$2:$F$65,"Limpo",Rodadas!$C$2:$C$65,"Unitário",Rodadas!$D$2:$D$65,"FS") -> 53 | G5: =IFERROR(F5/E5,0) -> 1 | H5: =COUNTIFS(Rodadas!$F$2:$F$65,"Limpo",Rodadas!$C$2:$C$65,"Unitário",Rodadas!$D$2:$D$65,"FS",Rodadas!$L$2:$L$65,0,Rodadas!$K$2:$K$65,">0") -> 7 | I5: =COUNTIFS(Rodadas!$F$2:$F$65,"Limpo",Rodadas!$C$2:$C$65,"Unitário",Rodadas!$D$2:$D$65,"FS",Rodadas!$I$2:$I$65,"Sim") -> 7 | J5: =COUNTIFS(Rodadas!$F$2:$F$65,"Limpo",Rodadas!$C$2:$C$65,"Unitário",Rodadas!$D$2:$D$65,"FS",Rodadas!$O$2:$O$65,">0") -> 0 | K5: =SUMIFS(Rodadas!$O$2:$O$65,Rodadas!$F$2:$F$65,"Limpo",Rodadas!$C$2:$C$65,"Unitário",Rodadas!$D$2:$D$65,"FS") -> 0 | L5: =IFERROR(K5/D5,0) -> 0 | M5: =COUNTIFS(Rodadas!$F$2:$F$65,"Limpo",Rodadas!$C$2:$C$65,"Unitário",Rodadas!$D$2:$D$65,"FS",Rodadas!$O$2:$O$65,3) -> 0 | N5: =SUMIFS(Rodadas!$P$2:$P$65,Rodadas!$F$2:$F$65,"Limpo",Rodadas!$C$2:$C$65,"Unitário",Rodadas!$D$2:$D$65,"FS") -> 9 | O5: =SUMIFS(Rodadas!$Q$2:$Q$65,Rodadas!$F$2:$F$65,"Limpo",Rodadas!$C$2:$C$65,"Unitário",Rodadas!$D$2:$D$65,"FS") -> 2 | P5: =COUNTIFS(Rodadas!$F$2:$F$65,"Limpo",Rodadas!$C$2:$C$65,"Unitário",Rodadas!$D$2:$D$65,"FS",Rodadas!$Q$2:$Q$65,">0") -> 2 | Q5: =COUNTIFS(Rodadas!$F$2:$F$65,"Limpo",Rodadas!$C$2:$C$65,"Unitário",Rodadas!$D$2:$D$65,"FS",Rodadas!$M$2:$M$65,"<>executa") -> 0
A6: Limpo | B6: Unitário | C6: COT | D6: =COUNTIFS(Rodadas!$F$2:$F$65,"Limpo",Rodadas!$C$2:$C$65,"Unitário",Rodadas!$D$2:$D$65,"COT") -> 7 | E6: =SUMIFS(Rodadas!$J$2:$J$65,Rodadas!$F$2:$F$65,"Limpo",Rodadas!$C$2:$C$65,"Unitário",Rodadas!$D$2:$D$65,"COT") -> 97 | F6: =SUMIFS(Rodadas!$K$2:$K$65,Rodadas!$F$2:$F$65,"Limpo",Rodadas!$C$2:$C$65,"Unitário",Rodadas!$D$2:$D$65,"COT") -> 97 | G6: =IFERROR(F6/E6,0) -> 1 | H6: =COUNTIFS(Rodadas!$F$2:$F$65,"Limpo",Rodadas!$C$2:$C$65,"Unitário",Rodadas!$D$2:$D$65,"COT",Rodadas!$L$2:$L$65,0,Rodadas!$K$2:$K$65,">0") -> 7 | I6: =COUNTIFS(Rodadas!$F$2:$F$65,"Limpo",Rodadas!$C$2:$C$65,"Unitário",Rodadas!$D$2:$D$65,"COT",Rodadas!$I$2:$I$65,"Sim") -> 7 | J6: =COUNTIFS(Rodadas!$F$2:$F$65,"Limpo",Rodadas!$C$2:$C$65,"Unitário",Rodadas!$D$2:$D$65,"COT",Rodadas!$O$2:$O$65,">0") -> 1 | K6: =SUMIFS(Rodadas!$O$2:$O$65,Rodadas!$F$2:$F$65,"Limpo",Rodadas!$C$2:$C$65,"Unitário",Rodadas!$D$2:$D$65,"COT") -> 1 | L6: =IFERROR(K6/D6,0) -> 0.14285714 | M6: =COUNTIFS(Rodadas!$F$2:$F$65,"Limpo",Rodadas!$C$2:$C$65,"Unitário",Rodadas!$D$2:$D$65,"COT",Rodadas!$O$2:$O$65,3) -> 0 | N6: =SUMIFS(Rodadas!$P$2:$P$65,Rodadas!$F$2:$F$65,"Limpo",Rodadas!$C$2:$C$65,"Unitário",Rodadas!$D$2:$D$65,"COT") -> 12 | O6: =SUMIFS(Rodadas!$Q$2:$Q$65,Rodadas!$F$2:$F$65,"Limpo",Rodadas!$C$2:$C$65,"Unitário",Rodadas!$D$2:$D$65,"COT") -> 4 | P6: =COUNTIFS(Rodadas!$F$2:$F$65,"Limpo",Rodadas!$C$2:$C$65,"Unitário",Rodadas!$D$2:$D$65,"COT",Rodadas!$Q$2:$Q$65,">0") -> 3 | Q6: =COUNTIFS(Rodadas!$F$2:$F$65,"Limpo",Rodadas!$C$2:$C$65,"Unitário",Rodadas!$D$2:$D$65,"COT",Rodadas!$M$2:$M$65,"<>executa") -> 0
A7: Limpo | B7: Unitário | C7: Todas | D7: =COUNTIFS(Rodadas!$F$2:$F$65,"Limpo",Rodadas!$C$2:$C$65,"Unitário") -> 21 | E7: =SUMIFS(Rodadas!$J$2:$J$65,Rodadas!$F$2:$F$65,"Limpo",Rodadas!$C$2:$C$65,"Unitário") -> 264 | F7: =SUMIFS(Rodadas!$K$2:$K$65,Rodadas!$F$2:$F$65,"Limpo",Rodadas!$C$2:$C$65,"Unitário") -> 264 | G7: =IFERROR(F7/E7,0) -> 1 | H7: =COUNTIFS(Rodadas!$F$2:$F$65,"Limpo",Rodadas!$C$2:$C$65,"Unitário",Rodadas!$L$2:$L$65,0,Rodadas!$K$2:$K$65,">0") -> 21 | I7: =COUNTIFS(Rodadas!$F$2:$F$65,"Limpo",Rodadas!$C$2:$C$65,"Unitário",Rodadas!$I$2:$I$65,"Sim") -> 21 | J7: =COUNTIFS(Rodadas!$F$2:$F$65,"Limpo",Rodadas!$C$2:$C$65,"Unitário",Rodadas!$O$2:$O$65,">0") -> 2 | K7: =SUMIFS(Rodadas!$O$2:$O$65,Rodadas!$F$2:$F$65,"Limpo",Rodadas!$C$2:$C$65,"Unitário") -> 2 | L7: =IFERROR(K7/D7,0) -> 0.095238095 | M7: =COUNTIFS(Rodadas!$F$2:$F$65,"Limpo",Rodadas!$C$2:$C$65,"Unitário",Rodadas!$O$2:$O$65,3) -> 0 | N7: =SUMIFS(Rodadas!$P$2:$P$65,Rodadas!$F$2:$F$65,"Limpo",Rodadas!$C$2:$C$65,"Unitário") -> 32 | O7: =SUMIFS(Rodadas!$Q$2:$Q$65,Rodadas!$F$2:$F$65,"Limpo",Rodadas!$C$2:$C$65,"Unitário") -> 10 | P7: =COUNTIFS(Rodadas!$F$2:$F$65,"Limpo",Rodadas!$C$2:$C$65,"Unitário",Rodadas!$Q$2:$Q$65,">0") -> 8 | Q7: =COUNTIFS(Rodadas!$F$2:$F$65,"Limpo",Rodadas!$C$2:$C$65,"Unitário",Rodadas!$M$2:$M$65,"<>executa") -> 0
A8: Limpo | B8: Widget | C8: ZS | D8: =COUNTIFS(Rodadas!$F$2:$F$65,"Limpo",Rodadas!$C$2:$C$65,"Widget",Rodadas!$D$2:$D$65,"ZS") -> 3 | E8: =SUMIFS(Rodadas!$J$2:$J$65,Rodadas!$F$2:$F$65,"Limpo",Rodadas!$C$2:$C$65,"Widget",Rodadas!$D$2:$D$65,"ZS") -> 19 | F8: =SUMIFS(Rodadas!$K$2:$K$65,Rodadas!$F$2:$F$65,"Limpo",Rodadas!$C$2:$C$65,"Widget",Rodadas!$D$2:$D$65,"ZS") -> 19 | G8: =IFERROR(F8/E8,0) -> 1 | H8: =COUNTIFS(Rodadas!$F$2:$F$65,"Limpo",Rodadas!$C$2:$C$65,"Widget",Rodadas!$D$2:$D$65,"ZS",Rodadas!$L$2:$L$65,0,Rodadas!$K$2:$K$65,">0") -> 3 | I8: =COUNTIFS(Rodadas!$F$2:$F$65,"Limpo",Rodadas!$C$2:$C$65,"Widget",Rodadas!$D$2:$D$65,"ZS",Rodadas!$I$2:$I$65,"Sim") -> 3 | J8: =COUNTIFS(Rodadas!$F$2:$F$65,"Limpo",Rodadas!$C$2:$C$65,"Widget",Rodadas!$D$2:$D$65,"ZS",Rodadas!$O$2:$O$65,">0") -> 2 | K8: =SUMIFS(Rodadas!$O$2:$O$65,Rodadas!$F$2:$F$65,"Limpo",Rodadas!$C$2:$C$65,"Widget",Rodadas!$D$2:$D$65,"ZS") -> 5 | L8: =IFERROR(K8/D8,0) -> 1.6666667 | M8: =COUNTIFS(Rodadas!$F$2:$F$65,"Limpo",Rodadas!$C$2:$C$65,"Widget",Rodadas!$D$2:$D$65,"ZS",Rodadas!$O$2:$O$65,3) -> 1 | N8: =SUMIFS(Rodadas!$P$2:$P$65,Rodadas!$F$2:$F$65,"Limpo",Rodadas!$C$2:$C$65,"Widget",Rodadas!$D$2:$D$65,"ZS") -> 4 | O8: =SUMIFS(Rodadas!$Q$2:$Q$65,Rodadas!$F$2:$F$65,"Limpo",Rodadas!$C$2:$C$65,"Widget",Rodadas!$D$2:$D$65,"ZS") -> 0 | P8: =COUNTIFS(Rodadas!$F$2:$F$65,"Limpo",Rodadas!$C$2:$C$65,"Widget",Rodadas!$D$2:$D$65,"ZS",Rodadas!$Q$2:$Q$65,">0") -> 0 | Q8: =COUNTIFS(Rodadas!$F$2:$F$65,"Limpo",Rodadas!$C$2:$C$65,"Widget",Rodadas!$D$2:$D$65,"ZS",Rodadas!$M$2:$M$65,"<>executa") -> 0
A9: Limpo | B9: Widget | C9: FS | D9: =COUNTIFS(Rodadas!$F$2:$F$65,"Limpo",Rodadas!$C$2:$C$65,"Widget",Rodadas!$D$2:$D$65,"FS") -> 3 | E9: =SUMIFS(Rodadas!$J$2:$J$65,Rodadas!$F$2:$F$65,"Limpo",Rodadas!$C$2:$C$65,"Widget",Rodadas!$D$2:$D$65,"FS") -> 21 | F9: =SUMIFS(Rodadas!$K$2:$K$65,Rodadas!$F$2:$F$65,"Limpo",Rodadas!$C$2:$C$65,"Widget",Rodadas!$D$2:$D$65,"FS") -> 21 | G9: =IFERROR(F9/E9,0) -> 1 | H9: =COUNTIFS(Rodadas!$F$2:$F$65,"Limpo",Rodadas!$C$2:$C$65,"Widget",Rodadas!$D$2:$D$65,"FS",Rodadas!$L$2:$L$65,0,Rodadas!$K$2:$K$65,">0") -> 3 | I9: =COUNTIFS(Rodadas!$F$2:$F$65,"Limpo",Rodadas!$C$2:$C$65,"Widget",Rodadas!$D$2:$D$65,"FS",Rodadas!$I$2:$I$65,"Sim") -> 3 | J9: =COUNTIFS(Rodadas!$F$2:$F$65,"Limpo",Rodadas!$C$2:$C$65,"Widget",Rodadas!$D$2:$D$65,"FS",Rodadas!$O$2:$O$65,">0") -> 2 | K9: =SUMIFS(Rodadas!$O$2:$O$65,Rodadas!$F$2:$F$65,"Limpo",Rodadas!$C$2:$C$65,"Widget",Rodadas!$D$2:$D$65,"FS") -> 3 | L9: =IFERROR(K9/D9,0) -> 1 | M9: =COUNTIFS(Rodadas!$F$2:$F$65,"Limpo",Rodadas!$C$2:$C$65,"Widget",Rodadas!$D$2:$D$65,"FS",Rodadas!$O$2:$O$65,3) -> 0 | N9: =SUMIFS(Rodadas!$P$2:$P$65,Rodadas!$F$2:$F$65,"Limpo",Rodadas!$C$2:$C$65,"Widget",Rodadas!$D$2:$D$65,"FS") -> 6 | O9: =SUMIFS(Rodadas!$Q$2:$Q$65,Rodadas!$F$2:$F$65,"Limpo",Rodadas!$C$2:$C$65,"Widget",Rodadas!$D$2:$D$65,"FS") -> 3 | P9: =COUNTIFS(Rodadas!$F$2:$F$65,"Limpo",Rodadas!$C$2:$C$65,"Widget",Rodadas!$D$2:$D$65,"FS",Rodadas!$Q$2:$Q$65,">0") -> 3 | Q9: =COUNTIFS(Rodadas!$F$2:$F$65,"Limpo",Rodadas!$C$2:$C$65,"Widget",Rodadas!$D$2:$D$65,"FS",Rodadas!$M$2:$M$65,"<>executa") -> 0
A10: Limpo | B10: Widget | C10: COT | D10: =COUNTIFS(Rodadas!$F$2:$F$65,"Limpo",Rodadas!$C$2:$C$65,"Widget",Rodadas!$D$2:$D$65,"COT") -> 3 | E10: =SUMIFS(Rodadas!$J$2:$J$65,Rodadas!$F$2:$F$65,"Limpo",Rodadas!$C$2:$C$65,"Widget",Rodadas!$D$2:$D$65,"COT") -> 31 | F10: =SUMIFS(Rodadas!$K$2:$K$65,Rodadas!$F$2:$F$65,"Limpo",Rodadas!$C$2:$C$65,"Widget",Rodadas!$D$2:$D$65,"COT") -> 15 | G10: =IFERROR(F10/E10,0) -> 0.48387097 | H10: =COUNTIFS(Rodadas!$F$2:$F$65,"Limpo",Rodadas!$C$2:$C$65,"Widget",Rodadas!$D$2:$D$65,"COT",Rodadas!$L$2:$L$65,0,Rodadas!$K$2:$K$65,">0") -> 0 | I10: =COUNTIFS(Rodadas!$F$2:$F$65,"Limpo",Rodadas!$C$2:$C$65,"Widget",Rodadas!$D$2:$D$65,"COT",Rodadas!$I$2:$I$65,"Sim") -> 0 | J10: =COUNTIFS(Rodadas!$F$2:$F$65,"Limpo",Rodadas!$C$2:$C$65,"Widget",Rodadas!$D$2:$D$65,"COT",Rodadas!$O$2:$O$65,">0") -> 3 | K10: =SUMIFS(Rodadas!$O$2:$O$65,Rodadas!$F$2:$F$65,"Limpo",Rodadas!$C$2:$C$65,"Widget",Rodadas!$D$2:$D$65,"COT") -> 9 | L10: =IFERROR(K10/D10,0) -> 3 | M10: =COUNTIFS(Rodadas!$F$2:$F$65,"Limpo",Rodadas!$C$2:$C$65,"Widget",Rodadas!$D$2:$D$65,"COT",Rodadas!$O$2:$O$65,3) -> 3 | N10: =SUMIFS(Rodadas!$P$2:$P$65,Rodadas!$F$2:$F$65,"Limpo",Rodadas!$C$2:$C$65,"Widget",Rodadas!$D$2:$D$65,"COT") -> 7 | O10: =SUMIFS(Rodadas!$Q$2:$Q$65,Rodadas!$F$2:$F$65,"Limpo",Rodadas!$C$2:$C$65,"Widget",Rodadas!$D$2:$D$65,"COT") -> 3 | P10: =COUNTIFS(Rodadas!$F$2:$F$65,"Limpo",Rodadas!$C$2:$C$65,"Widget",Rodadas!$D$2:$D$65,"COT",Rodadas!$Q$2:$Q$65,">0") -> 2 | Q10: =COUNTIFS(Rodadas!$F$2:$F$65,"Limpo",Rodadas!$C$2:$C$65,"Widget",Rodadas!$D$2:$D$65,"COT",Rodadas!$M$2:$M$65,"<>executa") -> 0
A11: Limpo | B11: Widget | C11: Todas | D11: =COUNTIFS(Rodadas!$F$2:$F$65,"Limpo",Rodadas!$C$2:$C$65,"Widget") -> 9 | E11: =SUMIFS(Rodadas!$J$2:$J$65,Rodadas!$F$2:$F$65,"Limpo",Rodadas!$C$2:$C$65,"Widget") -> 71 | F11: =SUMIFS(Rodadas!$K$2:$K$65,Rodadas!$F$2:$F$65,"Limpo",Rodadas!$C$2:$C$65,"Widget") -> 55 | G11: =IFERROR(F11/E11,0) -> 0.77464789 | H11: =COUNTIFS(Rodadas!$F$2:$F$65,"Limpo",Rodadas!$C$2:$C$65,"Widget",Rodadas!$L$2:$L$65,0,Rodadas!$K$2:$K$65,">0") -> 6 | I11: =COUNTIFS(Rodadas!$F$2:$F$65,"Limpo",Rodadas!$C$2:$C$65,"Widget",Rodadas!$I$2:$I$65,"Sim") -> 6 | J11: =COUNTIFS(Rodadas!$F$2:$F$65,"Limpo",Rodadas!$C$2:$C$65,"Widget",Rodadas!$O$2:$O$65,">0") -> 7 | K11: =SUMIFS(Rodadas!$O$2:$O$65,Rodadas!$F$2:$F$65,"Limpo",Rodadas!$C$2:$C$65,"Widget") -> 17 | L11: =IFERROR(K11/D11,0) -> 1.8888889 | M11: =COUNTIFS(Rodadas!$F$2:$F$65,"Limpo",Rodadas!$C$2:$C$65,"Widget",Rodadas!$O$2:$O$65,3) -> 4 | N11: =SUMIFS(Rodadas!$P$2:$P$65,Rodadas!$F$2:$F$65,"Limpo",Rodadas!$C$2:$C$65,"Widget") -> 17 | O11: =SUMIFS(Rodadas!$Q$2:$Q$65,Rodadas!$F$2:$F$65,"Limpo",Rodadas!$C$2:$C$65,"Widget") -> 6 | P11: =COUNTIFS(Rodadas!$F$2:$F$65,"Limpo",Rodadas!$C$2:$C$65,"Widget",Rodadas!$Q$2:$Q$65,">0") -> 5 | Q11: =COUNTIFS(Rodadas!$F$2:$F$65,"Limpo",Rodadas!$C$2:$C$65,"Widget",Rodadas!$M$2:$M$65,"<>executa") -> 0
A12: Limpo | B12: Integração | C12: ZS | D12: =COUNTIFS(Rodadas!$F$2:$F$65,"Limpo",Rodadas!$C$2:$C$65,"Integração",Rodadas!$D$2:$D$65,"ZS") -> 3 | E12: =SUMIFS(Rodadas!$J$2:$J$65,Rodadas!$F$2:$F$65,"Limpo",Rodadas!$C$2:$C$65,"Integração",Rodadas!$D$2:$D$65,"ZS") -> 14 | F12: =SUMIFS(Rodadas!$K$2:$K$65,Rodadas!$F$2:$F$65,"Limpo",Rodadas!$C$2:$C$65,"Integração",Rodadas!$D$2:$D$65,"ZS") -> 9 | G12: =IFERROR(F12/E12,0) -> 0.64285714 | H12: =COUNTIFS(Rodadas!$F$2:$F$65,"Limpo",Rodadas!$C$2:$C$65,"Integração",Rodadas!$D$2:$D$65,"ZS",Rodadas!$L$2:$L$65,0,Rodadas!$K$2:$K$65,">0") -> 1 | I12: =COUNTIFS(Rodadas!$F$2:$F$65,"Limpo",Rodadas!$C$2:$C$65,"Integração",Rodadas!$D$2:$D$65,"ZS",Rodadas!$I$2:$I$65,"Sim") -> 1 | J12: =COUNTIFS(Rodadas!$F$2:$F$65,"Limpo",Rodadas!$C$2:$C$65,"Integração",Rodadas!$D$2:$D$65,"ZS",Rodadas!$O$2:$O$65,">0") -> 2 | K12: =SUMIFS(Rodadas!$O$2:$O$65,Rodadas!$F$2:$F$65,"Limpo",Rodadas!$C$2:$C$65,"Integração",Rodadas!$D$2:$D$65,"ZS") -> 6 | L12: =IFERROR(K12/D12,0) -> 2 | M12: =COUNTIFS(Rodadas!$F$2:$F$65,"Limpo",Rodadas!$C$2:$C$65,"Integração",Rodadas!$D$2:$D$65,"ZS",Rodadas!$O$2:$O$65,3) -> 2 | N12: =SUMIFS(Rodadas!$P$2:$P$65,Rodadas!$F$2:$F$65,"Limpo",Rodadas!$C$2:$C$65,"Integração",Rodadas!$D$2:$D$65,"ZS") -> 3 | O12: =SUMIFS(Rodadas!$Q$2:$Q$65,Rodadas!$F$2:$F$65,"Limpo",Rodadas!$C$2:$C$65,"Integração",Rodadas!$D$2:$D$65,"ZS") -> 0 | P12: =COUNTIFS(Rodadas!$F$2:$F$65,"Limpo",Rodadas!$C$2:$C$65,"Integração",Rodadas!$D$2:$D$65,"ZS",Rodadas!$Q$2:$Q$65,">0") -> 0 | Q12: =COUNTIFS(Rodadas!$F$2:$F$65,"Limpo",Rodadas!$C$2:$C$65,"Integração",Rodadas!$D$2:$D$65,"ZS",Rodadas!$M$2:$M$65,"<>executa") -> 1
A13: Limpo | B13: Integração | C13: FS | D13: =COUNTIFS(Rodadas!$F$2:$F$65,"Limpo",Rodadas!$C$2:$C$65,"Integração",Rodadas!$D$2:$D$65,"FS") -> 3 | E13: =SUMIFS(Rodadas!$J$2:$J$65,Rodadas!$F$2:$F$65,"Limpo",Rodadas!$C$2:$C$65,"Integração",Rodadas!$D$2:$D$65,"FS") -> 8 | F13: =SUMIFS(Rodadas!$K$2:$K$65,Rodadas!$F$2:$F$65,"Limpo",Rodadas!$C$2:$C$65,"Integração",Rodadas!$D$2:$D$65,"FS") -> 3 | G13: =IFERROR(F13/E13,0) -> 0.375 | H13: =COUNTIFS(Rodadas!$F$2:$F$65,"Limpo",Rodadas!$C$2:$C$65,"Integração",Rodadas!$D$2:$D$65,"FS",Rodadas!$L$2:$L$65,0,Rodadas!$K$2:$K$65,">0") -> 1 | I13: =COUNTIFS(Rodadas!$F$2:$F$65,"Limpo",Rodadas!$C$2:$C$65,"Integração",Rodadas!$D$2:$D$65,"FS",Rodadas!$I$2:$I$65,"Sim") -> 1 | J13: =COUNTIFS(Rodadas!$F$2:$F$65,"Limpo",Rodadas!$C$2:$C$65,"Integração",Rodadas!$D$2:$D$65,"FS",Rodadas!$O$2:$O$65,">0") -> 2 | K13: =SUMIFS(Rodadas!$O$2:$O$65,Rodadas!$F$2:$F$65,"Limpo",Rodadas!$C$2:$C$65,"Integração",Rodadas!$D$2:$D$65,"FS") -> 6 | L13: =IFERROR(K13/D13,0) -> 2 | M13: =COUNTIFS(Rodadas!$F$2:$F$65,"Limpo",Rodadas!$C$2:$C$65,"Integração",Rodadas!$D$2:$D$65,"FS",Rodadas!$O$2:$O$65,3) -> 2 | N13: =SUMIFS(Rodadas!$P$2:$P$65,Rodadas!$F$2:$F$65,"Limpo",Rodadas!$C$2:$C$65,"Integração",Rodadas!$D$2:$D$65,"FS") -> 4 | O13: =SUMIFS(Rodadas!$Q$2:$Q$65,Rodadas!$F$2:$F$65,"Limpo",Rodadas!$C$2:$C$65,"Integração",Rodadas!$D$2:$D$65,"FS") -> 1 | P13: =COUNTIFS(Rodadas!$F$2:$F$65,"Limpo",Rodadas!$C$2:$C$65,"Integração",Rodadas!$D$2:$D$65,"FS",Rodadas!$Q$2:$Q$65,">0") -> 1 | Q13: =COUNTIFS(Rodadas!$F$2:$F$65,"Limpo",Rodadas!$C$2:$C$65,"Integração",Rodadas!$D$2:$D$65,"FS",Rodadas!$M$2:$M$65,"<>executa") -> 0
A14: Limpo | B14: Integração | C14: COT | D14: =COUNTIFS(Rodadas!$F$2:$F$65,"Limpo",Rodadas!$C$2:$C$65,"Integração",Rodadas!$D$2:$D$65,"COT") -> 3 | E14: =SUMIFS(Rodadas!$J$2:$J$65,Rodadas!$F$2:$F$65,"Limpo",Rodadas!$C$2:$C$65,"Integração",Rodadas!$D$2:$D$65,"COT") -> 19 | F14: =SUMIFS(Rodadas!$K$2:$K$65,Rodadas!$F$2:$F$65,"Limpo",Rodadas!$C$2:$C$65,"Integração",Rodadas!$D$2:$D$65,"COT") -> 11 | G14: =IFERROR(F14/E14,0) -> 0.57894737 | H14: =COUNTIFS(Rodadas!$F$2:$F$65,"Limpo",Rodadas!$C$2:$C$65,"Integração",Rodadas!$D$2:$D$65,"COT",Rodadas!$L$2:$L$65,0,Rodadas!$K$2:$K$65,">0") -> 2 | I14: =COUNTIFS(Rodadas!$F$2:$F$65,"Limpo",Rodadas!$C$2:$C$65,"Integração",Rodadas!$D$2:$D$65,"COT",Rodadas!$I$2:$I$65,"Sim") -> 2 | J14: =COUNTIFS(Rodadas!$F$2:$F$65,"Limpo",Rodadas!$C$2:$C$65,"Integração",Rodadas!$D$2:$D$65,"COT",Rodadas!$O$2:$O$65,">0") -> 3 | K14: =SUMIFS(Rodadas!$O$2:$O$65,Rodadas!$F$2:$F$65,"Limpo",Rodadas!$C$2:$C$65,"Integração",Rodadas!$D$2:$D$65,"COT") -> 8 | L14: =IFERROR(K14/D14,0) -> 2.6666667 | M14: =COUNTIFS(Rodadas!$F$2:$F$65,"Limpo",Rodadas!$C$2:$C$65,"Integração",Rodadas!$D$2:$D$65,"COT",Rodadas!$O$2:$O$65,3) -> 2 | N14: =SUMIFS(Rodadas!$P$2:$P$65,Rodadas!$F$2:$F$65,"Limpo",Rodadas!$C$2:$C$65,"Integração",Rodadas!$D$2:$D$65,"COT") -> 3 | O14: =SUMIFS(Rodadas!$Q$2:$Q$65,Rodadas!$F$2:$F$65,"Limpo",Rodadas!$C$2:$C$65,"Integração",Rodadas!$D$2:$D$65,"COT") -> 0 | P14: =COUNTIFS(Rodadas!$F$2:$F$65,"Limpo",Rodadas!$C$2:$C$65,"Integração",Rodadas!$D$2:$D$65,"COT",Rodadas!$Q$2:$Q$65,">0") -> 0 | Q14: =COUNTIFS(Rodadas!$F$2:$F$65,"Limpo",Rodadas!$C$2:$C$65,"Integração",Rodadas!$D$2:$D$65,"COT",Rodadas!$M$2:$M$65,"<>executa") -> 1
A15: Limpo | B15: Integração | C15: Todas | D15: =COUNTIFS(Rodadas!$F$2:$F$65,"Limpo",Rodadas!$C$2:$C$65,"Integração") -> 9 | E15: =SUMIFS(Rodadas!$J$2:$J$65,Rodadas!$F$2:$F$65,"Limpo",Rodadas!$C$2:$C$65,"Integração") -> 41 | F15: =SUMIFS(Rodadas!$K$2:$K$65,Rodadas!$F$2:$F$65,"Limpo",Rodadas!$C$2:$C$65,"Integração") -> 23 | G15: =IFERROR(F15/E15,0) -> 0.56097561 | H15: =COUNTIFS(Rodadas!$F$2:$F$65,"Limpo",Rodadas!$C$2:$C$65,"Integração",Rodadas!$L$2:$L$65,0,Rodadas!$K$2:$K$65,">0") -> 4 | I15: =COUNTIFS(Rodadas!$F$2:$F$65,"Limpo",Rodadas!$C$2:$C$65,"Integração",Rodadas!$I$2:$I$65,"Sim") -> 4 | J15: =COUNTIFS(Rodadas!$F$2:$F$65,"Limpo",Rodadas!$C$2:$C$65,"Integração",Rodadas!$O$2:$O$65,">0") -> 7 | K15: =SUMIFS(Rodadas!$O$2:$O$65,Rodadas!$F$2:$F$65,"Limpo",Rodadas!$C$2:$C$65,"Integração") -> 20 | L15: =IFERROR(K15/D15,0) -> 2.2222222 | M15: =COUNTIFS(Rodadas!$F$2:$F$65,"Limpo",Rodadas!$C$2:$C$65,"Integração",Rodadas!$O$2:$O$65,3) -> 6 | N15: =SUMIFS(Rodadas!$P$2:$P$65,Rodadas!$F$2:$F$65,"Limpo",Rodadas!$C$2:$C$65,"Integração") -> 10 | O15: =SUMIFS(Rodadas!$Q$2:$Q$65,Rodadas!$F$2:$F$65,"Limpo",Rodadas!$C$2:$C$65,"Integração") -> 1 | P15: =COUNTIFS(Rodadas!$F$2:$F$65,"Limpo",Rodadas!$C$2:$C$65,"Integração",Rodadas!$Q$2:$Q$65,">0") -> 1 | Q15: =COUNTIFS(Rodadas!$F$2:$F$65,"Limpo",Rodadas!$C$2:$C$65,"Integração",Rodadas!$M$2:$M$65,"<>executa") -> 2
A16: Limpo | B16: Todos | C16: Todas | D16: =COUNTIFS(Rodadas!$F$2:$F$65,"Limpo") -> 39 | E16: =SUMIFS(Rodadas!$J$2:$J$65,Rodadas!$F$2:$F$65,"Limpo") -> 376 | F16: =SUMIFS(Rodadas!$K$2:$K$65,Rodadas!$F$2:$F$65,"Limpo") -> 342 | G16: =IFERROR(F16/E16,0) -> 0.90957447 | H16: =COUNTIFS(Rodadas!$F$2:$F$65,"Limpo",Rodadas!$L$2:$L$65,0,Rodadas!$K$2:$K$65,">0") -> 31 | I16: =COUNTIFS(Rodadas!$F$2:$F$65,"Limpo",Rodadas!$I$2:$I$65,"Sim") -> 31 | J16: =COUNTIFS(Rodadas!$F$2:$F$65,"Limpo",Rodadas!$O$2:$O$65,">0") -> 16 | K16: =SUMIFS(Rodadas!$O$2:$O$65,Rodadas!$F$2:$F$65,"Limpo") -> 39 | L16: =IFERROR(K16/D16,0) -> 1 | M16: =COUNTIFS(Rodadas!$F$2:$F$65,"Limpo",Rodadas!$O$2:$O$65,3) -> 10 | N16: =SUMIFS(Rodadas!$P$2:$P$65,Rodadas!$F$2:$F$65,"Limpo") -> 59 | O16: =SUMIFS(Rodadas!$Q$2:$Q$65,Rodadas!$F$2:$F$65,"Limpo") -> 17 | P16: =COUNTIFS(Rodadas!$F$2:$F$65,"Limpo",Rodadas!$Q$2:$Q$65,">0") -> 14 | Q16: =COUNTIFS(Rodadas!$F$2:$F$65,"Limpo",Rodadas!$M$2:$M$65,"<>executa") -> 2
A18: Bug plantado | B18: Unitário | C18: ZS | D18: =COUNTIFS(Rodadas!$F$2:$F$65,"Bug plantado",Rodadas!$C$2:$C$65,"Unitário",Rodadas!$D$2:$D$65,"ZS") -> 2 | E18: =SUMIFS(Rodadas!$J$2:$J$65,Rodadas!$F$2:$F$65,"Bug plantado",Rodadas!$C$2:$C$65,"Unitário",Rodadas!$D$2:$D$65,"ZS") -> 18 | F18: =SUMIFS(Rodadas!$K$2:$K$65,Rodadas!$F$2:$F$65,"Bug plantado",Rodadas!$C$2:$C$65,"Unitário",Rodadas!$D$2:$D$65,"ZS") -> 18 | G18: =IFERROR(F18/E18,0) -> 1 | H18: =COUNTIFS(Rodadas!$F$2:$F$65,"Bug plantado",Rodadas!$C$2:$C$65,"Unitário",Rodadas!$D$2:$D$65,"ZS",Rodadas!$L$2:$L$65,0,Rodadas!$K$2:$K$65,">0") -> 2 | I18: =COUNTIFS(Rodadas!$F$2:$F$65,"Bug plantado",Rodadas!$C$2:$C$65,"Unitário",Rodadas!$D$2:$D$65,"ZS",Rodadas!$I$2:$I$65,"Sim") -> 2 | J18: =COUNTIFS(Rodadas!$F$2:$F$65,"Bug plantado",Rodadas!$C$2:$C$65,"Unitário",Rodadas!$D$2:$D$65,"ZS",Rodadas!$O$2:$O$65,">0") -> 0 | K18: =SUMIFS(Rodadas!$O$2:$O$65,Rodadas!$F$2:$F$65,"Bug plantado",Rodadas!$C$2:$C$65,"Unitário",Rodadas!$D$2:$D$65,"ZS") -> 0 | L18: =IFERROR(K18/D18,0) -> 0 | M18: =COUNTIFS(Rodadas!$F$2:$F$65,"Bug plantado",Rodadas!$C$2:$C$65,"Unitário",Rodadas!$D$2:$D$65,"ZS",Rodadas!$O$2:$O$65,3) -> 0 | N18: =SUMIFS(Rodadas!$P$2:$P$65,Rodadas!$F$2:$F$65,"Bug plantado",Rodadas!$C$2:$C$65,"Unitário",Rodadas!$D$2:$D$65,"ZS") -> 2 | O18: =SUMIFS(Rodadas!$Q$2:$Q$65,Rodadas!$F$2:$F$65,"Bug plantado",Rodadas!$C$2:$C$65,"Unitário",Rodadas!$D$2:$D$65,"ZS") -> 0 | P18: =COUNTIFS(Rodadas!$F$2:$F$65,"Bug plantado",Rodadas!$C$2:$C$65,"Unitário",Rodadas!$D$2:$D$65,"ZS",Rodadas!$Q$2:$Q$65,">0") -> 0 | Q18: =COUNTIFS(Rodadas!$F$2:$F$65,"Bug plantado",Rodadas!$C$2:$C$65,"Unitário",Rodadas!$D$2:$D$65,"ZS",Rodadas!$M$2:$M$65,"<>executa") -> 0
A19: Bug plantado | B19: Unitário | C19: FS | D19: =COUNTIFS(Rodadas!$F$2:$F$65,"Bug plantado",Rodadas!$C$2:$C$65,"Unitário",Rodadas!$D$2:$D$65,"FS") -> 2 | E19: =SUMIFS(Rodadas!$J$2:$J$65,Rodadas!$F$2:$F$65,"Bug plantado",Rodadas!$C$2:$C$65,"Unitário",Rodadas!$D$2:$D$65,"FS") -> 11 | F19: =SUMIFS(Rodadas!$K$2:$K$65,Rodadas!$F$2:$F$65,"Bug plantado",Rodadas!$C$2:$C$65,"Unitário",Rodadas!$D$2:$D$65,"FS") -> 11 | G19: =IFERROR(F19/E19,0) -> 1 | H19: =COUNTIFS(Rodadas!$F$2:$F$65,"Bug plantado",Rodadas!$C$2:$C$65,"Unitário",Rodadas!$D$2:$D$65,"FS",Rodadas!$L$2:$L$65,0,Rodadas!$K$2:$K$65,">0") -> 2 | I19: =COUNTIFS(Rodadas!$F$2:$F$65,"Bug plantado",Rodadas!$C$2:$C$65,"Unitário",Rodadas!$D$2:$D$65,"FS",Rodadas!$I$2:$I$65,"Sim") -> 2 | J19: =COUNTIFS(Rodadas!$F$2:$F$65,"Bug plantado",Rodadas!$C$2:$C$65,"Unitário",Rodadas!$D$2:$D$65,"FS",Rodadas!$O$2:$O$65,">0") -> 0 | K19: =SUMIFS(Rodadas!$O$2:$O$65,Rodadas!$F$2:$F$65,"Bug plantado",Rodadas!$C$2:$C$65,"Unitário",Rodadas!$D$2:$D$65,"FS") -> 0 | L19: =IFERROR(K19/D19,0) -> 0 | M19: =COUNTIFS(Rodadas!$F$2:$F$65,"Bug plantado",Rodadas!$C$2:$C$65,"Unitário",Rodadas!$D$2:$D$65,"FS",Rodadas!$O$2:$O$65,3) -> 0 | N19: =SUMIFS(Rodadas!$P$2:$P$65,Rodadas!$F$2:$F$65,"Bug plantado",Rodadas!$C$2:$C$65,"Unitário",Rodadas!$D$2:$D$65,"FS") -> 2 | O19: =SUMIFS(Rodadas!$Q$2:$Q$65,Rodadas!$F$2:$F$65,"Bug plantado",Rodadas!$C$2:$C$65,"Unitário",Rodadas!$D$2:$D$65,"FS") -> 0 | P19: =COUNTIFS(Rodadas!$F$2:$F$65,"Bug plantado",Rodadas!$C$2:$C$65,"Unitário",Rodadas!$D$2:$D$65,"FS",Rodadas!$Q$2:$Q$65,">0") -> 0 | Q19: =COUNTIFS(Rodadas!$F$2:$F$65,"Bug plantado",Rodadas!$C$2:$C$65,"Unitário",Rodadas!$D$2:$D$65,"FS",Rodadas!$M$2:$M$65,"<>executa") -> 0
A20: Bug plantado | B20: Unitário | C20: COT | D20: =COUNTIFS(Rodadas!$F$2:$F$65,"Bug plantado",Rodadas!$C$2:$C$65,"Unitário",Rodadas!$D$2:$D$65,"COT") -> 2 | E20: =SUMIFS(Rodadas!$J$2:$J$65,Rodadas!$F$2:$F$65,"Bug plantado",Rodadas!$C$2:$C$65,"Unitário",Rodadas!$D$2:$D$65,"COT") -> 18 | F20: =SUMIFS(Rodadas!$K$2:$K$65,Rodadas!$F$2:$F$65,"Bug plantado",Rodadas!$C$2:$C$65,"Unitário",Rodadas!$D$2:$D$65,"COT") -> 18 | G20: =IFERROR(F20/E20,0) -> 1 | H20: =COUNTIFS(Rodadas!$F$2:$F$65,"Bug plantado",Rodadas!$C$2:$C$65,"Unitário",Rodadas!$D$2:$D$65,"COT",Rodadas!$L$2:$L$65,0,Rodadas!$K$2:$K$65,">0") -> 2 | I20: =COUNTIFS(Rodadas!$F$2:$F$65,"Bug plantado",Rodadas!$C$2:$C$65,"Unitário",Rodadas!$D$2:$D$65,"COT",Rodadas!$I$2:$I$65,"Sim") -> 2 | J20: =COUNTIFS(Rodadas!$F$2:$F$65,"Bug plantado",Rodadas!$C$2:$C$65,"Unitário",Rodadas!$D$2:$D$65,"COT",Rodadas!$O$2:$O$65,">0") -> 0 | K20: =SUMIFS(Rodadas!$O$2:$O$65,Rodadas!$F$2:$F$65,"Bug plantado",Rodadas!$C$2:$C$65,"Unitário",Rodadas!$D$2:$D$65,"COT") -> 0 | L20: =IFERROR(K20/D20,0) -> 0 | M20: =COUNTIFS(Rodadas!$F$2:$F$65,"Bug plantado",Rodadas!$C$2:$C$65,"Unitário",Rodadas!$D$2:$D$65,"COT",Rodadas!$O$2:$O$65,3) -> 0 | N20: =SUMIFS(Rodadas!$P$2:$P$65,Rodadas!$F$2:$F$65,"Bug plantado",Rodadas!$C$2:$C$65,"Unitário",Rodadas!$D$2:$D$65,"COT") -> 3 | O20: =SUMIFS(Rodadas!$Q$2:$Q$65,Rodadas!$F$2:$F$65,"Bug plantado",Rodadas!$C$2:$C$65,"Unitário",Rodadas!$D$2:$D$65,"COT") -> 1 | P20: =COUNTIFS(Rodadas!$F$2:$F$65,"Bug plantado",Rodadas!$C$2:$C$65,"Unitário",Rodadas!$D$2:$D$65,"COT",Rodadas!$Q$2:$Q$65,">0") -> 1 | Q20: =COUNTIFS(Rodadas!$F$2:$F$65,"Bug plantado",Rodadas!$C$2:$C$65,"Unitário",Rodadas!$D$2:$D$65,"COT",Rodadas!$M$2:$M$65,"<>executa") -> 0
A21: Bug plantado | B21: Unitário | C21: Todas | D21: =COUNTIFS(Rodadas!$F$2:$F$65,"Bug plantado",Rodadas!$C$2:$C$65,"Unitário") -> 6 | E21: =SUMIFS(Rodadas!$J$2:$J$65,Rodadas!$F$2:$F$65,"Bug plantado",Rodadas!$C$2:$C$65,"Unitário") -> 47 | F21: =SUMIFS(Rodadas!$K$2:$K$65,Rodadas!$F$2:$F$65,"Bug plantado",Rodadas!$C$2:$C$65,"Unitário") -> 47 | G21: =IFERROR(F21/E21,0) -> 1 | H21: =COUNTIFS(Rodadas!$F$2:$F$65,"Bug plantado",Rodadas!$C$2:$C$65,"Unitário",Rodadas!$L$2:$L$65,0,Rodadas!$K$2:$K$65,">0") -> 6 | I21: =COUNTIFS(Rodadas!$F$2:$F$65,"Bug plantado",Rodadas!$C$2:$C$65,"Unitário",Rodadas!$I$2:$I$65,"Sim") -> 6 | J21: =COUNTIFS(Rodadas!$F$2:$F$65,"Bug plantado",Rodadas!$C$2:$C$65,"Unitário",Rodadas!$O$2:$O$65,">0") -> 0 | K21: =SUMIFS(Rodadas!$O$2:$O$65,Rodadas!$F$2:$F$65,"Bug plantado",Rodadas!$C$2:$C$65,"Unitário") -> 0 | L21: =IFERROR(K21/D21,0) -> 0 | M21: =COUNTIFS(Rodadas!$F$2:$F$65,"Bug plantado",Rodadas!$C$2:$C$65,"Unitário",Rodadas!$O$2:$O$65,3) -> 0 | N21: =SUMIFS(Rodadas!$P$2:$P$65,Rodadas!$F$2:$F$65,"Bug plantado",Rodadas!$C$2:$C$65,"Unitário") -> 7 | O21: =SUMIFS(Rodadas!$Q$2:$Q$65,Rodadas!$F$2:$F$65,"Bug plantado",Rodadas!$C$2:$C$65,"Unitário") -> 1 | P21: =COUNTIFS(Rodadas!$F$2:$F$65,"Bug plantado",Rodadas!$C$2:$C$65,"Unitário",Rodadas!$Q$2:$Q$65,">0") -> 1 | Q21: =COUNTIFS(Rodadas!$F$2:$F$65,"Bug plantado",Rodadas!$C$2:$C$65,"Unitário",Rodadas!$M$2:$M$65,"<>executa") -> 0
A22: Bug plantado | B22: Widget | C22: ZS | D22: =COUNTIFS(Rodadas!$F$2:$F$65,"Bug plantado",Rodadas!$C$2:$C$65,"Widget",Rodadas!$D$2:$D$65,"ZS") -> 2 | E22: =SUMIFS(Rodadas!$J$2:$J$65,Rodadas!$F$2:$F$65,"Bug plantado",Rodadas!$C$2:$C$65,"Widget",Rodadas!$D$2:$D$65,"ZS") -> 16 | F22: =SUMIFS(Rodadas!$K$2:$K$65,Rodadas!$F$2:$F$65,"Bug plantado",Rodadas!$C$2:$C$65,"Widget",Rodadas!$D$2:$D$65,"ZS") -> 15 | G22: =IFERROR(F22/E22,0) -> 0.9375 | H22: =COUNTIFS(Rodadas!$F$2:$F$65,"Bug plantado",Rodadas!$C$2:$C$65,"Widget",Rodadas!$D$2:$D$65,"ZS",Rodadas!$L$2:$L$65,0,Rodadas!$K$2:$K$65,">0") -> 1 | I22: =COUNTIFS(Rodadas!$F$2:$F$65,"Bug plantado",Rodadas!$C$2:$C$65,"Widget",Rodadas!$D$2:$D$65,"ZS",Rodadas!$I$2:$I$65,"Sim") -> 2 | J22: =COUNTIFS(Rodadas!$F$2:$F$65,"Bug plantado",Rodadas!$C$2:$C$65,"Widget",Rodadas!$D$2:$D$65,"ZS",Rodadas!$O$2:$O$65,">0") -> 1 | K22: =SUMIFS(Rodadas!$O$2:$O$65,Rodadas!$F$2:$F$65,"Bug plantado",Rodadas!$C$2:$C$65,"Widget",Rodadas!$D$2:$D$65,"ZS") -> 2 | L22: =IFERROR(K22/D22,0) -> 1 | M22: =COUNTIFS(Rodadas!$F$2:$F$65,"Bug plantado",Rodadas!$C$2:$C$65,"Widget",Rodadas!$D$2:$D$65,"ZS",Rodadas!$O$2:$O$65,3) -> 0 | N22: =SUMIFS(Rodadas!$P$2:$P$65,Rodadas!$F$2:$F$65,"Bug plantado",Rodadas!$C$2:$C$65,"Widget",Rodadas!$D$2:$D$65,"ZS") -> 3 | O22: =SUMIFS(Rodadas!$Q$2:$Q$65,Rodadas!$F$2:$F$65,"Bug plantado",Rodadas!$C$2:$C$65,"Widget",Rodadas!$D$2:$D$65,"ZS") -> 1 | P22: =COUNTIFS(Rodadas!$F$2:$F$65,"Bug plantado",Rodadas!$C$2:$C$65,"Widget",Rodadas!$D$2:$D$65,"ZS",Rodadas!$Q$2:$Q$65,">0") -> 1 | Q22: =COUNTIFS(Rodadas!$F$2:$F$65,"Bug plantado",Rodadas!$C$2:$C$65,"Widget",Rodadas!$D$2:$D$65,"ZS",Rodadas!$M$2:$M$65,"<>executa") -> 0
A23: Bug plantado | B23: Widget | C23: FS | D23: =COUNTIFS(Rodadas!$F$2:$F$65,"Bug plantado",Rodadas!$C$2:$C$65,"Widget",Rodadas!$D$2:$D$65,"FS") -> 2 | E23: =SUMIFS(Rodadas!$J$2:$J$65,Rodadas!$F$2:$F$65,"Bug plantado",Rodadas!$C$2:$C$65,"Widget",Rodadas!$D$2:$D$65,"FS") -> 14 | F23: =SUMIFS(Rodadas!$K$2:$K$65,Rodadas!$F$2:$F$65,"Bug plantado",Rodadas!$C$2:$C$65,"Widget",Rodadas!$D$2:$D$65,"FS") -> 12 | G23: =IFERROR(F23/E23,0) -> 0.85714286 | H23: =COUNTIFS(Rodadas!$F$2:$F$65,"Bug plantado",Rodadas!$C$2:$C$65,"Widget",Rodadas!$D$2:$D$65,"FS",Rodadas!$L$2:$L$65,0,Rodadas!$K$2:$K$65,">0") -> 1 | I23: =COUNTIFS(Rodadas!$F$2:$F$65,"Bug plantado",Rodadas!$C$2:$C$65,"Widget",Rodadas!$D$2:$D$65,"FS",Rodadas!$I$2:$I$65,"Sim") -> 0 | J23: =COUNTIFS(Rodadas!$F$2:$F$65,"Bug plantado",Rodadas!$C$2:$C$65,"Widget",Rodadas!$D$2:$D$65,"FS",Rodadas!$O$2:$O$65,">0") -> 2 | K23: =SUMIFS(Rodadas!$O$2:$O$65,Rodadas!$F$2:$F$65,"Bug plantado",Rodadas!$C$2:$C$65,"Widget",Rodadas!$D$2:$D$65,"FS") -> 5 | L23: =IFERROR(K23/D23,0) -> 2.5 | M23: =COUNTIFS(Rodadas!$F$2:$F$65,"Bug plantado",Rodadas!$C$2:$C$65,"Widget",Rodadas!$D$2:$D$65,"FS",Rodadas!$O$2:$O$65,3) -> 1 | N23: =SUMIFS(Rodadas!$P$2:$P$65,Rodadas!$F$2:$F$65,"Bug plantado",Rodadas!$C$2:$C$65,"Widget",Rodadas!$D$2:$D$65,"FS") -> 2 | O23: =SUMIFS(Rodadas!$Q$2:$Q$65,Rodadas!$F$2:$F$65,"Bug plantado",Rodadas!$C$2:$C$65,"Widget",Rodadas!$D$2:$D$65,"FS") -> 0 | P23: =COUNTIFS(Rodadas!$F$2:$F$65,"Bug plantado",Rodadas!$C$2:$C$65,"Widget",Rodadas!$D$2:$D$65,"FS",Rodadas!$Q$2:$Q$65,">0") -> 0 | Q23: =COUNTIFS(Rodadas!$F$2:$F$65,"Bug plantado",Rodadas!$C$2:$C$65,"Widget",Rodadas!$D$2:$D$65,"FS",Rodadas!$M$2:$M$65,"<>executa") -> 0
A24: Bug plantado | B24: Widget | C24: COT | D24: =COUNTIFS(Rodadas!$F$2:$F$65,"Bug plantado",Rodadas!$C$2:$C$65,"Widget",Rodadas!$D$2:$D$65,"COT") -> 2 | E24: =SUMIFS(Rodadas!$J$2:$J$65,Rodadas!$F$2:$F$65,"Bug plantado",Rodadas!$C$2:$C$65,"Widget",Rodadas!$D$2:$D$65,"COT") -> 19 | F24: =SUMIFS(Rodadas!$K$2:$K$65,Rodadas!$F$2:$F$65,"Bug plantado",Rodadas!$C$2:$C$65,"Widget",Rodadas!$D$2:$D$65,"COT") -> 18 | G24: =IFERROR(F24/E24,0) -> 0.94736842 | H24: =COUNTIFS(Rodadas!$F$2:$F$65,"Bug plantado",Rodadas!$C$2:$C$65,"Widget",Rodadas!$D$2:$D$65,"COT",Rodadas!$L$2:$L$65,0,Rodadas!$K$2:$K$65,">0") -> 1 | I24: =COUNTIFS(Rodadas!$F$2:$F$65,"Bug plantado",Rodadas!$C$2:$C$65,"Widget",Rodadas!$D$2:$D$65,"COT",Rodadas!$I$2:$I$65,"Sim") -> 2 | J24: =COUNTIFS(Rodadas!$F$2:$F$65,"Bug plantado",Rodadas!$C$2:$C$65,"Widget",Rodadas!$D$2:$D$65,"COT",Rodadas!$O$2:$O$65,">0") -> 1 | K24: =SUMIFS(Rodadas!$O$2:$O$65,Rodadas!$F$2:$F$65,"Bug plantado",Rodadas!$C$2:$C$65,"Widget",Rodadas!$D$2:$D$65,"COT") -> 1 | L24: =IFERROR(K24/D24,0) -> 0.5 | M24: =COUNTIFS(Rodadas!$F$2:$F$65,"Bug plantado",Rodadas!$C$2:$C$65,"Widget",Rodadas!$D$2:$D$65,"COT",Rodadas!$O$2:$O$65,3) -> 0 | N24: =SUMIFS(Rodadas!$P$2:$P$65,Rodadas!$F$2:$F$65,"Bug plantado",Rodadas!$C$2:$C$65,"Widget",Rodadas!$D$2:$D$65,"COT") -> 2 | O24: =SUMIFS(Rodadas!$Q$2:$Q$65,Rodadas!$F$2:$F$65,"Bug plantado",Rodadas!$C$2:$C$65,"Widget",Rodadas!$D$2:$D$65,"COT") -> 0 | P24: =COUNTIFS(Rodadas!$F$2:$F$65,"Bug plantado",Rodadas!$C$2:$C$65,"Widget",Rodadas!$D$2:$D$65,"COT",Rodadas!$Q$2:$Q$65,">0") -> 0 | Q24: =COUNTIFS(Rodadas!$F$2:$F$65,"Bug plantado",Rodadas!$C$2:$C$65,"Widget",Rodadas!$D$2:$D$65,"COT",Rodadas!$M$2:$M$65,"<>executa") -> 0
A25: Bug plantado | B25: Widget | C25: Todas | D25: =COUNTIFS(Rodadas!$F$2:$F$65,"Bug plantado",Rodadas!$C$2:$C$65,"Widget") -> 6 | E25: =SUMIFS(Rodadas!$J$2:$J$65,Rodadas!$F$2:$F$65,"Bug plantado",Rodadas!$C$2:$C$65,"Widget") -> 49 | F25: =SUMIFS(Rodadas!$K$2:$K$65,Rodadas!$F$2:$F$65,"Bug plantado",Rodadas!$C$2:$C$65,"Widget") -> 45 | G25: =IFERROR(F25/E25,0) -> 0.91836735 | H25: =COUNTIFS(Rodadas!$F$2:$F$65,"Bug plantado",Rodadas!$C$2:$C$65,"Widget",Rodadas!$L$2:$L$65,0,Rodadas!$K$2:$K$65,">0") -> 3 | I25: =COUNTIFS(Rodadas!$F$2:$F$65,"Bug plantado",Rodadas!$C$2:$C$65,"Widget",Rodadas!$I$2:$I$65,"Sim") -> 4 | J25: =COUNTIFS(Rodadas!$F$2:$F$65,"Bug plantado",Rodadas!$C$2:$C$65,"Widget",Rodadas!$O$2:$O$65,">0") -> 4 | K25: =SUMIFS(Rodadas!$O$2:$O$65,Rodadas!$F$2:$F$65,"Bug plantado",Rodadas!$C$2:$C$65,"Widget") -> 8 | L25: =IFERROR(K25/D25,0) -> 1.3333333 | M25: =COUNTIFS(Rodadas!$F$2:$F$65,"Bug plantado",Rodadas!$C$2:$C$65,"Widget",Rodadas!$O$2:$O$65,3) -> 1 | N25: =SUMIFS(Rodadas!$P$2:$P$65,Rodadas!$F$2:$F$65,"Bug plantado",Rodadas!$C$2:$C$65,"Widget") -> 7 | O25: =SUMIFS(Rodadas!$Q$2:$Q$65,Rodadas!$F$2:$F$65,"Bug plantado",Rodadas!$C$2:$C$65,"Widget") -> 1 | P25: =COUNTIFS(Rodadas!$F$2:$F$65,"Bug plantado",Rodadas!$C$2:$C$65,"Widget",Rodadas!$Q$2:$Q$65,">0") -> 1 | Q25: =COUNTIFS(Rodadas!$F$2:$F$65,"Bug plantado",Rodadas!$C$2:$C$65,"Widget",Rodadas!$M$2:$M$65,"<>executa") -> 0
A26: Bug plantado | B26: Integração | C26: ZS | D26: =COUNTIFS(Rodadas!$F$2:$F$65,"Bug plantado",Rodadas!$C$2:$C$65,"Integração",Rodadas!$D$2:$D$65,"ZS") -> 2 | E26: =SUMIFS(Rodadas!$J$2:$J$65,Rodadas!$F$2:$F$65,"Bug plantado",Rodadas!$C$2:$C$65,"Integração",Rodadas!$D$2:$D$65,"ZS") -> 7 | F26: =SUMIFS(Rodadas!$K$2:$K$65,Rodadas!$F$2:$F$65,"Bug plantado",Rodadas!$C$2:$C$65,"Integração",Rodadas!$D$2:$D$65,"ZS") -> 3 | G26: =IFERROR(F26/E26,0) -> 0.42857143 | H26: =COUNTIFS(Rodadas!$F$2:$F$65,"Bug plantado",Rodadas!$C$2:$C$65,"Integração",Rodadas!$D$2:$D$65,"ZS",Rodadas!$L$2:$L$65,0,Rodadas!$K$2:$K$65,">0") -> 1 | I26: =COUNTIFS(Rodadas!$F$2:$F$65,"Bug plantado",Rodadas!$C$2:$C$65,"Integração",Rodadas!$D$2:$D$65,"ZS",Rodadas!$I$2:$I$65,"Sim") -> 1 | J26: =COUNTIFS(Rodadas!$F$2:$F$65,"Bug plantado",Rodadas!$C$2:$C$65,"Integração",Rodadas!$D$2:$D$65,"ZS",Rodadas!$O$2:$O$65,">0") -> 2 | K26: =SUMIFS(Rodadas!$O$2:$O$65,Rodadas!$F$2:$F$65,"Bug plantado",Rodadas!$C$2:$C$65,"Integração",Rodadas!$D$2:$D$65,"ZS") -> 4 | L26: =IFERROR(K26/D26,0) -> 2 | M26: =COUNTIFS(Rodadas!$F$2:$F$65,"Bug plantado",Rodadas!$C$2:$C$65,"Integração",Rodadas!$D$2:$D$65,"ZS",Rodadas!$O$2:$O$65,3) -> 1 | N26: =SUMIFS(Rodadas!$P$2:$P$65,Rodadas!$F$2:$F$65,"Bug plantado",Rodadas!$C$2:$C$65,"Integração",Rodadas!$D$2:$D$65,"ZS") -> 2 | O26: =SUMIFS(Rodadas!$Q$2:$Q$65,Rodadas!$F$2:$F$65,"Bug plantado",Rodadas!$C$2:$C$65,"Integração",Rodadas!$D$2:$D$65,"ZS") -> 0 | P26: =COUNTIFS(Rodadas!$F$2:$F$65,"Bug plantado",Rodadas!$C$2:$C$65,"Integração",Rodadas!$D$2:$D$65,"ZS",Rodadas!$Q$2:$Q$65,">0") -> 0 | Q26: =COUNTIFS(Rodadas!$F$2:$F$65,"Bug plantado",Rodadas!$C$2:$C$65,"Integração",Rodadas!$D$2:$D$65,"ZS",Rodadas!$M$2:$M$65,"<>executa") -> 0
A27: Bug plantado | B27: Integração | C27: FS | D27: =COUNTIFS(Rodadas!$F$2:$F$65,"Bug plantado",Rodadas!$C$2:$C$65,"Integração",Rodadas!$D$2:$D$65,"FS") -> 2 | E27: =SUMIFS(Rodadas!$J$2:$J$65,Rodadas!$F$2:$F$65,"Bug plantado",Rodadas!$C$2:$C$65,"Integração",Rodadas!$D$2:$D$65,"FS") -> 6 | F27: =SUMIFS(Rodadas!$K$2:$K$65,Rodadas!$F$2:$F$65,"Bug plantado",Rodadas!$C$2:$C$65,"Integração",Rodadas!$D$2:$D$65,"FS") -> 1 | G27: =IFERROR(F27/E27,0) -> 0.16666667 | H27: =COUNTIFS(Rodadas!$F$2:$F$65,"Bug plantado",Rodadas!$C$2:$C$65,"Integração",Rodadas!$D$2:$D$65,"FS",Rodadas!$L$2:$L$65,0,Rodadas!$K$2:$K$65,">0") -> 0 | I27: =COUNTIFS(Rodadas!$F$2:$F$65,"Bug plantado",Rodadas!$C$2:$C$65,"Integração",Rodadas!$D$2:$D$65,"FS",Rodadas!$I$2:$I$65,"Sim") -> 0 | J27: =COUNTIFS(Rodadas!$F$2:$F$65,"Bug plantado",Rodadas!$C$2:$C$65,"Integração",Rodadas!$D$2:$D$65,"FS",Rodadas!$O$2:$O$65,">0") -> 2 | K27: =SUMIFS(Rodadas!$O$2:$O$65,Rodadas!$F$2:$F$65,"Bug plantado",Rodadas!$C$2:$C$65,"Integração",Rodadas!$D$2:$D$65,"FS") -> 5 | L27: =IFERROR(K27/D27,0) -> 2.5 | M27: =COUNTIFS(Rodadas!$F$2:$F$65,"Bug plantado",Rodadas!$C$2:$C$65,"Integração",Rodadas!$D$2:$D$65,"FS",Rodadas!$O$2:$O$65,3) -> 1 | N27: =SUMIFS(Rodadas!$P$2:$P$65,Rodadas!$F$2:$F$65,"Bug plantado",Rodadas!$C$2:$C$65,"Integração",Rodadas!$D$2:$D$65,"FS") -> 2 | O27: =SUMIFS(Rodadas!$Q$2:$Q$65,Rodadas!$F$2:$F$65,"Bug plantado",Rodadas!$C$2:$C$65,"Integração",Rodadas!$D$2:$D$65,"FS") -> 0 | P27: =COUNTIFS(Rodadas!$F$2:$F$65,"Bug plantado",Rodadas!$C$2:$C$65,"Integração",Rodadas!$D$2:$D$65,"FS",Rodadas!$Q$2:$Q$65,">0") -> 0 | Q27: =COUNTIFS(Rodadas!$F$2:$F$65,"Bug plantado",Rodadas!$C$2:$C$65,"Integração",Rodadas!$D$2:$D$65,"FS",Rodadas!$M$2:$M$65,"<>executa") -> 1
A28: Bug plantado | B28: Integração | C28: COT | D28: =COUNTIFS(Rodadas!$F$2:$F$65,"Bug plantado",Rodadas!$C$2:$C$65,"Integração",Rodadas!$D$2:$D$65,"COT") -> 2 | E28: =SUMIFS(Rodadas!$J$2:$J$65,Rodadas!$F$2:$F$65,"Bug plantado",Rodadas!$C$2:$C$65,"Integração",Rodadas!$D$2:$D$65,"COT") -> 10 | F28: =SUMIFS(Rodadas!$K$2:$K$65,Rodadas!$F$2:$F$65,"Bug plantado",Rodadas!$C$2:$C$65,"Integração",Rodadas!$D$2:$D$65,"COT") -> 6 | G28: =IFERROR(F28/E28,0) -> 0.6 | H28: =COUNTIFS(Rodadas!$F$2:$F$65,"Bug plantado",Rodadas!$C$2:$C$65,"Integração",Rodadas!$D$2:$D$65,"COT",Rodadas!$L$2:$L$65,0,Rodadas!$K$2:$K$65,">0") -> 1 | I28: =COUNTIFS(Rodadas!$F$2:$F$65,"Bug plantado",Rodadas!$C$2:$C$65,"Integração",Rodadas!$D$2:$D$65,"COT",Rodadas!$I$2:$I$65,"Sim") -> 1 | J28: =COUNTIFS(Rodadas!$F$2:$F$65,"Bug plantado",Rodadas!$C$2:$C$65,"Integração",Rodadas!$D$2:$D$65,"COT",Rodadas!$O$2:$O$65,">0") -> 2 | K28: =SUMIFS(Rodadas!$O$2:$O$65,Rodadas!$F$2:$F$65,"Bug plantado",Rodadas!$C$2:$C$65,"Integração",Rodadas!$D$2:$D$65,"COT") -> 4 | L28: =IFERROR(K28/D28,0) -> 2 | M28: =COUNTIFS(Rodadas!$F$2:$F$65,"Bug plantado",Rodadas!$C$2:$C$65,"Integração",Rodadas!$D$2:$D$65,"COT",Rodadas!$O$2:$O$65,3) -> 1 | N28: =SUMIFS(Rodadas!$P$2:$P$65,Rodadas!$F$2:$F$65,"Bug plantado",Rodadas!$C$2:$C$65,"Integração",Rodadas!$D$2:$D$65,"COT") -> 2 | O28: =SUMIFS(Rodadas!$Q$2:$Q$65,Rodadas!$F$2:$F$65,"Bug plantado",Rodadas!$C$2:$C$65,"Integração",Rodadas!$D$2:$D$65,"COT") -> 0 | P28: =COUNTIFS(Rodadas!$F$2:$F$65,"Bug plantado",Rodadas!$C$2:$C$65,"Integração",Rodadas!$D$2:$D$65,"COT",Rodadas!$Q$2:$Q$65,">0") -> 0 | Q28: =COUNTIFS(Rodadas!$F$2:$F$65,"Bug plantado",Rodadas!$C$2:$C$65,"Integração",Rodadas!$D$2:$D$65,"COT",Rodadas!$M$2:$M$65,"<>executa") -> 0
A29: Bug plantado | B29: Integração | C29: Todas | D29: =COUNTIFS(Rodadas!$F$2:$F$65,"Bug plantado",Rodadas!$C$2:$C$65,"Integração") -> 6 | E29: =SUMIFS(Rodadas!$J$2:$J$65,Rodadas!$F$2:$F$65,"Bug plantado",Rodadas!$C$2:$C$65,"Integração") -> 23 | F29: =SUMIFS(Rodadas!$K$2:$K$65,Rodadas!$F$2:$F$65,"Bug plantado",Rodadas!$C$2:$C$65,"Integração") -> 10 | G29: =IFERROR(F29/E29,0) -> 0.43478261 | H29: =COUNTIFS(Rodadas!$F$2:$F$65,"Bug plantado",Rodadas!$C$2:$C$65,"Integração",Rodadas!$L$2:$L$65,0,Rodadas!$K$2:$K$65,">0") -> 2 | I29: =COUNTIFS(Rodadas!$F$2:$F$65,"Bug plantado",Rodadas!$C$2:$C$65,"Integração",Rodadas!$I$2:$I$65,"Sim") -> 2 | J29: =COUNTIFS(Rodadas!$F$2:$F$65,"Bug plantado",Rodadas!$C$2:$C$65,"Integração",Rodadas!$O$2:$O$65,">0") -> 6 | K29: =SUMIFS(Rodadas!$O$2:$O$65,Rodadas!$F$2:$F$65,"Bug plantado",Rodadas!$C$2:$C$65,"Integração") -> 13 | L29: =IFERROR(K29/D29,0) -> 2.1666667 | M29: =COUNTIFS(Rodadas!$F$2:$F$65,"Bug plantado",Rodadas!$C$2:$C$65,"Integração",Rodadas!$O$2:$O$65,3) -> 3 | N29: =SUMIFS(Rodadas!$P$2:$P$65,Rodadas!$F$2:$F$65,"Bug plantado",Rodadas!$C$2:$C$65,"Integração") -> 6 | O29: =SUMIFS(Rodadas!$Q$2:$Q$65,Rodadas!$F$2:$F$65,"Bug plantado",Rodadas!$C$2:$C$65,"Integração") -> 0 | P29: =COUNTIFS(Rodadas!$F$2:$F$65,"Bug plantado",Rodadas!$C$2:$C$65,"Integração",Rodadas!$Q$2:$Q$65,">0") -> 0 | Q29: =COUNTIFS(Rodadas!$F$2:$F$65,"Bug plantado",Rodadas!$C$2:$C$65,"Integração",Rodadas!$M$2:$M$65,"<>executa") -> 1
A30: Bug plantado | B30: Todos | C30: Todas | D30: =COUNTIFS(Rodadas!$F$2:$F$65,"Bug plantado") -> 18 | E30: =SUMIFS(Rodadas!$J$2:$J$65,Rodadas!$F$2:$F$65,"Bug plantado") -> 119 | F30: =SUMIFS(Rodadas!$K$2:$K$65,Rodadas!$F$2:$F$65,"Bug plantado") -> 102 | G30: =IFERROR(F30/E30,0) -> 0.85714286 | H30: =COUNTIFS(Rodadas!$F$2:$F$65,"Bug plantado",Rodadas!$L$2:$L$65,0,Rodadas!$K$2:$K$65,">0") -> 11 | I30: =COUNTIFS(Rodadas!$F$2:$F$65,"Bug plantado",Rodadas!$I$2:$I$65,"Sim") -> 12 | J30: =COUNTIFS(Rodadas!$F$2:$F$65,"Bug plantado",Rodadas!$O$2:$O$65,">0") -> 10 | K30: =SUMIFS(Rodadas!$O$2:$O$65,Rodadas!$F$2:$F$65,"Bug plantado") -> 21 | L30: =IFERROR(K30/D30,0) -> 1.1666667 | M30: =COUNTIFS(Rodadas!$F$2:$F$65,"Bug plantado",Rodadas!$O$2:$O$65,3) -> 4 | N30: =SUMIFS(Rodadas!$P$2:$P$65,Rodadas!$F$2:$F$65,"Bug plantado") -> 20 | O30: =SUMIFS(Rodadas!$Q$2:$Q$65,Rodadas!$F$2:$F$65,"Bug plantado") -> 2 | P30: =COUNTIFS(Rodadas!$F$2:$F$65,"Bug plantado",Rodadas!$Q$2:$Q$65,">0") -> 2 | Q30: =COUNTIFS(Rodadas!$F$2:$F$65,"Bug plantado",Rodadas!$M$2:$M$65,"<>executa") -> 1
A32: formatName (bug nativo) | B32: Unitário | C32: ZS | D32: =COUNTIFS(Rodadas!$F$2:$F$65,"formatName (bug nativo)",Rodadas!$C$2:$C$65,"Unitário",Rodadas!$D$2:$D$65,"ZS") -> 1 | E32: =SUMIFS(Rodadas!$J$2:$J$65,Rodadas!$F$2:$F$65,"formatName (bug nativo)",Rodadas!$C$2:$C$65,"Unitário",Rodadas!$D$2:$D$65,"ZS") -> 10 | F32: =SUMIFS(Rodadas!$K$2:$K$65,Rodadas!$F$2:$F$65,"formatName (bug nativo)",Rodadas!$C$2:$C$65,"Unitário",Rodadas!$D$2:$D$65,"ZS") -> 10 | G32: =IFERROR(F32/E32,0) -> 1 | H32: =COUNTIFS(Rodadas!$F$2:$F$65,"formatName (bug nativo)",Rodadas!$C$2:$C$65,"Unitário",Rodadas!$D$2:$D$65,"ZS",Rodadas!$L$2:$L$65,0,Rodadas!$K$2:$K$65,">0") -> 1 | I32: =COUNTIFS(Rodadas!$F$2:$F$65,"formatName (bug nativo)",Rodadas!$C$2:$C$65,"Unitário",Rodadas!$D$2:$D$65,"ZS",Rodadas!$I$2:$I$65,"Sim") -> 1 | J32: =COUNTIFS(Rodadas!$F$2:$F$65,"formatName (bug nativo)",Rodadas!$C$2:$C$65,"Unitário",Rodadas!$D$2:$D$65,"ZS",Rodadas!$O$2:$O$65,">0") -> 0 | K32: =SUMIFS(Rodadas!$O$2:$O$65,Rodadas!$F$2:$F$65,"formatName (bug nativo)",Rodadas!$C$2:$C$65,"Unitário",Rodadas!$D$2:$D$65,"ZS") -> 0 | L32: =IFERROR(K32/D32,0) -> 0 | M32: =COUNTIFS(Rodadas!$F$2:$F$65,"formatName (bug nativo)",Rodadas!$C$2:$C$65,"Unitário",Rodadas!$D$2:$D$65,"ZS",Rodadas!$O$2:$O$65,3) -> 0 | N32: =SUMIFS(Rodadas!$P$2:$P$65,Rodadas!$F$2:$F$65,"formatName (bug nativo)",Rodadas!$C$2:$C$65,"Unitário",Rodadas!$D$2:$D$65,"ZS") -> 3 | O32: =SUMIFS(Rodadas!$Q$2:$Q$65,Rodadas!$F$2:$F$65,"formatName (bug nativo)",Rodadas!$C$2:$C$65,"Unitário",Rodadas!$D$2:$D$65,"ZS") -> 2 | P32: =COUNTIFS(Rodadas!$F$2:$F$65,"formatName (bug nativo)",Rodadas!$C$2:$C$65,"Unitário",Rodadas!$D$2:$D$65,"ZS",Rodadas!$Q$2:$Q$65,">0") -> 1 | Q32: =COUNTIFS(Rodadas!$F$2:$F$65,"formatName (bug nativo)",Rodadas!$C$2:$C$65,"Unitário",Rodadas!$D$2:$D$65,"ZS",Rodadas!$M$2:$M$65,"<>executa") -> 0
A33: formatName (bug nativo) | B33: Unitário | C33: FS | D33: =COUNTIFS(Rodadas!$F$2:$F$65,"formatName (bug nativo)",Rodadas!$C$2:$C$65,"Unitário",Rodadas!$D$2:$D$65,"FS") -> 1 | E33: =SUMIFS(Rodadas!$J$2:$J$65,Rodadas!$F$2:$F$65,"formatName (bug nativo)",Rodadas!$C$2:$C$65,"Unitário",Rodadas!$D$2:$D$65,"FS") -> 5 | F33: =SUMIFS(Rodadas!$K$2:$K$65,Rodadas!$F$2:$F$65,"formatName (bug nativo)",Rodadas!$C$2:$C$65,"Unitário",Rodadas!$D$2:$D$65,"FS") -> 5 | G33: =IFERROR(F33/E33,0) -> 1 | H33: =COUNTIFS(Rodadas!$F$2:$F$65,"formatName (bug nativo)",Rodadas!$C$2:$C$65,"Unitário",Rodadas!$D$2:$D$65,"FS",Rodadas!$L$2:$L$65,0,Rodadas!$K$2:$K$65,">0") -> 1 | I33: =COUNTIFS(Rodadas!$F$2:$F$65,"formatName (bug nativo)",Rodadas!$C$2:$C$65,"Unitário",Rodadas!$D$2:$D$65,"FS",Rodadas!$I$2:$I$65,"Sim") -> 1 | J33: =COUNTIFS(Rodadas!$F$2:$F$65,"formatName (bug nativo)",Rodadas!$C$2:$C$65,"Unitário",Rodadas!$D$2:$D$65,"FS",Rodadas!$O$2:$O$65,">0") -> 0 | K33: =SUMIFS(Rodadas!$O$2:$O$65,Rodadas!$F$2:$F$65,"formatName (bug nativo)",Rodadas!$C$2:$C$65,"Unitário",Rodadas!$D$2:$D$65,"FS") -> 0 | L33: =IFERROR(K33/D33,0) -> 0 | M33: =COUNTIFS(Rodadas!$F$2:$F$65,"formatName (bug nativo)",Rodadas!$C$2:$C$65,"Unitário",Rodadas!$D$2:$D$65,"FS",Rodadas!$O$2:$O$65,3) -> 0 | N33: =SUMIFS(Rodadas!$P$2:$P$65,Rodadas!$F$2:$F$65,"formatName (bug nativo)",Rodadas!$C$2:$C$65,"Unitário",Rodadas!$D$2:$D$65,"FS") -> 1 | O33: =SUMIFS(Rodadas!$Q$2:$Q$65,Rodadas!$F$2:$F$65,"formatName (bug nativo)",Rodadas!$C$2:$C$65,"Unitário",Rodadas!$D$2:$D$65,"FS") -> 0 | P33: =COUNTIFS(Rodadas!$F$2:$F$65,"formatName (bug nativo)",Rodadas!$C$2:$C$65,"Unitário",Rodadas!$D$2:$D$65,"FS",Rodadas!$Q$2:$Q$65,">0") -> 0 | Q33: =COUNTIFS(Rodadas!$F$2:$F$65,"formatName (bug nativo)",Rodadas!$C$2:$C$65,"Unitário",Rodadas!$D$2:$D$65,"FS",Rodadas!$M$2:$M$65,"<>executa") -> 0
