Workbook

Sheet Leia-me
A1: Pirâmide de testes unificada — Fases 2 e 3, ChatGPT × Gemini (gerado em 2026-10-07)
A2: Fonte: fase2/ (ChatGPT, 60 rodadas: 49 originais + 15 reexecutadas em 2026-09-24 com reparo fixo), fase2-gemini-consolidado/ (Gemini, 60), fase3-e2e/ (36 rodadas E2E). Pass/fail = última saída de flutter test de cada rodada, verificada externamente (0 divergências nas três fases).
A3: Regras: REEXEC e formatName ficam fora da pirâmide (abas próprias/filtros). Limpos: 21 unitário + 9 widget + 9 integração + 9 E2E por modelo. Bugs: 6 + 6 + 6 + 9 por modelo (E2E: 7 com dado no ChatGPT).
A4: Taxa = passando ÷ (passando + falhando) somados nas rodadas cujo arquivo final executa; arquivo que não compila conta 0 passando e N falhando (N = testes declarados) e fica fora da taxa. Verde = executa com 0 falhas. Compilou 1ª = a geração inicial compilou.
A5: Detecção (codificação uniforme da Fase 2): Capturou (teste falha com o bug e é mantido) > Caracterizou c/ alerta (asserção fixa o comportamento com bug, mas a resposta o chama de defeito) > Viu sem asserção (resposta nomeia o defeito, sem asserção) > Canonizou (asserção fixa o comportamento com bug, sem alerta) > Não viu. Fase 3: 'Chegou sem afirmar' (Gemini C3-COT) mapeado para Não viu, conforme nota de equivalência do consolidado da Fase 3. 'Sem dado (serviço)' = ChatGPT P2-ZS e C3-COT, fora da contagem.
A6: (B) emitidos = iterações de reparo autoclassificadas (B) pelo modelo (contagem sobre o campo de classes de cada rodada). Corretos/falsos por auditoria humana: Fase 3 no consolidado_fase3.md §3; Fase 2 (bugs plantados) em comparacao_chatgpt_x_gemini.md §1.
A7: Condições de sessão: ChatGPT deslogado (GPT-5.5/5.6 nas 49 originais; GPT-5.6 Luna nas 15 reexecutadas e na Fase 3); Gemini logado Pro, 3.8 Flash. Não é carro-chefe × carro-chefe; declarar.

Sheet Rodadas
A1: Fase | B1: Nível | C1: Modelo | D1: Estratégia | E1: Grupo | F1: ID | G1: Bug | H1: Compilou 1ª (1/0) | I1: Gerados | J1: Passando (final) | K1: Falhando (final) | L1: Estado final | M1: Iterações | N1: Detecção (uniforme) | O1: (B) emitidos | P1: Verde (1/0)
A2: Fase 2 | B2: Unitário | C2: chatgpt | D2: COT | E2: Limpo | F2: FASE2-UNIT-COT-01_validateNome | H2: 1 | I2: 21 | J2: 21 | K2: 0 | L2: executa | M2: 0 | O2: 0 | P2: =IF(AND(L2="executa",K2=0,J2>0),1,0) -> 1
A3: Fase 2 | B3: Unitário | C3: chatgpt | D3: COT | E3: Limpo | F3: FASE2-UNIT-COT-03_validateNumero | H3: 1 | I3: 19 | J3: 19 | K3: 0 | L3: executa | M3: 1 | O3: 0 | P3: =IF(AND(L3="executa",K3=0,J3>0),1,0) -> 1
A4: Fase 2 | B4: Unitário | C4: chatgpt | D4: COT | E4: Limpo | F4: FASE2-UNIT-COT-04_validateCEP | H4: 1 | I4: 23 | J4: 23 | K4: 0 | L4: executa | M4: 0 | O4: 0 | P4: =IF(AND(L4="executa",K4=0,J4>0),1,0) -> 1
A5: Fase 2 | B5: Unitário | C5: chatgpt | D5: COT | E5: Limpo | F5: FASE2-UNIT-COT-05_validateEmail | H5: 1 | I5: 24 | J5: 24 | K5: 0 | L5: executa | M5: 0 | O5: 0 | P5: =IF(AND(L5="executa",K5=0,J5>0),1,0) -> 1
A6: Fase 2 | B6: Unitário | C6: chatgpt | D6: COT | E6: Limpo | F6: FASE2-UNIT-COT-06_validateEmailLogin | H6: 1 | I6: 19 | J6: 18 | K6: 1 | L6: executa | M6: 1 | O6: 1 | P6: =IF(AND(L6="executa",K6=0,J6>0),1,0) -> 0
A7: Fase 2 | B7: Unitário | C7: chatgpt | D7: COT | E7: Limpo | F7: FASE2-UNIT-COT-07_validateEmailEdit | H7: 1 | I7: 37 | J7: 37 | K7: 0 | L7: executa | M7: 0 | O7: 0 | P7: =IF(AND(L7="executa",K7=0,J7>0),1,0) -> 1
A8: Fase 2 | B8: Unitário | C8: chatgpt | D8: COT | E8: Limpo | F8: FASE2-UNIT-COT-10_validateDate | H8: 1 | I8: 32 | J8: 32 | K8: 0 | L8: executa | M8: 1 | O8: 0 | P8: =IF(AND(L8="executa",K8=0,J8>0),1,0) -> 1
A9: Fase 2 | B9: Unitário | C9: chatgpt | D9: FS | E9: Limpo | F9: FASE2-UNIT-FS-01_validateNome | H9: 1 | I9: 6 | J9: 6 | K9: 0 | L9: executa | M9: 0 | O9: 0 | P9: =IF(AND(L9="executa",K9=0,J9>0),1,0) -> 1
A10: Fase 2 | B10: Unitário | C10: chatgpt | D10: FS | E10: Limpo | F10: FASE2-UNIT-FS-03_validateNumero | H10: 1 | I10: 4 | J10: 4 | K10: 0 | L10: executa | M10: 0 | O10: 0 | P10: =IF(AND(L10="executa",K10=0,J10>0),1,0) -> 1
A11: Fase 2 | B11: Unitário | C11: chatgpt | D11: FS | E11: Limpo | F11: FASE2-UNIT-FS-04_validateCEP | H11: 1 | I11: 7 | J11: 7 | K11: 0 | L11: executa | M11: 0 | O11: 0 | P11: =IF(AND(L11="executa",K11=0,J11>0),1,0) -> 1
A12: Fase 2 | B12: Unitário | C12: chatgpt | D12: FS | E12: Limpo | F12: FASE2-UNIT-FS-05_validateEmail | H12: 1 | I12: 9 | J12: 9 | K12: 0 | L12: executa | M12: 0 | O12: 0 | P12: =IF(AND(L12="executa",K12=0,J12>0),1,0) -> 1
A13: Fase 2 | B13: Unitário | C13: chatgpt | D13: FS | E13: Limpo | F13: FASE2-UNIT-FS-06_validateEmailLogin | H13: 1 | I13: 6 | J13: 6 | K13: 0 | L13: executa | M13: 0 | O13: 0 | P13: =IF(AND(L13="executa",K13=0,J13>0),1,0) -> 1
... A22: Fase 2 | B22: Unitário | C22: chatgpt | D22: ZS | E22: Limpo | F22: FASE2-UNIT-ZS-10_validateDate | H22: 1 | I22: 33 | J22: 33 | K22: 0 | L22: executa | M22: 0 | O22: 0 | P22: =IF(AND(L22="executa",K22=0,J22>0),1,0) -> 1
A23: Fase 2 | B23: Unitário | C23: chatgpt | D23: COT | E23: Bug | F23: FASE2-UCRASH-COT | G23: U-CRASH | H23: 1 | I23: 12 | J23: 12 | K23: 0 | L23: executa | M23: 0 | N23: Caracterizou c/ alerta | O23: 0 | P23: =IF(AND(L23="executa",K23=0,J23>0),1,0) -> 1
A24: Fase 2 | B24: Unitário | C24: chatgpt | D24: COT | E24: Bug | F24: FASE2-USILENT-COT | G24: U-SILENT | H24: 1 | I24: 14 | J24: 14 | K24: 0 | L24: executa | M24: 0 | N24: Caracterizou c/ alerta | O24: 0 | P24: =IF(AND(L24="executa",K24=0,J24>0),1,0) -> 1
A25: Fase 2 | B25: Unitário | C25: chatgpt | D25: FS | E25: Bug | F25: FASE2-UCRASH-FS | G25: U-CRASH | H25: 1 | I25: 6 | J25: 5 | K25: 1 | L25: executa | M25: 1 | N25: Capturou | O25: 1 | P25: =IF(AND(L25="executa",K25=0,J25>0),1,0) -> 0
A26: Fase 2 | B26: Unitário | C26: chatgpt | D26: FS | E26: Bug | F26: FASE2-USILENT-FS | G26: U-SILENT | H26: 1 | I26: 6 | J26: 6 | K26: 0 | L26: executa | M26: 0 | N26: Caracterizou c/ alerta | O26: 0 | P26: =IF(AND(L26="executa",K26=0,J26>0),1,0) -> 1
A27: Fase 2 | B27: Unitário | C27: chatgpt | D27: ZS | E27: Bug | F27: FASE2-UCRASH-ZS | G27: U-CRASH | H27: 1 | I27: 12 | J27: 12 | K27: 0 | L27: executa | M27: 0 | N27: Caracterizou c/ alerta | O27: 0 | P27: =IF(AND(L27="executa",K27=0,J27>0),1,0) -> 1
A28: Fase 2 | B28: Unitário | C28: chatgpt | D28: ZS | E28: Bug | F28: FASE2-USILENT-ZS | G28: U-SILENT | H28: 1 | I28: 12 | J28: 12 | K28: 0 | L28: executa | M28: 0 | N28: Caracterizou c/ alerta | O28: 0 | P28: =IF(AND(L28="executa",K28=0,J28>0),1,0) -> 1
A29: Fase 2 | B29: Unitário | C29: chatgpt | D29: COT | E29: formatName | F29: FASE2-UNIT-COT-08_formatName | H29: 1 | I29: 15 | J29: 15 | K29: 0 | L29: executa | M29: 0 | O29: 0 | P29: =IF(AND(L29="executa",K29=0,J29>0),1,0) -> 1
A30: Fase 2 | B30: Unitário | C30: chatgpt | D30: FS | E30: formatName | F30: FASE2-UNIT-FS-08_formatName | H30: 1 | I30: 4 | J30: 4 | K30: 0 | L30: executa | M30: 0 | O30: 0 | P30: =IF(AND(L30="executa",K30=0,J30>0),1,0) -> 1
A31: Fase 2 | B31: Unitário | C31: chatgpt | D31: ZS | E31: formatName | F31: FASE2-UNIT-ZS-08_formatName | H31: 1 | I31: 13 | J31: 13 | K31: 0 | L31: executa | M31: 0 | O31: 0 | P31: =IF(AND(L31="executa",K31=0,J31>0),1,0) -> 1
A32: Fase 2 | B32: Unitário | C32: gemini | D32: COT | E32: Limpo | F32: FASE2-UNIT-COT-01_validateNome | H32: 1 | I32: 11 | J32: 11 | K32: 0 | L32: executa | M32: 0 | O32: 0 | P32: =IF(AND(L32="executa",K32=0,J32>0),1,0) -> 1
A33: Fase 2 | B33: Unitário | C33: gemini | D33: COT | E33: Limpo | F33: FASE2-UNIT-COT-03_validateNumero | H33: 1 | I33: 13 | J33: 13 | K33: 0 | L33: executa | M33: 1 | O33: 0 | P33: =IF(AND(L33="executa",K33=0,J33>0),1,0) -> 1
A34: Fase 2 | B34: Unitário | C34: gemini | D34: COT | E34: Limpo | F34: FASE2-UNIT-COT-04_validateCEP | H34: 1 | I34: 12 | J34: 12 | K34: 0 | L34: executa | M34: 0 | O34: 0 | P34: =IF(AND(L34="executa",K34=0,J34>0),1,0) -> 1
A35: Fase 2 | B35: Unitário | C35: gemini | D35: COT | E35: Limpo | F35: FASE2-UNIT-COT-05_validateEmail | H35: 1 | I35: 15 | J35: 15 | K35: 0 | L35: executa | M35: 0 | O35: 0 | P35: =IF(AND(L35="executa",K35=0,J35>0),1,0) -> 1
A36: Fase 2 | B36: Unitário | C36: gemini | D36: COT | E36: Limpo | F36: FASE2-UNIT-COT-06_validateEmailLogin | H36: 1 | I36: 11 | J36: 11 | K36: 0 | L36: executa | M36: 0 | O36: 0 | P36: =IF(AND(L36="executa",K36=0,J36>0),1,0) -> 1
A37: Fase 2 | B37: Unitário | C37: gemini | D37: COT | E37: Limpo | F37: FASE2-UNIT-COT-07_validateEmailEdit | H37: 1 | I37: 16 | J37: 16 | K37: 0 | L37: executa | M37: 0 | O37: 0 | P37: =IF(AND(L37="executa",K37=0,J37>0),1,0) -> 1
A38: Fase 2 | B38: Unitário | C38: gemini | D38: COT | E38: Limpo | F38: FASE2-UNIT-COT-10_validateDate | H38: 1 | I38: 19 | J38: 19 | K38: 0 | L38: executa | M38: 0 | O38: 0 | P38: =IF(AND(L38="executa",K38=0,J38>0),1,0) -> 1
A39: Fase 2 | B39: Unitário | C39: gemini | D39: FS | E39: Limpo | F39: FASE2-UNIT-FS-01_validateNome | H39: 1 | I39: 7 | J39: 7 | K39: 0 | L39: executa | M39: 0 | O39: 0 | P39: =IF(AND(L39="executa",K39=0,J39>0),1,0) -> 1
A40: Fase 2 | B40: Unitário | C40: gemini | D40: FS | E40: Limpo | F40: FASE2-UNIT-FS-03_validateNumero | H40: 1 | I40: 6 | J40: 6 | K40: 0 | L40: executa | M40: 0 | O40: 0 | P40: =IF(AND(L40="executa",K40=0,J40>0),1,0) -> 1
... A52: Fase 2 | B52: Unitário | C52: gemini | D52: ZS | E52: Limpo | F52: FASE2-UNIT-ZS-10_validateDate | H52: 1 | I52: 23 | J52: 23 | K52: 0 | L52: executa | M52: 0 | O52: 0 | P52: =IF(AND(L52="executa",K52=0,J52>0),1,0) -> 1
A53: Fase 2 | B53: Unitário | C53: gemini | D53: COT | E53: Bug | F53: FASE2-UCRASH-COT | G53: U-CRASH | H53: 1 | I53: 10 | J53: 10 | K53: 0 | L53: executa | M53: 0 | N53: Caracterizou c/ alerta | O53: 0 | P53: =IF(AND(L53="executa",K53=0,J53>0),1,0) -> 1
A54: Fase 2 | B54: Unitário | C54: gemini | D54: COT | E54: Bug | F54: FASE2-USILENT-COT | G54: U-SILENT | H54: 1 | I54: 8 | J54: 8 | K54: 0 | L54: executa | M54: 0 | N54: Caracterizou c/ alerta | O54: 0 | P54: =IF(AND(L54="executa",K54=0,J54>0),1,0) -> 1
A55: Fase 2 | B55: Unitário | C55: gemini | D55: FS | E55: Bug | F55: FASE2-UCRASH-FS | G55: U-CRASH | H55: 1 | I55: 6 | J55: 6 | K55: 0 | L55: executa | M55: 0 | N55: Viu sem asserção | O55: 0 | P55: =IF(AND(L55="executa",K55=0,J55>0),1,0) -> 1
A56: Fase 2 | B56: Unitário | C56: gemini | D56: FS | E56: Bug | F56: FASE2-USILENT-FS | G56: U-SILENT | H56: 1 | I56: 5 | J56: 5 | K56: 0 | L56: executa | M56: 0 | N56: Caracterizou c/ alerta | O56: 0 | P56: =IF(AND(L56="executa",K56=0,J56>0),1,0) -> 1
A57: Fase 2 | B57: Unitário | C57: gemini | D57: ZS | E57: Bug | F57: FASE2-UCRASH-ZS | G57: U-CRASH | H57: 1 | I57: 11 | J57: 11 | K57: 0 | L57: executa | M57: 0 | N57: Caracterizou c/ alerta | O57: 0 | P57: =IF(AND(L57="executa",K57=0,J57>0),1,0) -> 1
A58: Fase 2 | B58: Unitário | C58: gemini | D58: ZS | E58: Bug | F58: FASE2-USILENT-ZS | G58: U-SILENT | H58: 1 | I58: 7 | J58: 7 | K58: 0 | L58: executa | M58: 0 | N58: Caracterizou c/ alerta | O58: 0 | P58: =IF(AND(L58="executa",K58=0,J58>0),1,0) -> 1
A59: Fase 2 | B59: Unitário | C59: gemini | D59: COT | E59: formatName | F59: FASE2-UNIT-COT-08_formatName | H59: 1 | I59: 9 | J59: 9 | K59: 0 | L59: executa | M59: 0 | O59: 0 | P59: =IF(AND(L59="executa",K59=0,J59>0),1,0) -> 1
...

Sheet Pirâmide
A1: A. Alvos limpos por nível × modelo
A2: Nível | B2: Modelo | C2: Rodadas | D2: Gerados | E2: Passando | F2: Falhando (executa) | G2: Taxa | H2: Verdes | I2: Compilou 1ª | J2: Não compila no final | K2: Iterações | L2: (B) emitidos
A3: Unitário | B3: ChatGPT | C3: =COUNTIFS(Rodadas!$B$2:$B$165,"Unitário",Rodadas!$C$2:$C$165,"chatgpt",Rodadas!$E$2:$E$165,"Limpo") -> 21 | D3: =SUMIFS(Rodadas!$I$2:$I$165,Rodadas!$B$2:$B$165,"Unitário",Rodadas!$C$2:$C$165,"chatgpt",Rodadas!$E$2:$E$165,"Limpo") -> 374 | E3: =SUMIFS(Rodadas!$J$2:$J$165,Rodadas!$B$2:$B$165,"Unitário",Rodadas!$C$2:$C$165,"chatgpt",Rodadas!$E$2:$E$165,"Limpo") -> 373 | F3: =SUMIFS(Rodadas!$K$2:$K$165,Rodadas!$B$2:$B$165,"Unitário",Rodadas!$C$2:$C$165,"chatgpt",Rodadas!$E$2:$E$165,"Limpo",Rodadas!$L$2:$L$165,"executa") -> 1 | G3: =IF(E3+F3=0,"",E3/(E3+F3)) -> 0.9973262 | H3: =SUMIFS(Rodadas!$P$2:$P$165,Rodadas!$B$2:$B$165,"Unitário",Rodadas!$C$2:$C$165,"chatgpt",Rodadas!$E$2:$E$165,"Limpo") -> 20 | I3: =SUMIFS(Rodadas!$H$2:$H$165,Rodadas!$B$2:$B$165,"Unitário",Rodadas!$C$2:$C$165,"chatgpt",Rodadas!$E$2:$E$165,"Limpo") -> 21 | J3: =COUNTIFS(Rodadas!$B$2:$B$165,"Unitário",Rodadas!$C$2:$C$165,"chatgpt",Rodadas!$E$2:$E$165,"Limpo",Rodadas!$L$2:$L$165,"não compila") -> 0 | K3: =SUMIFS(Rodadas!$M$2:$M$165,Rodadas!$B$2:$B$165,"Unitário",Rodadas!$C$2:$C$165,"chatgpt",Rodadas!$E$2:$E$165,"Limpo") -> 6 | L3: =SUMIFS(Rodadas!$O$2:$O$165,Rodadas!$B$2:$B$165,"Unitário",Rodadas!$C$2:$C$165,"chatgpt",Rodadas!$E$2:$E$165,"Limpo") -> 1
A4: Unitário | B4: Gemini | C4: =COUNTIFS(Rodadas!$B$2:$B$165,"Unitário",Rodadas!$C$2:$C$165,"gemini",Rodadas!$E$2:$E$165,"Limpo") -> 21 | D4: =SUMIFS(Rodadas!$I$2:$I$165,Rodadas!$B$2:$B$165,"Unitário",Rodadas!$C$2:$C$165,"gemini",Rodadas!$E$2:$E$165,"Limpo") -> 264 | E4: =SUMIFS(Rodadas!$J$2:$J$165,Rodadas!$B$2:$B$165,"Unitário",Rodadas!$C$2:$C$165,"gemini",Rodadas!$E$2:$E$165,"Limpo") -> 264 | F4: =SUMIFS(Rodadas!$K$2:$K$165,Rodadas!$B$2:$B$165,"Unitário",Rodadas!$C$2:$C$165,"gemini",Rodadas!$E$2:$E$165,"Limpo",Rodadas!$L$2:$L$165,"executa") -> 0 | G4: =IF(E4+F4=0,"",E4/(E4+F4)) -> 1 | H4: =SUMIFS(Rodadas!$P$2:$P$165,Rodadas!$B$2:$B$165,"Unitário",Rodadas!$C$2:$C$165,"gemini",Rodadas!$E$2:$E$165,"Limpo") -> 21 | I4: =SUMIFS(Rodadas!$H$2:$H$165,Rodadas!$B$2:$B$165,"Unitário",Rodadas!$C$2:$C$165,"gemini",Rodadas!$E$2:$E$165,"Limpo") -> 21 | J4: =COUNTIFS(Rodadas!$B$2:$B$165,"Unitário",Rodadas!$C$2:$C$165,"gemini",Rodadas!$E$2:$E$165,"Limpo",Rodadas!$L$2:$L$165,"não compila") -> 0 | K4: =SUMIFS(Rodadas!$M$2:$M$165,Rodadas!$B$2:$B$165,"Unitário",Rodadas!$C$2:$C$165,"gemini",Rodadas!$E$2:$E$165,"Limpo") -> 2 | L4: =SUMIFS(Rodadas!$O$2:$O$165,Rodadas!$B$2:$B$165,"Unitário",Rodadas!$C$2:$C$165,"gemini",Rodadas!$E$2:$E$165,"Limpo") -> 0
A5: Widget | B5: ChatGPT | C5: =COUNTIFS(Rodadas!$B$2:$B$165,"Widget",Rodadas!$C$2:$C$165,"chatgpt",Rodadas!$E$2:$E$165,"Limpo") -> 9 | D5: =SUMIFS(Rodadas!$I$2:$I$165,Rodadas!$B$2:$B$165,"Widget",Rodadas!$C$2:$C$165,"chatgpt",Rodadas!$E$2:$E$165,"Limpo") -> 152 | E5: =SUMIFS(Rodadas!$J$2:$J$165,Rodadas!$B$2:$B$165,"Widget",Rodadas!$C$2:$C$165,"chatgpt",Rodadas!$E$2:$E$165,"Limpo") -> 113 | F5: =SUMIFS(Rodadas!$K$2:$K$165,Rodadas!$B$2:$B$165,"Widget",Rodadas!$C$2:$C$165,"chatgpt",Rodadas!$E$2:$E$165,"Limpo",Rodadas!$L$2:$L$165,"executa") -> 14 | G5: =IF(E5+F5=0,"",E5/(E5+F5)) -> 0.88976378 | H5: =SUMIFS(Rodadas!$P$2:$P$165,Rodadas!$B$2:$B$165,"Widget",Rodadas!$C$2:$C$165,"chatgpt",Rodadas!$E$2:$E$165,"Limpo") -> 2 | I5: =SUMIFS(Rodadas!$H$2:$H$165,Rodadas!$B$2:$B$165,"Widget",Rodadas!$C$2:$C$165,"chatgpt",Rodadas!$E$2:$E$165,"Limpo") -> 3 | J5: =COUNTIFS(Rodadas!$B$2:$B$165,"Widget",Rodadas!$C$2:$C$165,"chatgpt",Rodadas!$E$2:$E$165,"Limpo",Rodadas!$L$2:$L$165,"não compila") -> 1 | K5: =SUMIFS(Rodadas!$M$2:$M$165,Rodadas!$B$2:$B$165,"Widget",Rodadas!$C$2:$C$165,"chatgpt",Rodadas!$E$2:$E$165,"Limpo") -> 24 | L5: =SUMIFS(Rodadas!$O$2:$O$165,Rodadas!$B$2:$B$165,"Widget",Rodadas!$C$2:$C$165,"chatgpt",Rodadas!$E$2:$E$165,"Limpo") -> 5
A6: Widget | B6: Gemini | C6: =COUNTIFS(Rodadas!$B$2:$B$165,"Widget",Rodadas!$C$2:$C$165,"gemini",Rodadas!$E$2:$E$165,"Limpo") -> 9 | D6: =SUMIFS(Rodadas!$I$2:$I$165,Rodadas!$B$2:$B$165,"Widget",Rodadas!$C$2:$C$165,"gemini",Rodadas!$E$2:$E$165,"Limpo") -> 71 | E6: =SUMIFS(Rodadas!$J$2:$J$165,Rodadas!$B$2:$B$165,"Widget",Rodadas!$C$2:$C$165,"gemini",Rodadas!$E$2:$E$165,"Limpo") -> 55 | F6: =SUMIFS(Rodadas!$K$2:$K$165,Rodadas!$B$2:$B$165,"Widget",Rodadas!$C$2:$C$165,"gemini",Rodadas!$E$2:$E$165,"Limpo",Rodadas!$L$2:$L$165,"executa") -> 16 | G6: =IF(E6+F6=0,"",E6/(E6+F6)) -> 0.77464789 | H6: =SUMIFS(Rodadas!$P$2:$P$165,Rodadas!$B$2:$B$165,"Widget",Rodadas!$C$2:$C$165,"gemini",Rodadas!$E$2:$E$165,"Limpo") -> 6 | I6: =SUMIFS(Rodadas!$H$2:$H$165,Rodadas!$B$2:$B$165,"Widget",Rodadas!$C$2:$C$165,"gemini",Rodadas!$E$2:$E$165,"Limpo") -> 6 | J6: =COUNTIFS(Rodadas!$B$2:$B$165,"Widget",Rodadas!$C$2:$C$165,"gemini",Rodadas!$E$2:$E$165,"Limpo",Rodadas!$L$2:$L$165,"não compila") -> 0 | K6: =SUMIFS(Rodadas!$M$2:$M$165,Rodadas!$B$2:$B$165,"Widget",Rodadas!$C$2:$C$165,"gemini",Rodadas!$E$2:$E$165,"Limpo") -> 17 | L6: =SUMIFS(Rodadas!$O$2:$O$165,Rodadas!$B$2:$B$165,"Widget",Rodadas!$C$2:$C$165,"gemini",Rodadas!$E$2:$E$165,"Limpo") -> 4
A7: Integração | B7: ChatGPT | C7: =COUNTIFS(Rodadas!$B$2:$B$165,"Integração",Rodadas!$C$2:$C$165,"chatgpt",Rodadas!$E$2:$E$165,"Limpo") -> 9 | D7: =SUMIFS(Rodadas!$I$2:$I$165,Rodadas!$B$2:$B$165,"Integração",Rodadas!$C$2:$C$165,"chatgpt",Rodadas!$E$2:$E$165,"Limpo") -> 50 | E7: =SUMIFS(Rodadas!$J$2:$J$165,Rodadas!$B$2:$B$165,"Integração",Rodadas!$C$2:$C$165,"chatgpt",Rodadas!$E$2:$E$165,"Limpo") -> 43 | F7: =SUMIFS(Rodadas!$K$2:$K$165,Rodadas!$B$2:$B$165,"Integração",Rodadas!$C$2:$C$165,"chatgpt",Rodadas!$E$2:$E$165,"Limpo",Rodadas!$L$2:$L$165,"executa") -> 7 | G7: =IF(E7+F7=0,"",E7/(E7+F7)) -> 0.86 | H7: =SUMIFS(Rodadas!$P$2:$P$165,Rodadas!$B$2:$B$165,"Integração",Rodadas!$C$2:$C$165,"chatgpt",Rodadas!$E$2:$E$165,"Limpo") -> 4 | I7: =SUMIFS(Rodadas!$H$2:$H$165,Rodadas!$B$2:$B$165,"Integração",Rodadas!$C$2:$C$165,"chatgpt",Rodadas!$E$2:$E$165,"Limpo") -> 1 | J7: =COUNTIFS(Rodadas!$B$2:$B$165,"Integração",Rodadas!$C$2:$C$165,"chatgpt",Rodadas!$E$2:$E$165,"Limpo",Rodadas!$L$2:$L$165,"não compila") -> 0 | K7: =SUMIFS(Rodadas!$M$2:$M$165,Rodadas!$B$2:$B$165,"Integração",Rodadas!$C$2:$C$165,"chatgpt",Rodadas!$E$2:$E$165,"Limpo") -> 20 | L7: =SUMIFS(Rodadas!$O$2:$O$165,Rodadas!$B$2:$B$165,"Integração",Rodadas!$C$2:$C$165,"chatgpt",Rodadas!$E$2:$E$165,"Limpo") -> 1
A8: Integração | B8: Gemini | C8: =COUNTIFS(Rodadas!$B$2:$B$165,"Integração",Rodadas!$C$2:$C$165,"gemini",Rodadas!$E$2:$E$165,"Limpo") -> 9 | D8: =SUMIFS(Rodadas!$I$2:$I$165,Rodadas!$B$2:$B$165,"Integração",Rodadas!$C$2:$C$165,"gemini",Rodadas!$E$2:$E$165,"Limpo") -> 41 | E8: =SUMIFS(Rodadas!$J$2:$J$165,Rodadas!$B$2:$B$165,"Integração",Rodadas!$C$2:$C$165,"gemini",Rodadas!$E$2:$E$165,"Limpo") -> 23 | F8: =SUMIFS(Rodadas!$K$2:$K$165,Rodadas!$B$2:$B$165,"Integração",Rodadas!$C$2:$C$165,"gemini",Rodadas!$E$2:$E$165,"Limpo",Rodadas!$L$2:$L$165,"executa") -> 6 | G8: =IF(E8+F8=0,"",E8/(E8+F8)) -> 0.79310345 | H8: =SUMIFS(Rodadas!$P$2:$P$165,Rodadas!$B$2:$B$165,"Integração",Rodadas!$C$2:$C$165,"gemini",Rodadas!$E$2:$E$165,"Limpo") -> 4 | I8: =SUMIFS(Rodadas!$H$2:$H$165,Rodadas!$B$2:$B$165,"Integração",Rodadas!$C$2:$C$165,"gemini",Rodadas!$E$2:$E$165,"Limpo") -> 4 | J8: =COUNTIFS(Rodadas!$B$2:$B$165,"Integração",Rodadas!$C$2:$C$165,"gemini",Rodadas!$E$2:$E$165,"Limpo",Rodadas!$L$2:$L$165,"não compila") -> 1 | K8: =SUMIFS(Rodadas!$M$2:$M$165,Rodadas!$B$2:$B$165,"Integração",Rodadas!$C$2:$C$165,"gemini",Rodadas!$E$2:$E$165,"Limpo") -> 20 | L8: =SUMIFS(Rodadas!$O$2:$O$165,Rodadas!$B$2:$B$165,"Integração",Rodadas!$C$2:$C$165,"gemini",Rodadas!$E$2:$E$165,"Limpo") -> 3
A9: E2E | B9: ChatGPT | C9: =COUNTIFS(Rodadas!$B$2:$B$165,"E2E",Rodadas!$C$2:$C$165,"chatgpt",Rodadas!$E$2:$E$165,"Limpo") -> 9 | D9: =SUMIFS(Rodadas!$I$2:$I$165,Rodadas!$B$2:$B$165,"E2E",Rodadas!$C$2:$C$165,"chatgpt",Rodadas!$E$2:$E$165,"Limpo") -> 43 | E9: =SUMIFS(Rodadas!$J$2:$J$165,Rodadas!$B$2:$B$165,"E2E",Rodadas!$C$2:$C$165,"chatgpt",Rodadas!$E$2:$E$165,"Limpo") -> 26 | F9: =SUMIFS(Rodadas!$K$2:$K$165,Rodadas!$B$2:$B$165,"E2E",Rodadas!$C$2:$C$165,"chatgpt",Rodadas!$E$2:$E$165,"Limpo",Rodadas!$L$2:$L$165,"executa") -> 17 | G9: =IF(E9+F9=0,"",E9/(E9+F9)) -> 0.60465116 | H9: =SUMIFS(Rodadas!$P$2:$P$165,Rodadas!$B$2:$B$165,"E2E",Rodadas!$C$2:$C$165,"chatgpt",Rodadas!$E$2:$E$165,"Limpo") -> 3 | I9: =SUMIFS(Rodadas!$H$2:$H$165,Rodadas!$B$2:$B$165,"E2E",Rodadas!$C$2:$C$165,"chatgpt",Rodadas!$E$2:$E$165,"Limpo") -> 4 | J9: =COUNTIFS(Rodadas!$B$2:$B$165,"E2E",Rodadas!$C$2:$C$165,"chatgpt",Rodadas!$E$2:$E$165,"Limpo",Rodadas!$L$2:$L$165,"não compila") -> 0 | K9: =SUMIFS(Rodadas!$M$2:$M$165,Rodadas!$B$2:$B$165,"E2E",Rodadas!$C$2:$C$165,"chatgpt",Rodadas!$E$2:$E$165,"Limpo") -> 22 | L9: =SUMIFS(Rodadas!$O$2:$O$165,Rodadas!$B$2:$B$165,"E2E",Rodadas!$C$2:$C$165,"chatgpt",Rodadas!$E$2:$E$165,"Limpo") -> 11
A10: E2E | B10: Gemini | C10: =COUNTIFS(Rodadas!$B$2:$B$165,"E2E",Rodadas!$C$2:$C$165,"gemini",Rodadas!$E$2:$E$165,"Limpo") -> 9 | D10: =SUMIFS(Rodadas!$I$2:$I$165,Rodadas!$B$2:$B$165,"E2E",Rodadas!$C$2:$C$165,"gemini",Rodadas!$E$2:$E$165,"Limpo") -> 29 | E10: =SUMIFS(Rodadas!$J$2:$J$165,Rodadas!$B$2:$B$165,"E2E",Rodadas!$C$2:$C$165,"gemini",Rodadas!$E$2:$E$165,"Limpo") -> 25 | F10: =SUMIFS(Rodadas!$K$2:$K$165,Rodadas!$B$2:$B$165,"E2E",Rodadas!$C$2:$C$165,"gemini",Rodadas!$E$2:$E$165,"Limpo",Rodadas!$L$2:$L$165,"executa") -> 3 | G10: =IF(E10+F10=0,"",E10/(E10+F10)) -> 0.89285714 | H10: =SUMIFS(Rodadas!$P$2:$P$165,Rodadas!$B$2:$B$165,"E2E",Rodadas!$C$2:$C$165,"gemini",Rodadas!$E$2:$E$165,"Limpo") -> 6 | I10: =SUMIFS(Rodadas!$H$2:$H$165,Rodadas!$B$2:$B$165,"E2E",Rodadas!$C$2:$C$165,"gemini",Rodadas!$E$2:$E$165,"Limpo") -> 8 | J10: =COUNTIFS(Rodadas!$B$2:$B$165,"E2E",Rodadas!$C$2:$C$165,"gemini",Rodadas!$E$2:$E$165,"Limpo",Rodadas!$L$2:$L$165,"não compila") -> 0 | K10: =SUMIFS(Rodadas!$M$2:$M$165,Rodadas!$B$2:$B$165,"E2E",Rodadas!$C$2:$C$165,"gemini",Rodadas!$E$2:$E$165,"Limpo") -> 17 | L10: =SUMIFS(Rodadas!$O$2:$O$165,Rodadas!$B$2:$B$165,"E2E",Rodadas!$C$2:$C$165,"gemini",Rodadas!$E$2:$E$165,"Limpo") -> 7
A11: Todos | B11: ChatGPT | C11: =COUNTIFS(Rodadas!$C$2:$C$165,"chatgpt",Rodadas!$E$2:$E$165,"Limpo") -> 48 | D11: =SUMIFS(Rodadas!$I$2:$I$165,Rodadas!$C$2:$C$165,"chatgpt",Rodadas!$E$2:$E$165,"Limpo") -> 619 | E11: =SUMIFS(Rodadas!$J$2:$J$165,Rodadas!$C$2:$C$165,"chatgpt",Rodadas!$E$2:$E$165,"Limpo") -> 555 | F11: =SUMIFS(Rodadas!$K$2:$K$165,Rodadas!$C$2:$C$165,"chatgpt",Rodadas!$E$2:$E$165,"Limpo",Rodadas!$L$2:$L$165,"executa") -> 39 | G11: =IF(E11+F11=0,"",E11/(E11+F11)) -> 0.93434343 | H11: =SUMIFS(Rodadas!$P$2:$P$165,Rodadas!$C$2:$C$165,"chatgpt",Rodadas!$E$2:$E$165,"Limpo") -> 29 | I11: =SUMIFS(Rodadas!$H$2:$H$165,Rodadas!$C$2:$C$165,"chatgpt",Rodadas!$E$2:$E$165,"Limpo") -> 29 | J11: =COUNTIFS(Rodadas!$C$2:$C$165,"chatgpt",Rodadas!$E$2:$E$165,"Limpo",Rodadas!$L$2:$L$165,"não compila") -> 1 | K11: =SUMIFS(Rodadas!$M$2:$M$165,Rodadas!$C$2:$C$165,"chatgpt",Rodadas!$E$2:$E$165,"Limpo") -> 72 | L11: =SUMIFS(Rodadas!$O$2:$O$165,Rodadas!$C$2:$C$165,"chatgpt",Rodadas!$E$2:$E$165,"Limpo") -> 18
A12: Todos | B12: Gemini | C12: =COUNTIFS(Rodadas!$C$2:$C$165,"gemini",Rodadas!$E$2:$E$165,"Limpo") -> 48 | D12: =SUMIFS(Rodadas!$I$2:$I$165,Rodadas!$C$2:$C$165,"gemini",Rodadas!$E$2:$E$165,"Limpo") -> 405 | E12: =SUMIFS(Rodadas!$J$2:$J$165,Rodadas!$C$2:$C$165,"gemini",Rodadas!$E$2:$E$165,"Limpo") -> 367 | F12: =SUMIFS(Rodadas!$K$2:$K$165,Rodadas!$C$2:$C$165,"gemini",Rodadas!$E$2:$E$165,"Limpo",Rodadas!$L$2:$L$165,"executa") -> 25 | G12: =IF(E12+F12=0,"",E12/(E12+F12)) -> 0.93622449 | H12: =SUMIFS(Rodadas!$P$2:$P$165,Rodadas!$C$2:$C$165,"gemini",Rodadas!$E$2:$E$165,"Limpo") -> 37 | I12: =SUMIFS(Rodadas!$H$2:$H$165,Rodadas!$C$2:$C$165,"gemini",Rodadas!$E$2:$E$165,"Limpo") -> 39 | J12: =COUNTIFS(Rodadas!$C$2:$C$165,"gemini",Rodadas!$E$2:$E$165,"Limpo",Rodadas!$L$2:$L$165,"não compila") -> 1 | K12: =SUMIFS(Rodadas!$M$2:$M$165,Rodadas!$C$2:$C$165,"gemini",Rodadas!$E$2:$E$165,"Limpo") -> 56 | L12: =SUMIFS(Rodadas!$O$2:$O$165,Rodadas!$C$2:$C$165,"gemini",Rodadas!$E$2:$E$165,"Limpo") -> 14
A14: B. Bugs plantados por nível × modelo (E2E ChatGPT: 7 rodadas com dado; 2 sem dado à parte)
A15: Nível | B15: Modelo | C15: Rodadas | D15: Gerados | E15: Passando | F15: Falhando (executa) | G15: Taxa | H15: Verdes | I15: Compilou 1ª | J15: Não compila no final | K15: Iterações | L15: (B) emitidos | M15: Capturou | N15: Caracterizou c/ alerta | O15: Viu sem asserção | P15: Canonizou | Q15: Não viu | R15: Sem dado (serviço)
A16: Unitário | B16: ChatGPT | C16: =COUNTIFS(Rodadas!$B$2:$B$165,"Unitário",Rodadas!$C$2:$C$165,"chatgpt",Rodadas!$E$2:$E$165,"Bug") -> 6 | D16: =SUMIFS(Rodadas!$I$2:$I$165,Rodadas!$B$2:$B$165,"Unitário",Rodadas!$C$2:$C$165,"chatgpt",Rodadas!$E$2:$E$165,"Bug") -> 62 | E16: =SUMIFS(Rodadas!$J$2:$J$165,Rodadas!$B$2:$B$165,"Unitário",Rodadas!$C$2:$C$165,"chatgpt",Rodadas!$E$2:$E$165,"Bug") -> 61 | F16: =SUMIFS(Rodadas!$K$2:$K$165,Rodadas!$B$2:$B$165,"Unitário",Rodadas!$C$2:$C$165,"chatgpt",Rodadas!$E$2:$E$165,"Bug",Rodadas!$L$2:$L$165,"executa") -> 1 | G16: =IF(E16+F16=0,"",E16/(E16+F16)) -> 0.98387097 | H16: =SUMIFS(Rodadas!$P$2:$P$165,Rodadas!$B$2:$B$165,"Unitário",Rodadas!$C$2:$C$165,"chatgpt",Rodadas!$E$2:$E$165,"Bug") -> 5 | I16: =SUMIFS(Rodadas!$H$2:$H$165,Rodadas!$B$2:$B$165,"Unitário",Rodadas!$C$2:$C$165,"chatgpt",Rodadas!$E$2:$E$165,"Bug") -> 6 | J16: =COUNTIFS(Rodadas!$B$2:$B$165,"Unitário",Rodadas!$C$2:$C$165,"chatgpt",Rodadas!$E$2:$E$165,"Bug",Rodadas!$L$2:$L$165,"não compila") -> 0 | K16: =SUMIFS(Rodadas!$M$2:$M$165,Rodadas!$B$2:$B$165,"Unitário",Rodadas!$C$2:$C$165,"chatgpt",Rodadas!$E$2:$E$165,"Bug") -> 1 | L16: =SUMIFS(Rodadas!$O$2:$O$165,Rodadas!$B$2:$B$165,"Unitário",Rodadas!$C$2:$C$165,"chatgpt",Rodadas!$E$2:$E$165,"Bug") -> 1 | M16: =COUNTIFS(Rodadas!$B$2:$B$165,"Unitário",Rodadas!$C$2:$C$165,"chatgpt",Rodadas!$E$2:$E$165,"Bug",Rodadas!$N$2:$N$165,"Capturou") -> 1 | N16: =COUNTIFS(Rodadas!$B$2:$B$165,"Unitário",Rodadas!$C$2:$C$165,"chatgpt",Rodadas!$E$2:$E$165,"Bug",Rodadas!$N$2:$N$165,"Caracterizou c/ alerta") -> 5 | O16: =COUNTIFS(Rodadas!$B$2:$B$165,"Unitário",Rodadas!$C$2:$C$165,"chatgpt",Rodadas!$E$2:$E$165,"Bug",Rodadas!$N$2:$N$165,"Viu sem asserção") -> 0 | P16: =COUNTIFS(Rodadas!$B$2:$B$165,"Unitário",Rodadas!$C$2:$C$165,"chatgpt",Rodadas!$E$2:$E$165,"Bug",Rodadas!$N$2:$N$165,"Canonizou") -> 0 | Q16: =COUNTIFS(Rodadas!$B$2:$B$165,"Unitário",Rodadas!$C$2:$C$165,"chatgpt",Rodadas!$E$2:$E$165,"Bug",Rodadas!$N$2:$N$165,"Não viu") -> 0 | R16: =COUNTIFS(Rodadas!$B$2:$B$165,"Unitário",Rodadas!$C$2:$C$165,"chatgpt",Rodadas!$E$2:$E$165,"Sem dado",Rodadas!$N$2:$N$165,"Sem dado (serviço)") -> 0
A17: Unitário | B17: Gemini | C17: =COUNTIFS(Rodadas!$B$2:$B$165,"Unitário",Rodadas!$C$2:$C$165,"gemini",Rodadas!$E$2:$E$165,"Bug") -> 6 | D17: =SUMIFS(Rodadas!$I$2:$I$165,Rodadas!$B$2:$B$165,"Unitário",Rodadas!$C$2:$C$165,"gemini",Rodadas!$E$2:$E$165,"Bug") -> 47 | E17: =SUMIFS(Rodadas!$J$2:$J$165,Rodadas!$B$2:$B$165,"Unitário",Rodadas!$C$2:$C$165,"gemini",Rodadas!$E$2:$E$165,"Bug") -> 47 | F17: =SUMIFS(Rodadas!$K$2:$K$165,Rodadas!$B$2:$B$165,"Unitário",Rodadas!$C$2:$C$165,"gemini",Rodadas!$E$2:$E$165,"Bug",Rodadas!$L$2:$L$165,"executa") -> 0 | G17: =IF(E17+F17=0,"",E17/(E17+F17)) -> 1 | H17: =SUMIFS(Rodadas!$P$2:$P$165,Rodadas!$B$2:$B$165,"Unitário",Rodadas!$C$2:$C$165,"gemini",Rodadas!$E$2:$E$165,"Bug") -> 6 | I17: =SUMIFS(Rodadas!$H$2:$H$165,Rodadas!$B$2:$B$165,"Unitário",Rodadas!$C$2:$C$165,"gemini",Rodadas!$E$2:$E$165,"Bug") -> 6 | J17: =COUNTIFS(Rodadas!$B$2:$B$165,"Unitário",Rodadas!$C$2:$C$165,"gemini",Rodadas!$E$2:$E$165,"Bug",Rodadas!$L$2:$L$165,"não compila") -> 0 | K17: =SUMIFS(Rodadas!$M$2:$M$165,Rodadas!$B$2:$B$165,"Unitário",Rodadas!$C$2:$C$165,"gemini",Rodadas!$E$2:$E$165,"Bug") -> 0 | L17: =SUMIFS(Rodadas!$O$2:$O$165,Rodadas!$B$2:$B$165,"Unitário",Rodadas!$C$2:$C$165,"gemini",Rodadas!$E$2:$E$165,"Bug") -> 0 | M17: =COUNTIFS(Rodadas!$B$2:$B$165,"Unitário",Rodadas!$C$2:$C$165,"gemini",Rodadas!$E$2:$E$165,"Bug",Rodadas!$N$2:$N$165,"Capturou") -> 0 | N17: =COUNTIFS(Rodadas!$B$2:$B$165,"Unitário",Rodadas!$C$2:$C$165,"gemini",Rodadas!$E$2:$E$165,"Bug",Rodadas!$N$2:$N$165,"Caracterizou c/ alerta") -> 5 | O17: =COUNTIFS(Rodadas!$B$2:$B$165,"Unitário",Rodadas!$C$2:$C$165,"gemini",Rodadas!$E$2:$E$165,"Bug",Rodadas!$N$2:$N$165,"Viu sem asserção") -> 1 | P17: =COUNTIFS(Rodadas!$B$2:$B$165,"Unitário",Rodadas!$C$2:$C$165,"gemini",Rodadas!$E$2:$E$165,"Bug",Rodadas!$N$2:$N$165,"Canonizou") -> 0 | Q17: =COUNTIFS(Rodadas!$B$2:$B$165,"Unitário",Rodadas!$C$2:$C$165,"gemini",Rodadas!$E$2:$E$165,"Bug",Rodadas!$N$2:$N$165,"Não viu") -> 0 | R17: =COUNTIFS(Rodadas!$B$2:$B$165,"Unitário",Rodadas!$C$2:$C$165,"gemini",Rodadas!$E$2:$E$165,"Sem dado",Rodadas!$N$2:$N$165,"Sem dado (serviço)") -> 0
A18: Widget | B18: ChatGPT | C18: =COUNTIFS(Rodadas!$B$2:$B$165,"Widget",Rodadas!$C$2:$C$165,"chatgpt",Rodadas!$E$2:$E$165,"Bug") -> 6 | D18: =SUMIFS(Rodadas!$I$2:$I$165,Rodadas!$B$2:$B$165,"Widget",Rodadas!$C$2:$C$165,"chatgpt",Rodadas!$E$2:$E$165,"Bug") -> 90 | E18: =SUMIFS(Rodadas!$J$2:$J$165,Rodadas!$B$2:$B$165,"Widget",Rodadas!$C$2:$C$165,"chatgpt",Rodadas!$E$2:$E$165,"Bug") -> 41 | F18: =SUMIFS(Rodadas!$K$2:$K$165,Rodadas!$B$2:$B$165,"Widget",Rodadas!$C$2:$C$165,"chatgpt",Rodadas!$E$2:$E$165,"Bug",Rodadas!$L$2:$L$165,"executa") -> 2 | G18: =IF(E18+F18=0,"",E18/(E18+F18)) -> 0.95348837 | H18: =SUMIFS(Rodadas!$P$2:$P$165,Rodadas!$B$2:$B$165,"Widget",Rodadas!$C$2:$C$165,"chatgpt",Rodadas!$E$2:$E$165,"Bug") -> 1 | I18: =SUMIFS(Rodadas!$H$2:$H$165,Rodadas!$B$2:$B$165,"Widget",Rodadas!$C$2:$C$165,"chatgpt",Rodadas!$E$2:$E$165,"Bug") -> 2 | J18: =COUNTIFS(Rodadas!$B$2:$B$165,"Widget",Rodadas!$C$2:$C$165,"chatgpt",Rodadas!$E$2:$E$165,"Bug",Rodadas!$L$2:$L$165,"não compila") -> 3 | K18: =SUMIFS(Rodadas!$M$2:$M$165,Rodadas!$B$2:$B$165,"Widget",Rodadas!$C$2:$C$165,"chatgpt",Rodadas!$E$2:$E$165,"Bug") -> 15 | L18: =SUMIFS(Rodadas!$O$2:$O$165,Rodadas!$B$2:$B$165,"Widget",Rodadas!$C$2:$C$165,"chatgpt",Rodadas!$E$2:$E$165,"Bug") -> 0 | M18: =COUNTIFS(Rodadas!$B$2:$B$165,"Widget",Rodadas!$C$2:$C$165,"chatgpt",Rodadas!$E$2:$E$165,"Bug",Rodadas!$N$2:$N$165,"Capturou") -> 0 | N18: =COUNTIFS(Rodadas!$B$2:$B$165,"Widget",Rodadas!$C$2:$C$165,"chatgpt",Rodadas!$E$2:$E$165,"Bug",Rodadas!$N$2:$N$165,"Caracterizou c/ alerta") -> 3 | O18: =COUNTIFS(Rodadas!$B$2:$B$165,"Widget",Rodadas!$C$2:$C$165,"chatgpt",Rodadas!$E$2:$E$165,"Bug",Rodadas!$N$2:$N$165,"Viu sem asserção") -> 0 | P18: =COUNTIFS(Rodadas!$B$2:$B$165,"Widget",Rodadas!$C$2:$C$165,"chatgpt",Rodadas!$E$2:$E$165,"Bug",Rodadas!$N$2:$N$165,"Canonizou") -> 0 | Q18: =COUNTIFS(Rodadas!$B$2:$B$165,"Widget",Rodadas!$C$2:$C$165,"chatgpt",Rodadas!$E$2:$E$165,"Bug",Rodadas!$N$2:$N$165,"Não viu") -> 3 | R18: =COUNTIFS(Rodadas!$B$2:$B$165,"Widget",Rodadas!$C$2:$C$165,"chatgpt",Rodadas!$E$2:$E$165,"Sem dado",Rodadas!$N$2:$N$165,"Sem dado (serviço)") -> 0
A19: Widget | B19: Gemini | C19: =COUNTIFS(Rodadas!$B$2:$B$165,"Widget",Rodadas!$C$2:$C$165,"gemini",Rodadas!$E$2:$E$165,"Bug") -> 6 | D19: =SUMIFS(Rodadas!$I$2:$I$165,Rodadas!$B$2:$B$165,"Widget",Rodadas!$C$2:$C$165,"gemini",Rodadas!$E$2:$E$165,"Bug") -> 49 | E19: =SUMIFS(Rodadas!$J$2:$J$165,Rodadas!$B$2:$B$165,"Widget",Rodadas!$C$2:$C$165,"gemini",Rodadas!$E$2:$E$165,"Bug") -> 45 | F19: =SUMIFS(Rodadas!$K$2:$K$165,Rodadas!$B$2:$B$165,"Widget",Rodadas!$C$2:$C$165,"gemini",Rodadas!$E$2:$E$165,"Bug",Rodadas!$L$2:$L$165,"executa") -> 4 | G19: =IF(E19+F19=0,"",E19/(E19+F19)) -> 0.91836735 | H19: =SUMIFS(Rodadas!$P$2:$P$165,Rodadas!$B$2:$B$165,"Widget",Rodadas!$C$2:$C$165,"gemini",Rodadas!$E$2:$E$165,"Bug") -> 3 | I19: =SUMIFS(Rodadas!$H$2:$H$165,Rodadas!$B$2:$B$165,"Widget",Rodadas!$C$2:$C$165,"gemini",Rodadas!$E$2:$E$165,"Bug") -> 4 | J19: =COUNTIFS(Rodadas!$B$2:$B$165,"Widget",Rodadas!$C$2:$C$165,"gemini",Rodadas!$E$2:$E$165,"Bug",Rodadas!$L$2:$L$165,"não compila") -> 0 | K19: =SUMIFS(Rodadas!$M$2:$M$165,Rodadas!$B$2:$B$165,"Widget",Rodadas!$C$2:$C$165,"gemini",Rodadas!$E$2:$E$165,"Bug") -> 8 | L19: =SUMIFS(Rodadas!$O$2:$O$165,Rodadas!$B$2:$B$165,"Widget",Rodadas!$C$2:$C$165,"gemini",Rodadas!$E$2:$E$165,"Bug") -> 2 | M19: =COUNTIFS(Rodadas!$B$2:$B$165,"Widget",Rodadas!$C$2:$C$165,"gemini",Rodadas!$E$2:$E$165,"Bug",Rodadas!$N$2:$N$165,"Capturou") -> 0 | N19: =COUNTIFS(Rodadas!$B$2:$B$165,"Widget",Rodadas!$C$2:$C$165,"gemini",Rodadas!$E$2:$E$165,"Bug",Rodadas!$N$2:$N$165,"Caracterizou c/ alerta") -> 0 | O19: =COUNTIFS(Rodadas!$B$2:$B$165,"Widget",Rodadas!$C$2:$C$165,"gemini",Rodadas!$E$2:$E$165,"Bug",Rodadas!$N$2:$N$165,"Viu sem asserção") -> 0 | P19: =COUNTIFS(Rodadas!$B$2:$B$165,"Widget",Rodadas!$C$2:$C$165,"gemini",Rodadas!$E$2:$E$165,"Bug",Rodadas!$N$2:$N$165,"Canonizou") -> 3 | Q19: =COUNTIFS(Rodadas!$B$2:$B$165,"Widget",Rodadas!$C$2:$C$165,"gemini",Rodadas!$E$2:$E$165,"Bug",Rodadas!$N$2:$N$165,"Não viu") -> 3 | R19: =COUNTIFS(Rodadas!$B$2:$B$165,"Widget",Rodadas!$C$2:$C$165,"gemini",Rodadas!$E$2:$E$165,"Sem dado",Rodadas!$N$2:$N$165,"Sem dado (serviço)") -> 0
A20: Integração | B20: ChatGPT | C20: =COUNTIFS(Rodadas!$B$2:$B$165,"Integração",Rodadas!$C$2:$C$165,"chatgpt",Rodadas!$E$2:$E$165,"Bug") -> 6 | D20: =SUMIFS(Rodadas!$I$2:$I$165,Rodadas!$B$2:$B$165,"Integração",Rodadas!$C$2:$C$165,"chatgpt",Rodadas!$E$2:$E$165,"Bug") -> 31 | E20: =SUMIFS(Rodadas!$J$2:$J$165,Rodadas!$B$2:$B$165,"Integração",Rodadas!$C$2:$C$165,"chatgpt",Rodadas!$E$2:$E$165,"Bug") -> 11 | F20: =SUMIFS(Rodadas!$K$2:$K$165,Rodadas!$B$2:$B$165,"Integração",Rodadas!$C$2:$C$165,"chatgpt",Rodadas!$E$2:$E$165,"Bug",Rodadas!$L$2:$L$165,"executa") -> 18 | G20: =IF(E20+F20=0,"",E20/(E20+F20)) -> 0.37931034 | H20: =SUMIFS(Rodadas!$P$2:$P$165,Rodadas!$B$2:$B$165,"Integração",Rodadas!$C$2:$C$165,"chatgpt",Rodadas!$E$2:$E$165,"Bug") -> 2 | I20: =SUMIFS(Rodadas!$H$2:$H$165,Rodadas!$B$2:$B$165,"Integração",Rodadas!$C$2:$C$165,"chatgpt",Rodadas!$E$2:$E$165,"Bug") -> 2 | J20: =COUNTIFS(Rodadas!$B$2:$B$165,"Integração",Rodadas!$C$2:$C$165,"chatgpt",Rodadas!$E$2:$E$165,"Bug",Rodadas!$L$2:$L$165,"não compila") -> 1 | K20: =SUMIFS(Rodadas!$M$2:$M$165,Rodadas!$B$2:$B$165,"Integração",Rodadas!$C$2:$C$165,"chatgpt",Rodadas!$E$2:$E$165,"Bug") -> 12 | L20: =SUMIFS(Rodadas!$O$2:$O$165,Rodadas!$B$2:$B$165,"Integração",Rodadas!$C$2:$C$165,"chatgpt",Rodadas!$E$2:$E$165,"Bug") -> 2 | M20: =COUNTIFS(Rodadas!$B$2:$B$165,"Integração",Rodadas!$C$2:$C$165,"chatgpt",Rodadas!$E$2:$E$165,"Bug",Rodadas!$N$2:$N$165,"Capturou") -> 0 | N20: =COUNTIFS(Rodadas!$B$2:$B$165,"Integração",Rodadas!$C$2:$C$165,"chatgpt",Rodadas!$E$2:$E$165,"Bug",Rodadas!$N$2:$N$165,"Caracterizou c/ alerta") -> 2 | O20: =COUNTIFS(Rodadas!$B$2:$B$165,"Integração",Rodadas!$C$2:$C$165,"chatgpt",Rodadas!$E$2:$E$165,"Bug",Rodadas!$N$2:$N$165,"Viu sem asserção") -> 1 | P20: =COUNTIFS(Rodadas!$B$2:$B$165,"Integração",Rodadas!$C$2:$C$165,"chatgpt",Rodadas!$E$2:$E$165,"Bug",Rodadas!$N$2:$N$165,"Canonizou") -> 2 | Q20: =COUNTIFS(Rodadas!$B$2:$B$165,"Integração",Rodadas!$C$2:$C$165,"chatgpt",Rodadas!$E$2:$E$165,"Bug",Rodadas!$N$2:$N$165,"Não viu") -> 1 | R20: =COUNTIFS(Rodadas!$B$2:$B$165,"Integração",Rodadas!$C$2:$C$165,"chatgpt",Rodadas!$E$2:$E$165,"Sem dado",Rodadas!$N$2:$N$165,"Sem dado (serviço)") -> 0
A21: Integração | B21: Gemini | C21: =COUNTIFS(Rodadas!$B$2:$B$165,"Integração",Rodadas!$C$2:$C$165,"gemini",Rodadas!$E$2:$E$165,"Bug") -> 6 | D21: =SUMIFS(Rodadas!$I$2:$I$165,Rodadas!$B$2:$B$165,"Integração",Rodadas!$C$2:$C$165,"gemini",Rodadas!$E$2:$E$165,"Bug") -> 23 | E21: =SUMIFS(Rodadas!$J$2:$J$165,Rodadas!$B$2:$B$165,"Integração",Rodadas!$C$2:$C$165,"gemini",Rodadas!$E$2:$E$165,"Bug") -> 10 | F21: =SUMIFS(Rodadas!$K$2:$K$165,Rodadas!$B$2:$B$165,"Integração",Rodadas!$C$2:$C$165,"gemini",Rodadas!$E$2:$E$165,"Bug",Rodadas!$L$2:$L$165,"executa") -> 11 | G21: =IF(E21+F21=0,"",E21/(E21+F21)) -> 0.47619048 | H21: =SUMIFS(Rodadas!$P$2:$P$165,Rodadas!$B$2:$B$165,"Integração",Rodadas!$C$2:$C$165,"gemini",Rodadas!$E$2:$E$165,"Bug") -> 2 | I21: =SUMIFS(Rodadas!$H$2:$H$165,Rodadas!$B$2:$B$165,"Integração",Rodadas!$C$2:$C$165,"gemini",Rodadas!$E$2:$E$165,"Bug") -> 2 | J21: =COUNTIFS(Rodadas!$B$2:$B$165,"Integração",Rodadas!$C$2:$C$165,"gemini",Rodadas!$E$2:$E$165,"Bug",Rodadas!$L$2:$L$165,"não compila") -> 1 | K21: =SUMIFS(Rodadas!$M$2:$M$165,Rodadas!$B$2:$B$165,"Integração",Rodadas!$C$2:$C$165,"gemini",Rodadas!$E$2:$E$165,"Bug") -> 13 | L21: =SUMIFS(Rodadas!$O$2:$O$165,Rodadas!$B$2:$B$165,"Integração",Rodadas!$C$2:$C$165,"gemini",Rodadas!$E$2:$E$165,"Bug") -> 3 | M21: =COUNTIFS(Rodadas!$B$2:$B$165,"Integração",Rodadas!$C$2:$C$165,"gemini",Rodadas!$E$2:$E$165,"Bug",Rodadas!$N$2:$N$165,"Capturou") -> 0 | N21: =COUNTIFS(Rodadas!$B$2:$B$165,"Integração",Rodadas!$C$2:$C$165,"gemini",Rodadas!$E$2:$E$165,"Bug",Rodadas!$N$2:$N$165,"Caracterizou c/ alerta") -> 0 | O21: =COUNTIFS(Rodadas!$B$2:$B$165,"Integração",Rodadas!$C$2:$C$165,"gemini",Rodadas!$E$2:$E$165,"Bug",Rodadas!$N$2:$N$165,"Viu sem asserção") -> 2 | P21: =COUNTIFS(Rodadas!$B$2:$B$165,"Integração",Rodadas!$C$2:$C$165,"gemini",Rodadas!$E$2:$E$165,"Bug",Rodadas!$N$2:$N$165,"Canonizou") -> 2 | Q21: =COUNTIFS(Rodadas!$B$2:$B$165,"Integração",Rodadas!$C$2:$C$165,"gemini",Rodadas!$E$2:$E$165,"Bug",Rodadas!$N$2:$N$165,"Não viu") -> 2 | R21: =COUNTIFS(Rodadas!$B$2:$B$165,"Integração",Rodadas!$C$2:$C$165,"gemini",Rodadas!$E$2:$E$165,"Sem dado",Rodadas!$N$2:$N$165,"Sem dado (serviço)") -> 0
A22: E2E | B22: ChatGPT | C22: =COUNTIFS(Rodadas!$B$2:$B$165,"E2E",Rodadas!$C$2:$C$165,"chatgpt",Rodadas!$E$2:$E$165,"Bug") -> 7 | D22: =SUMIFS(Rodadas!$I$2:$I$165,Rodadas!$B$2:$B$165,"E2E",Rodadas!$C$2:$C$165,"chatgpt",Rodadas!$E$2:$E$165,"Bug") -> 24 | E22: =SUMIFS(Rodadas!$J$2:$J$165,Rodadas!$B$2:$B$165,"E2E",Rodadas!$C$2:$C$165,"chatgpt",Rodadas!$E$2:$E$165,"Bug") -> 14 | F22: =SUMIFS(Rodadas!$K$2:$K$165,Rodadas!$B$2:$B$165,"E2E",Rodadas!$C$2:$C$165,"chatgpt",Rodadas!$E$2:$E$165,"Bug",Rodadas!$L$2:$L$165,"executa") -> 6 | G22: =IF(E22+F22=0,"",E22/(E22+F22)) -> 0.7 | H22: =SUMIFS(Rodadas!$P$2:$P$165,Rodadas!$B$2:$B$165,"E2E",Rodadas!$C$2:$C$165,"chatgpt",Rodadas!$E$2:$E$165,"Bug") -> 0 | I22: =SUMIFS(Rodadas!$H$2:$H$165,Rodadas!$B$2:$B$165,"E2E",Rodadas!$C$2:$C$165,"chatgpt",Rodadas!$E$2:$E$165,"Bug") -> 3 | J22: =COUNTIFS(Rodadas!$B$2:$B$165,"E2E",Rodadas!$C$2:$C$165,"chatgpt",Rodadas!$E$2:$E$165,"Bug",Rodadas!$L$2:$L$165,"não compila") -> 1 | K22: =SUMIFS(Rodadas!$M$2:$M$165,Rodadas!$B$2:$B$165,"E2E",Rodadas!$C$2:$C$165,"chatgpt",Rodadas!$E$2:$E$165,"Bug") -> 21 | L22: =SUMIFS(Rodadas!$O$2:$O$165,Rodadas!$B$2:$B$165,"E2E",Rodadas!$C$2:$C$165,"chatgpt",Rodadas!$E$2:$E$165,"Bug") -> 9 | M22: =COUNTIFS(Rodadas!$B$2:$B$165,"E2E",Rodadas!$C$2:$C$165,"chatgpt",Rodadas!$E$2:$E$165,"Bug",Rodadas!$N$2:$N$165,"Capturou") -> 4 | N22: =COUNTIFS(Rodadas!$B$2:$B$165,"E2E",Rodadas!$C$2:$C$165,"chatgpt",Rodadas!$E$2:$E$165,"Bug",Rodadas!$N$2:$N$165,"Caracterizou c/ alerta") -> 0 | O22: =COUNTIFS(Rodadas!$B$2:$B$165,"E2E",Rodadas!$C$2:$C$165,"chatgpt",Rodadas!$E$2:$E$165,"Bug",Rodadas!$N$2:$N$165,"Viu sem asserção") -> 0 | P22: =COUNTIFS(Rodadas!$B$2:$B$165,"E2E",Rodadas!$C$2:$C$165,"chatgpt",Rodadas!$E$2:$E$165,"Bug",Rodadas!$N$2:$N$165,"Canonizou") -> 0 | Q22: =COUNTIFS(Rodadas!$B$2:$B$165,"E2E",Rodadas!$C$2:$C$165,"chatgpt",Rodadas!$E$2:$E$165,"Bug",Rodadas!$N$2:$N$165,"Não viu") -> 3 | R22: =COUNTIFS(Rodadas!$B$2:$B$165,"E2E",Rodadas!$C$2:$C$165,"chatgpt",Rodadas!$E$2:$E$165,"Sem dado",Rodadas!$N$2:$N$165,"Sem dado (serviço)") -> 2
A23: E2E | B23: Gemini | C23: =COUNTIFS(Rodadas!$B$2:$B$165,"E2E",Rodadas!$C$2:$C$165,"gemini",Rodadas!$E$2:$E$165,"Bug") -> 9 | D23: =SUMIFS(Rodadas!$I$2:$I$165,Rodadas!$B$2:$B$165,"E2E",Rodadas!$C$2:$C$165,"gemini",Rodadas!$E$2:$E$165,"Bug") -> 29 | E23: =SUMIFS(Rodadas!$J$2:$J$165,Rodadas!$B$2:$B$165,"E2E",Rodadas!$C$2:$C$165,"gemini",Rodadas!$E$2:$E$165,"Bug") -> 16 | F23: =SUMIFS(Rodadas!$K$2:$K$165,Rodadas!$B$2:$B$165,"E2E",Rodadas!$C$2:$C$165,"gemini",Rodadas!$E$2:$E$165,"Bug",Rodadas!$L$2:$L$165,"executa") -> 13 | G23: =IF(E23+F23=0,"",E23/(E23+F23)) -> 0.55172414 | H23: =SUMIFS(Rodadas!$P$2:$P$165,Rodadas!$B$2:$B$165,"E2E",Rodadas!$C$2:$C$165,"gemini",Rodadas!$E$2:$E$165,"Bug") -> 1 | I23: =SUMIFS(Rodadas!$H$2:$H$165,Rodadas!$B$2:$B$165,"E2E",Rodadas!$C$2:$C$165,"gemini",Rodadas!$E$2:$E$165,"Bug") -> 8 | J23: =COUNTIFS(Rodadas!$B$2:$B$165,"E2E",Rodadas!$C$2:$C$165,"gemini",Rodadas!$E$2:$E$165,"Bug",Rodadas!$L$2:$L$165,"não compila") -> 0 | K23: =SUMIFS(Rodadas!$M$2:$M$165,Rodadas!$B$2:$B$165,"E2E",Rodadas!$C$2:$C$165,"gemini",Rodadas!$E$2:$E$165,"Bug") -> 25 | L23: =SUMIFS(Rodadas!$O$2:$O$165,Rodadas!$B$2:$B$165,"E2E",Rodadas!$C$2:$C$165,"gemini",Rodadas!$E$2:$E$165,"Bug") -> 11 | M23: =COUNTIFS(Rodadas!$B$2:$B$165,"E2E",Rodadas!$C$2:$C$165,"gemini",Rodadas!$E$2:$E$165,"Bug",Rodadas!$N$2:$N$165,"Capturou") -> 7 | N23: =COUNTIFS(Rodadas!$B$2:$B$165,"E2E",Rodadas!$C$2:$C$165,"gemini",Rodadas!$E$2:$E$165,"Bug",Rodadas!$N$2:$N$165,"Caracterizou c/ alerta") -> 0 | O23: =COUNTIFS(Rodadas!$B$2:$B$165,"E2E",Rodadas!$C$2:$C$165,"gemini",Rodadas!$E$2:$E$165,"Bug",Rodadas!$N$2:$N$165,"Viu sem asserção") -> 0 | P23: =COUNTIFS(Rodadas!$B$2:$B$165,"E2E",Rodadas!$C$2:$C$165,"gemini",Rodadas!$E$2:$E$165,"Bug",Rodadas!$N$2:$N$165,"Canonizou") -> 0 | Q23: =COUNTIFS(Rodadas!$B$2:$B$165,"E2E",Rodadas!$C$2:$C$165,"gemini",Rodadas!$E$2:$E$165,"Bug",Rodadas!$N$2:$N$165,"Não viu") -> 2 | R23: =COUNTIFS(Rodadas!$B$2:$B$165,"E2E",Rodadas!$C$2:$C$165,"gemini",Rodadas!$E$2:$E$165,"Sem dado",Rodadas!$N$2:$N$165,"Sem dado (serviço)") -> 0
A24: Todos | B24: ChatGPT | C24: =COUNTIFS(Rodadas!$C$2:$C$165,"chatgpt",Rodadas!$E$2:$E$165,"Bug") -> 25 | D24: =SUMIFS(Rodadas!$I$2:$I$165,Rodadas!$C$2:$C$165,"chatgpt",Rodadas!$E$2:$E$165,"Bug") -> 207 | E24: =SUMIFS(Rodadas!$J$2:$J$165,Rodadas!$C$2:$C$165,"chatgpt",Rodadas!$E$2:$E$165,"Bug") -> 127 | F24: =SUMIFS(Rodadas!$K$2:$K$165,Rodadas!$C$2:$C$165,"chatgpt",Rodadas!$E$2:$E$165,"Bug",Rodadas!$L$2:$L$165,"executa") -> 27 | G24: =IF(E24+F24=0,"",E24/(E24+F24)) -> 0.82467532 | H24: =SUMIFS(Rodadas!$P$2:$P$165,Rodadas!$C$2:$C$165,"chatgpt",Rodadas!$E$2:$E$165,"Bug") -> 8 | I24: =SUMIFS(Rodadas!$H$2:$H$165,Rodadas!$C$2:$C$165,"chatgpt",Rodadas!$E$2:$E$165,"Bug") -> 13 | J24: =COUNTIFS(Rodadas!$C$2:$C$165,"chatgpt",Rodadas!$E$2:$E$165,"Bug",Rodadas!$L$2:$L$165,"não compila") -> 5 | K24: =SUMIFS(Rodadas!$M$2:$M$165,Rodadas!$C$2:$C$165,"chatgpt",Rodadas!$E$2:$E$165,"Bug") -> 49 | L24: =SUMIFS(Rodadas!$O$2:$O$165,Rodadas!$C$2:$C$165,"chatgpt",Rodadas!$E$2:$E$165,"Bug") -> 12 | M24: =COUNTIFS(Rodadas!$C$2:$C$165,"chatgpt",Rodadas!$E$2:$E$165,"Bug",Rodadas!$N$2:$N$165,"Capturou") -> 5 | N24: =COUNTIFS(Rodadas!$C$2:$C$165,"chatgpt",Rodadas!$E$2:$E$165,"Bug",Rodadas!$N$2:$N$165,"Caracterizou c/ alerta") -> 10 | O24: =COUNTIFS(Rodadas!$C$2:$C$165,"chatgpt",Rodadas!$E$2:$E$165,"Bug",Rodadas!$N$2:$N$165,"Viu sem asserção") -> 1 | P24: =COUNTIFS(Rodadas!$C$2:$C$165,"chatgpt",Rodadas!$E$2:$E$165,"Bug",Rodadas!$N$2:$N$165,"Canonizou") -> 2 | Q24: =COUNTIFS(Rodadas!$C$2:$C$165,"chatgpt",Rodadas!$E$2:$E$165,"Bug",Rodadas!$N$2:$N$165,"Não viu") -> 7 | R24: =COUNTIFS(Rodadas!$C$2:$C$165,"chatgpt",Rodadas!$E$2:$E$165,"Sem dado",Rodadas!$N$2:$N$165,"Sem dado (serviço)") -> 2
A25: Todos | B25: Gemini | C25: =COUNTIFS(Rodadas!$C$2:$C$165,"gemini",Rodadas!$E$2:$E$165,"Bug") -> 27 | D25: =SUMIFS(Rodadas!$I$2:$I$165,Rodadas!$C$2:$C$165,"gemini",Rodadas!$E$2:$E$165,"Bug") -> 148 | E25: =SUMIFS(Rodadas!$J$2:$J$165,Rodadas!$C$2:$C$165,"gemini",Rodadas!$E$2:$E$165,"Bug") -> 118 | F25: =SUMIFS(Rodadas!$K$2:$K$165,Rodadas!$C$2:$C$165,"gemini",Rodadas!$E$2:$E$165,"Bug",Rodadas!$L$2:$L$165,"executa") -> 28 | G25: =IF(E25+F25=0,"",E25/(E25+F25)) -> 0.80821918 | H25: =SUMIFS(Rodadas!$P$2:$P$165,Rodadas!$C$2:$C$165,"gemini",Rodadas!$E$2:$E$165,"Bug") -> 12 | I25: =SUMIFS(Rodadas!$H$2:$H$165,Rodadas!$C$2:$C$165,"gemini",Rodadas!$E$2:$E$165,"Bug") -> 20 | J25: =COUNTIFS(Rodadas!$C$2:$C$165,"gemini",Rodadas!$E$2:$E$165,"Bug",Rodadas!$L$2:$L$165,"não compila") -> 1 | K25: =SUMIFS(Rodadas!$M$2:$M$165,Rodadas!$C$2:$C$165,"gemini",Rodadas!$E$2:$E$165,"Bug") -> 46 | L25: =SUMIFS(Rodadas!$O$2:$O$165,Rodadas!$C$2:$C$165,"gemini",Rodadas!$E$2:$E$165,"Bug") -> 16 | M25: =COUNTIFS(Rodadas!$C$2:$C$165,"gemini",Rodadas!$E$2:$E$165,"Bug",Rodadas!$N$2:$N$165,"Capturou") -> 7 | N25: =COUNTIFS(Rodadas!$C$2:$C$165,"gemini",Rodadas!$E$2:$E$165,"Bug",Rodadas!$N$2:$N$165,"Caracterizou c/ alerta") -> 5 | O25: =COUNTIFS(Rodadas!$C$2:$C$165,"gemini",Rodadas!$E$2:$E$165,"Bug",Rodadas!$N$2:$N$165,"Viu sem asserção") -> 3 | P25: =COUNTIFS(Rodadas!$C$2:$C$165,"gemini",Rodadas!$E$2:$E$165,"Bug",Rodadas!$N$2:$N$165,"Canonizou") -> 5 | Q25: =COUNTIFS(Rodadas!$C$2:$C$165,"gemini",Rodadas!$E$2:$E$165,"Bug",Rodadas!$N$2:$N$165,"Não viu") -> 7 | R25: =COUNTIFS(Rodadas!$C$2:$C$165,"gemini",Rodadas!$E$2:$E$165,"Sem dado",Rodadas!$N$2:$N$165,"Sem dado (serviço)") -> 0
A27: C. Por estratégia × modelo (todos os níveis, limpos | bugs)
A28: Estratégia | B28: Modelo | C28: Limpos: rodadas | D28: Gerados | E28: Passando | F28: Taxa | G28: Verdes | H28: Compilou 1ª | I28: Bugs: rodadas c/ dado | J28: Taxa | K28: Capturou | L28: Caracterizou c/ alerta | M28: Viu sem asserção | N28: Canonizou | O28: Não viu
A29: ZS | B29: ChatGPT | C29: =COUNTIFS(Rodadas!$D$2:$D$165,"ZS",Rodadas!$C$2:$C$165,"chatgpt",Rodadas!$E$2:$E$165,"Limpo") -> 16 | D29: =SUMIFS(Rodadas!$I$2:$I$165,Rodadas!$D$2:$D$165,"ZS",Rodadas!$C$2:$C$165,"chatgpt",Rodadas!$E$2:$E$165,"Limpo") -> 217 | E29: =SUMIFS(Rodadas!$J$2:$J$165,Rodadas!$D$2:$D$165,"ZS",Rodadas!$C$2:$C$165,"chatgpt",Rodadas!$E$2:$E$165,"Limpo") -> 208 | F29: =IF(E29+SUMIFS(Rodadas!$K$2:$K$165,Rodadas!$D$2:$D$165,"ZS",Rodadas!$C$2:$C$165,"chatgpt",Rodadas!$E$2:$E$165,"Limpo",Rodadas!$L$2:$L$165,"executa")=0,"",E29/(E29+SUMIFS(Rodadas!$K$2:$K$165,Rodadas!$D$2:$D$165,"ZS",Rodadas!$C$2:$C$165,"chatgpt",Rodadas!$E$2:$E$165,"Limpo",Rodadas!$L$2:$L$165,"executa"))) -> 0.95852535 | G29: =SUMIFS(Rodadas!$P$2:$P$165,Rodadas!$D$2:$D$165,"ZS",Rodadas!$C$2:$C$165,"chatgpt",Rodadas!$E$2:$E$165,"Limpo") -> 10 | H29: =SUMIFS(Rodadas!$H$2:$H$165,Rodadas!$D$2:$D$165,"ZS",Rodadas!$C$2:$C$165,"chatgpt",Rodadas!$E$2:$E$165,"Limpo") -> 11 | I29: =COUNTIFS(Rodadas!$D$2:$D$165,"ZS",Rodadas!$C$2:$C$165,"chatgpt",Rodadas!$E$2:$E$165,"Bug") -> 8 | J29: =IF(SUMIFS(Rodadas!$J$2:$J$165,Rodadas!$D$2:$D$165,"ZS",Rodadas!$C$2:$C$165,"chatgpt",Rodadas!$E$2:$E$165,"Bug")+SUMIFS(Rodadas!$K$2:$K$165,Rodadas!$D$2:$D$165,"ZS",Rodadas!$C$2:$C$165,"chatgpt",Rodadas!$E$2:$E$165,"Bug",Rodadas!$L$2:$L$165,"executa")=0,"",SUMIFS(Rodadas!$J$2:$J$165,Rodadas!$D$2:$D$165,"ZS",Rodadas!$C$2:$C$165,"chatgpt",Rodadas!$E$2:$E$165,"Bug")/(SUMIFS(Rodadas!$J$2:$J$165,Rodadas!$D$2:$D$165,"ZS",Rodadas!$C$2:$C$165,"chatgpt",Rodadas!$E$2:$E$165,"Bug")+SUMIFS(Rodadas!$K$2:$K$165,Rodadas!$D$2:$D$165,"ZS",Rodadas!$C$2:$C$165,"chatgpt",Rodadas!$E$2:$E$165,"Bug",Rodadas!$L$2:$L$165,"executa"))) -> 0.87301587 | K29: =COUNTIFS(Rodadas!$D$2:$D$165,"ZS",Rodadas!$C$2:$C$165,"chatgpt",Rodadas!$E$2:$E$165,"Bug",Rodadas!$N$2:$N$165,"Capturou") -> 1 | L29: =COUNTIFS(Rodadas!$D$2:$D$165,"ZS",Rodadas!$C$2:$C$165,"chatgpt",Rodadas!$E$2:$E$165,"Bug",Rodadas!$N$2:$N$165,"Caracterizou c/ alerta") -> 4 | M29: =COUNTIFS(Rodadas!$D$2:$D$165,"ZS",Rodadas!$C$2:$C$165,"chatgpt",Rodadas!$E$2:$E$165,"Bug",Rodadas!$N$2:$N$165,"Viu sem asserção") -> 1 | N29: =COUNTIFS(Rodadas!$D$2:$D$165,"ZS",Rodadas!$C$2:$C$165,"chatgpt",Rodadas!$E$2:$E$165,"Bug",Rodadas!$N$2:$N$165,"Canonizou") -> 0 | O29: =COUNTIFS(Rodadas!$D$2:$D$165,"ZS",Rodadas!$C$2:$C$165,"chatgpt",Rodadas!$E$2:$E$165,"Bug",Rodadas!$N$2:$N$165,"Não viu") -> 2
A30: ZS | B30: Gemini | C30: =COUNTIFS(Rodadas!$D$2:$D$165,"ZS",Rodadas!$C$2:$C$165,"gemini",Rodadas!$E$2:$E$165,"Limpo") -> 16 | D30: =SUMIFS(Rodadas!$I$2:$I$165,Rodadas!$D$2:$D$165,"ZS",Rodadas!$C$2:$C$165,"gemini",Rodadas!$E$2:$E$165,"Limpo") -> 159 | E30: =SUMIFS(Rodadas!$J$2:$J$165,Rodadas!$D$2:$D$165,"ZS",Rodadas!$C$2:$C$165,"gemini",Rodadas!$E$2:$E$165,"Limpo") -> 153 | F30: =IF(E30+SUMIFS(Rodadas!$K$2:$K$165,Rodadas!$D$2:$D$165,"ZS",Rodadas!$C$2:$C$165,"gemini",Rodadas!$E$2:$E$165,"Limpo",Rodadas!$L$2:$L$165,"executa")=0,"",E30/(E30+SUMIFS(Rodadas!$K$2:$K$165,Rodadas!$D$2:$D$165,"ZS",Rodadas!$C$2:$C$165,"gemini",Rodadas!$E$2:$E$165,"Limpo",Rodadas!$L$2:$L$165,"executa"))) -> 0.99350649 | G30: =SUMIFS(Rodadas!$P$2:$P$165,Rodadas!$D$2:$D$165,"ZS",Rodadas!$C$2:$C$165,"gemini",Rodadas!$E$2:$E$165,"Limpo") -> 14 | H30: =SUMIFS(Rodadas!$H$2:$H$165,Rodadas!$D$2:$D$165,"ZS",Rodadas!$C$2:$C$165,"gemini",Rodadas!$E$2:$E$165,"Limpo") -> 13 | I30: =COUNTIFS(Rodadas!$D$2:$D$165,"ZS",Rodadas!$C$2:$C$165,"gemini",Rodadas!$E$2:$E$165,"Bug") -> 9 | J30: =IF(SUMIFS(Rodadas!$J$2:$J$165,Rodadas!$D$2:$D$165,"ZS",Rodadas!$C$2:$C$165,"gemini",Rodadas!$E$2:$E$165,"Bug")+SUMIFS(Rodadas!$K$2:$K$165,Rodadas!$D$2:$D$165,"ZS",Rodadas!$C$2:$C$165,"gemini",Rodadas!$E$2:$E$165,"Bug",Rodadas!$L$2:$L$165,"executa")=0,"",SUMIFS(Rodadas!$J$2:$J$165,Rodadas!$D$2:$D$165,"ZS",Rodadas!$C$2:$C$165,"gemini",Rodadas!$E$2:$E$165,"Bug")/(SUMIFS(Rodadas!$J$2:$J$165,Rodadas!$D$2:$D$165,"ZS",Rodadas!$C$2:$C$165,"gemini",Rodadas!$E$2:$E$165,"Bug")+SUMIFS(Rodadas!$K$2:$K$165,Rodadas!$D$2:$D$165,"ZS",Rodadas!$C$2:$C$165,"gemini",Rodadas!$E$2:$E$165,"Bug",Rodadas!$L$2:$L$165,"executa"))) -> 0.80392157 | K30: =COUNTIFS(Rodadas!$D$2:$D$165,"ZS",Rodadas!$C$2:$C$165,"gemini",Rodadas!$E$2:$E$165,"Bug",Rodadas!$N$2:$N$165,"Capturou") -> 2 | L30: =COUNTIFS(Rodadas!$D$2:$D$165,"ZS",Rodadas!$C$2:$C$165,"gemini",Rodadas!$E$2:$E$165,"Bug",Rodadas!$N$2:$N$165,"Caracterizou c/ alerta") -> 2 | M30: =COUNTIFS(Rodadas!$D$2:$D$165,"ZS",Rodadas!$C$2:$C$165,"gemini",Rodadas!$E$2:$E$165,"Bug",Rodadas!$N$2:$N$165,"Viu sem asserção") -> 1 | N30: =COUNTIFS(Rodadas!$D$2:$D$165,"ZS",Rodadas!$C$2:$C$165,"gemini",Rodadas!$E$2:$E$165,"Bug",Rodadas!$N$2:$N$165,"Canonizou") -> 1 | O30: =COUNTIFS(Rodadas!$D$2:$D$165,"ZS",Rodadas!$C$2:$C$165,"gemini",Rodadas!$E$2:$E$165,"Bug",Rodadas!$N$2:$N$165,"Não viu") -> 3
A31: FS | B31: ChatGPT | C31: =COUNTIFS(Rodadas!$D$2:$D$165,"FS",Rodadas!$C$2:$C$165,"chatgpt",Rodadas!$E$2:$E$165,"Limpo") -> 16 | D31: =SUMIFS(Rodadas!$I$2:$I$165,Rodadas!$D$2:$D$165,"FS",Rodadas!$C$2:$C$165,"chatgpt",Rodadas!$E$2:$E$165,"Limpo") -> 117 | E31: =SUMIFS(Rodadas!$J$2:$J$165,Rodadas!$D$2:$D$165,"FS",Rodadas!$C$2:$C$165,"chatgpt",Rodadas!$E$2:$E$165,"Limpo") -> 103 | F31: =IF(E31+SUMIFS(Rodadas!$K$2:$K$165,Rodadas!$D$2:$D$165,"FS",Rodadas!$C$2:$C$165,"chatgpt",Rodadas!$E$2:$E$165,"Limpo",Rodadas!$L$2:$L$165,"executa")=0,"",E31/(E31+SUMIFS(Rodadas!$K$2:$K$165,Rodadas!$D$2:$D$165,"FS",Rodadas!$C$2:$C$165,"chatgpt",Rodadas!$E$2:$E$165,"Limpo",Rodadas!$L$2:$L$165,"executa"))) -> 0.88034188 | G31: =SUMIFS(Rodadas!$P$2:$P$165,Rodadas!$D$2:$D$165,"FS",Rodadas!$C$2:$C$165,"chatgpt",Rodadas!$E$2:$E$165,"Limpo") -> 9 | H31: =SUMIFS(Rodadas!$H$2:$H$165,Rodadas!$D$2:$D$165,"FS",Rodadas!$C$2:$C$165,"chatgpt",Rodadas!$E$2:$E$165,"Limpo") -> 9 | I31: =COUNTIFS(Rodadas!$D$2:$D$165,"FS",Rodadas!$C$2:$C$165,"chatgpt",Rodadas!$E$2:$E$165,"Bug") -> 9 | J31: =IF(SUMIFS(Rodadas!$J$2:$J$165,Rodadas!$D$2:$D$165,"FS",Rodadas!$C$2:$C$165,"chatgpt",Rodadas!$E$2:$E$165,"Bug")+SUMIFS(Rodadas!$K$2:$K$165,Rodadas!$D$2:$D$165,"FS",Rodadas!$C$2:$C$165,"chatgpt",Rodadas!$E$2:$E$165,"Bug",Rodadas!$L$2:$L$165,"executa")=0,"",SUMIFS(Rodadas!$J$2:$J$165,Rodadas!$D$2:$D$165,"FS",Rodadas!$C$2:$C$165,"chatgpt",Rodadas!$E$2:$E$165,"Bug")/(SUMIFS(Rodadas!$J$2:$J$165,Rodadas!$D$2:$D$165,"FS",Rodadas!$C$2:$C$165,"chatgpt",Rodadas!$E$2:$E$165,"Bug")+SUMIFS(Rodadas!$K$2:$K$165,Rodadas!$D$2:$D$165,"FS",Rodadas!$C$2:$C$165,"chatgpt",Rodadas!$E$2:$E$165,"Bug",Rodadas!$L$2:$L$165,"executa"))) -> 0.73684211 | K31: =COUNTIFS(Rodadas!$D$2:$D$165,"FS",Rodadas!$C$2:$C$165,"chatgpt",Rodadas!$E$2:$E$165,"Bug",Rodadas!$N$2:$N$165,"Capturou") -> 3 | L31: =COUNTIFS(Rodadas!$D$2:$D$165,"FS",Rodadas!$C$2:$C$165,"chatgpt",Rodadas!$E$2:$E$165,"Bug",Rodadas!$N$2:$N$165,"Caracterizou c/ alerta") -> 3 | M31: =COUNTIFS(Rodadas!$D$2:$D$165,"FS",Rodadas!$C$2:$C$165,"chatgpt",Rodadas!$E$2:$E$165,"Bug",Rodadas!$N$2:$N$165,"Viu sem asserção") -> 0 | N31: =COUNTIFS(Rodadas!$D$2:$D$165,"FS",Rodadas!$C$2:$C$165,"chatgpt",Rodadas!$E$2:$E$165,"Bug",Rodadas!$N$2:$N$165,"Canonizou") -> 0 | O31: =COUNTIFS(Rodadas!$D$2:$D$165,"FS",Rodadas!$C$2:$C$165,"chatgpt",Rodadas!$E$2:$E$165,"Bug",Rodadas!$N$2:$N$165,"Não viu") -> 3
A32: FS | B32: Gemini | C32: =COUNTIFS(Rodadas!$D$2:$D$165,"FS",Rodadas!$C$2:$C$165,"gemini",Rodadas!$E$2:$E$165,"Limpo") -> 16 | D32: =SUMIFS(Rodadas!$I$2:$I$165,Rodadas!$D$2:$D$165,"FS",Rodadas!$C$2:$C$165,"gemini",Rodadas!$E$2:$E$165,"Limpo") -> 86 | E32: =SUMIFS(Rodadas!$J$2:$J$165,Rodadas!$D$2:$D$165,"FS",Rodadas!$C$2:$C$165,"gemini",Rodadas!$E$2:$E$165,"Limpo") -> 80 | F32: =IF(E32+SUMIFS(Rodadas!$K$2:$K$165,Rodadas!$D$2:$D$165,"FS",Rodadas!$C$2:$C$165,"gemini",Rodadas!$E$2:$E$165,"Limpo",Rodadas!$L$2:$L$165,"executa")=0,"",E32/(E32+SUMIFS(Rodadas!$K$2:$K$165,Rodadas!$D$2:$D$165,"FS",Rodadas!$C$2:$C$165,"gemini",Rodadas!$E$2:$E$165,"Limpo",Rodadas!$L$2:$L$165,"executa"))) -> 0.93023256 | G32: =SUMIFS(Rodadas!$P$2:$P$165,Rodadas!$D$2:$D$165,"FS",Rodadas!$C$2:$C$165,"gemini",Rodadas!$E$2:$E$165,"Limpo") -> 13 | H32: =SUMIFS(Rodadas!$H$2:$H$165,Rodadas!$D$2:$D$165,"FS",Rodadas!$C$2:$C$165,"gemini",Rodadas!$E$2:$E$165,"Limpo") -> 14 | I32: =COUNTIFS(Rodadas!$D$2:$D$165,"FS",Rodadas!$C$2:$C$165,"gemini",Rodadas!$E$2:$E$165,"Bug") -> 9 | J32: =IF(SUMIFS(Rodadas!$J$2:$J$165,Rodadas!$D$2:$D$165,"FS",Rodadas!$C$2:$C$165,"gemini",Rodadas!$E$2:$E$165,"Bug")+SUMIFS(Rodadas!$K$2:$K$165,Rodadas!$D$2:$D$165,"FS",Rodadas!$C$2:$C$165,"gemini",Rodadas!$E$2:$E$165,"Bug",Rodadas!$L$2:$L$165,"executa")=0,"",SUMIFS(Rodadas!$J$2:$J$165,Rodadas!$D$2:$D$165,"FS",Rodadas!$C$2:$C$165,"gemini",Rodadas!$E$2:$E$165,"Bug")/(SUMIFS(Rodadas!$J$2:$J$165,Rodadas!$D$2:$D$165,"FS",Rodadas!$C$2:$C$165,"gemini",Rodadas!$E$2:$E$165,"Bug")+SUMIFS(Rodadas!$K$2:$K$165,Rodadas!$D$2:$D$165,"FS",Rodadas!$C$2:$C$165,"gemini",Rodadas!$E$2:$E$165,"Bug",Rodadas!$L$2:$L$165,"executa"))) -> 0.75757576 | K32: =COUNTIFS(Rodadas!$D$2:$D$165,"FS",Rodadas!$C$2:$C$165,"gemini",Rodadas!$E$2:$E$165,"Bug",Rodadas!$N$2:$N$165,"Capturou") -> 3 | L32: =COUNTIFS(Rodadas!$D$2:$D$165,"FS",Rodadas!$C$2:$C$165,"gemini",Rodadas!$E$2:$E$165,"Bug",Rodadas!$N$2:$N$165,"Caracterizou c/ alerta") -> 1 | M32: =COUNTIFS(Rodadas!$D$2:$D$165,"FS",Rodadas!$C$2:$C$165,"gemini",Rodadas!$E$2:$E$165,"Bug",Rodadas!$N$2:$N$165,"Viu sem asserção") -> 2 | N32: =COUNTIFS(Rodadas!$D$2:$D$165,"FS",Rodadas!$C$2:$C$165,"gemini",Rodadas!$E$2:$E$165,"Bug",Rodadas!$N$2:$N$165,"Canonizou") -> 1 | O32: =COUNTIFS(Rodadas!$D$2:$D$165,"FS",Rodadas!$C$2:$C$165,"gemini",Rodadas!$E$2:$E$165,"Bug",Rodadas!$N$2:$N$165,"Não viu") -> 2
A33: COT | B33: ChatGPT | C33: =COUNTIFS(Rodadas!$D$2:$D$165,"COT",Rodadas!$C$2:$C$165,"chatgpt",Rodadas!$E$2:$E$165,"Limpo") -> 16 | D33: =SUMIFS(Rodadas!$I$2:$I$165,Rodadas!$D$2:$D$165,"COT",Rodadas!$C$2:$C$165,"chatgpt",Rodadas!$E$2:$E$165,"Limpo") -> 285 | E33: =SUMIFS(Rodadas!$J$2:$J$165,Rodadas!$D$2:$D$165,"COT",Rodadas!$C$2:$C$165,"chatgpt",Rodadas!$E$2:$E$165,"Limpo") -> 244 | F33: =IF(E33+SUMIFS(Rodadas!$K$2:$K$165,Rodadas!$D$2:$D$165,"COT",Rodadas!$C$2:$C$165,"chatgpt",Rodadas!$E$2:$E$165,"Limpo",Rodadas!$L$2:$L$165,"executa")=0,"",E33/(E33+SUMIFS(Rodadas!$K$2:$K$165,Rodadas!$D$2:$D$165,"COT",Rodadas!$C$2:$C$165,"chatgpt",Rodadas!$E$2:$E$165,"Limpo",Rodadas!$L$2:$L$165,"executa"))) -> 0.93846154 | G33: =SUMIFS(Rodadas!$P$2:$P$165,Rodadas!$D$2:$D$165,"COT",Rodadas!$C$2:$C$165,"chatgpt",Rodadas!$E$2:$E$165,"Limpo") -> 10 | H33: =SUMIFS(Rodadas!$H$2:$H$165,Rodadas!$D$2:$D$165,"COT",Rodadas!$C$2:$C$165,"chatgpt",Rodadas!$E$2:$E$165,"Limpo") -> 9 | I33: =COUNTIFS(Rodadas!$D$2:$D$165,"COT",Rodadas!$C$2:$C$165,"chatgpt",Rodadas!$E$2:$E$165,"Bug") -> 8 | J33: =IF(SUMIFS(Rodadas!$J$2:$J$165,Rodadas!$D$2:$D$165,"COT",Rodadas!$C$2:$C$165,"chatgpt",Rodadas!$E$2:$E$165,"Bug")+SUMIFS(Rodadas!$K$2:$K$165,Rodadas!$D$2:$D$165,"COT",Rodadas!$C$2:$C$165,"chatgpt",Rodadas!$E$2:$E$165,"Bug",Rodadas!$L$2:$L$165,"executa")=0,"",SUMIFS(Rodadas!$J$2:$J$165,Rodadas!$D$2:$D$165,"COT",Rodadas!$C$2:$C$165,"chatgpt",Rodadas!$E$2:$E$165,"Bug")/(SUMIFS(Rodadas!$J$2:$J$165,Rodadas!$D$2:$D$165,"COT",Rodadas!$C$2:$C$165,"chatgpt",Rodadas!$E$2:$E$165,"Bug")+SUMIFS(Rodadas!$K$2:$K$165,Rodadas!$D$2:$D$165,"COT",Rodadas!$C$2:$C$165,"chatgpt",Rodadas!$E$2:$E$165,"Bug",Rodadas!$L$2:$L$165,"executa"))) -> 0.80555556 | K33: =COUNTIFS(Rodadas!$D$2:$D$165,"COT",Rodadas!$C$2:$C$165,"chatgpt",Rodadas!$E$2:$E$165,"Bug",Rodadas!$N$2:$N$165,"Capturou") -> 1 | L33: =COUNTIFS(Rodadas!$D$2:$D$165,"COT",Rodadas!$C$2:$C$165,"chatgpt",Rodadas!$E$2:$E$165,"Bug",Rodadas!$N$2:$N$165,"Caracterizou c/ alerta") -> 3 | M33: =COUNTIFS(Rodadas!$D$2:$D$165,"COT",Rodadas!$C$2:$C$165,"chatgpt",Rodadas!$E$2:$E$165,"Bug",Rodadas!$N$2:$N$165,"Viu sem asserção") -> 0 | N33: =COUNTIFS(Rodadas!$D$2:$D$165,"COT",Rodadas!$C$2:$C$165,"chatgpt",Rodadas!$E$2:$E$165,"Bug",Rodadas!$N$2:$N$165,"Canonizou") -> 2 | O33: =COUNTIFS(Rodadas!$D$2:$D$165,"COT",Rodadas!$C$2:$C$165,"chatgpt",Rodadas!$E$2:$E$165,"Bug",Rodadas!$N$2:$N$165,"Não viu") -> 2
A34: COT | B34: Gemini | C34: =COUNTIFS(Rodadas!$D$2:$D$165,"COT",Rodadas!$C$2:$C$165,"gemini",Rodadas!$E$2:$E$165,"Limpo") -> 16 | D34: =SUMIFS(Rodadas!$I$2:$I$165,Rodadas!$D$2:$D$165,"COT",Rodadas!$C$2:$C$165,"gemini",Rodadas!$E$2:$E$165,"Limpo") -> 160 | E34: =SUMIFS(Rodadas!$J$2:$J$165,Rodadas!$D$2:$D$165,"COT",Rodadas!$C$2:$C$165,"gemini",Rodadas!$E$2:$E$165,"Limpo") -> 134 | F34: =IF(E34+SUMIFS(Rodadas!$K$2:$K$165,Rodadas!$D$2:$D$165,"COT",Rodadas!$C$2:$C$165,"gemini",Rodadas!$E$2:$E$165,"Limpo",Rodadas!$L$2:$L$165,"executa")=0,"",E34/(E34+SUMIFS(Rodadas!$K$2:$K$165,Rodadas!$D$2:$D$165,"COT",Rodadas!$C$2:$C$165,"gemini",Rodadas!$E$2:$E$165,"Limpo",Rodadas!$L$2:$L$165,"executa"))) -> 0.88157895 | G34: =SUMIFS(Rodadas!$P$2:$P$165,Rodadas!$D$2:$D$165,"COT",Rodadas!$C$2:$C$165,"gemini",Rodadas!$E$2:$E$165,"Limpo") -> 10 | H34: =SUMIFS(Rodadas!$H$2:$H$165,Rodadas!$D$2:$D$165,"COT",Rodadas!$C$2:$C$165,"gemini",Rodadas!$E$2:$E$165,"Limpo") -> 12 | I34: =COUNTIFS(Rodadas!$D$2:$D$165,"COT",Rodadas!$C$2:$C$165,"gemini",Rodadas!$E$2:$E$165,"Bug") -> 9 | J34: =IF(SUMIFS(Rodadas!$J$2:$J$165,Rodadas!$D$2:$D$165,"COT",Rodadas!$C$2:$C$165,"gemini",Rodadas!$E$2:$E$165,"Bug")+SUMIFS(Rodadas!$K$2:$K$165,Rodadas!$D$2:$D$165,"COT",Rodadas!$C$2:$C$165,"gemini",Rodadas!$E$2:$E$165,"Bug",Rodadas!$L$2:$L$165,"executa")=0,"",SUMIFS(Rodadas!$J$2:$J$165,Rodadas!$D$2:$D$165,"COT",Rodadas!$C$2:$C$165,"gemini",Rodadas!$E$2:$E$165,"Bug")/(SUMIFS(Rodadas!$J$2:$J$165,Rodadas!$D$2:$D$165,"COT",Rodadas!$C$2:$C$165,"gemini",Rodadas!$E$2:$E$165,"Bug")+SUMIFS(Rodadas!$K$2:$K$165,Rodadas!$D$2:$D$165,"COT",Rodadas!$C$2:$C$165,"gemini",Rodadas!$E$2:$E$165,"Bug",Rodadas!$L$2:$L$165,"executa"))) -> 0.83870968 | K34: =COUNTIFS(Rodadas!$D$2:$D$165,"COT",Rodadas!$C$2:$C$165,"gemini",Rodadas!$E$2:$E$165,"Bug",Rodadas!$N$2:$N$165,"Capturou") -> 2 | L34: =COUNTIFS(Rodadas!$D$2:$D$165,"COT",Rodadas!$C$2:$C$165,"gemini",Rodadas!$E$2:$E$165,"Bug",Rodadas!$N$2:$N$165,"Caracterizou c/ alerta") -> 2 | M34: =COUNTIFS(Rodadas!$D$2:$D$165,"COT",Rodadas!$C$2:$C$165,"gemini",Rodadas!$E$2:$E$165,"Bug",Rodadas!$N$2:$N$165,"Viu sem asserção") -> 0 | N34: =COUNTIFS(Rodadas!$D$2:$D$165,"COT",Rodadas!$C$2:$C$165,"gemini",Rodadas!$E$2:$E$165,"Bug",Rodadas!$N$2:$N$165,"Canonizou") -> 3 | O34: =COUNTIFS(Rodadas!$D$2:$D$165,"COT",Rodadas!$C$2:$C$165,"gemini",Rodadas!$E$2:$E$165,"Bug",Rodadas!$N$2:$N$165,"Não viu") -> 2

Sheet Detecção por bug
A1: Nível | B1: Bug | C1: Tipo | D1: Estratégia | E1: ChatGPT | F1: Gemini
A2: Unitário | B2: U-CRASH | C2: CRASH | D2: ZS | E2: Caracterizou c/ alerta | F2: Caracterizou c/ alerta
A3: Unitário | B3: U-CRASH | C3: CRASH | D3: FS | E3: Capturou | F3: Viu sem asserção
A4: Unitário | B4: U-CRASH | C4: CRASH | D4: COT | E4: Caracterizou c/ alerta | F4: Caracterizou c/ alerta
A5: Unitário | B5: U-SILENT | C5: SILENT | D5: ZS | E5: Caracterizou c/ alerta | F5: Caracterizou c/ alerta
A6: Unitário | B6: U-SILENT | C6: SILENT | D6: FS | E6: Caracterizou c/ alerta | F6: Caracterizou c/ alerta
A7: Unitário | B7: U-SILENT | C7: SILENT | D7: COT | E7: Caracterizou c/ alerta | F7: Caracterizou c/ alerta
A8: Widget | B8: W-CRASH | C8: CRASH | D8: ZS | E8: Não viu | F8: Não viu
A9: Widget | B9: W-CRASH | C9: CRASH | D9: FS | E9: Não viu | F9: Não viu
A10: Widget | B10: W-CRASH | C10: CRASH | D10: COT | E10: Não viu | F10: Não viu
A11: Widget | B11: W-SILENT | C11: SILENT | D11: ZS | E11: Caracterizou c/ alerta | F11: Canonizou
